Workbook

Sheet 마스터
A1: 라벨 마스터 (재질·규격별 입고/출고/재고·가격·채널별 판매) — 재고 2026-10-07 실재고 · 오픈마켓 판매는 판매현황 시트 기준
A2: 수수료율 | C2: 0.054
A3: 부가세율 | C3: 0.1
A4: No | B4: 재질 | C4: 규격 | D4: 입고수량 | E4: 전체판매수량 (입고−재고) | F4: 오픈마켓 판매 합계(롤) | G4: 재고수량 (10/7 실재고) | H4: 오픈마켓 판매건수 (판매현황 기준) | I4: 출고 중 오픈마켓 비중 | J4: 재고순위 (재고 많은 순) | K4: 판매순위 (출고 많은 순) | L4: 롤당 수량(매) | M4: 장당 원가 | N4: 원가 | O4: 판매가 (부가세 별도) | P4: 등록가 (부가세 포함) | Q4: 이익금액(원) (수수료 제외) | R4: 마진율 (수수료 제외) | S4: 쿠팡 (롤) | T4: 지마켓 (롤) | U4: 전문몰 (롤) | V4: 11번가 (롤) | W4: 상태 | X4: 옵션 가능 수 (같은 재질 다른 사이즈) | Y4: 비고 | Z4: 기타몰 (롤) | AA4: 일반 판매 (오픈마켓 외, 롤)
A5: 1 | B5: 아트지 | C5: 35*20 | D5: 120 | E5: =D5-G5 -> 16 | F5: =S5+T5+U5+V5+Z5 -> 0 | G5: 104 | H5: =COUNTIFS(판매현황!$C$3:$C$1000,LEFT($B5,3),판매현황!$D$3:$D$1000,$C5,판매현황!$G$3:$G$1000,">0") -> 0 | I5: =IF(E5=0,"",F5/E5) -> 0 | J5: =COUNTIFS($A$5:$A$30,">0",$G$5:$G$30,">"&G5)+1 -> 2 | K5: =COUNTIFS($A$5:$A$30,">0",$E$5:$E$30,">"&E5)+1 -> 18 | L5: 2500 | M5: 0.6 | N5: =L5*M5 -> 1500 | O5: 2500 | P5: =IF(O5="","",ROUNDDOWN(O5*(1+$C$3),-1)) -> 2750 | Q5: =IF(O5="","",O5-O5*$C$2-N5) -> 865 | R5: =IF(O5="","",Q5/O5) -> 0.346 | S5: =SUMIFS(판매현황!$G$3:$G$1000,판매현황!$C$3:$C$1000,LEFT($B5,3),판매현황!$D$3:$D$1000,$C5,판매현황!$F$3:$F$1000,"쿠팡") -> 0 | T5: =SUMIFS(판매현황!$G$3:$G$1000,판매현황!$C$3:$C$1000,LEFT($B5,3),판매현황!$D$3:$D$1000,$C5,판매현황!$F$3:$F$1000,"지마켓") -> 0 | U5: =SUMIFS(판매현황!$G$3:$G$1000,판매현황!$C$3:$C$1000,LEFT($B5,3),판매현황!$D$3:$D$1000,$C5,판매현황!$F$3:$F$1000,"전문몰") -> 0 | V5: =SUMIFS(판매현황!$G$3:$G$1000,판매현황!$C$3:$C$1000,LEFT($B5,3),판매현황!$D$3:$D$1000,$C5,판매현황!$F$3:$F$1000,"11번가") -> 0 | W5: =IF(G5<=0,"품절",IF(E5=0,"미판매","판매중")) -> 판매중 | X5: =아트지!G23 -> 3 | Y5: 오픈마켓 판매 아님 | Z5: =SUMIFS(판매현황!$G$3:$G$1000,판매현황!$C$3:$C$1000,LEFT($B5,3),판매현황!$D$3:$D$1000,$C5)-S5-T5-U5-V5 -> 0 | AA5: =E5-F5 -> 16
A6: 2 | B6: 아트지 | C6: 40*20 | D6: 100 | E6: =D6-G6 -> 71 | F6: =S6+T6+U6+V6+Z6 -> 14 | G6: 29 | H6: =COUNTIFS(판매현황!$C$3:$C$1000,LEFT($B6,3),판매현황!$D$3:$D$1000,$C6,판매현황!$G$3:$G$1000,">0") -> 2 | I6: =IF(E6=0,"",F6/E6) -> 0.1971831 | J6: =COUNTIFS($A$5:$A$30,">0",$G$5:$G$30,">"&G6)+1 -> 11 | K6: =COUNTIFS($A$5:$A$30,">0",$E$5:$E$30,">"&E6)+1 -> 4 | L6: 2500 | M6: 0.6 | N6: =L6*M6 -> 1500 | O6: 2500 | P6: =IF(O6="","",ROUNDDOWN(O6*(1+$C$3),-1)) -> 2750 | Q6: =IF(O6="","",O6-O6*$C$2-N6) -> 865 | R6: =IF(O6="","",Q6/O6) -> 0.346 | S6: =SUMIFS(판매현황!$G$3:$G$1000,판매현황!$C$3:$C$1000,LEFT($B6,3),판매현황!$D$3:$D$1000,$C6,판매현황!$F$3:$F$1000,"쿠팡") -> 12 | T6: =SUMIFS(판매현황!$G$3:$G$1000,판매현황!$C$3:$C$1000,LEFT($B6,3),판매현황!$D$3:$D$1000,$C6,판매현황!$F$3:$F$1000,"지마켓") -> 0 | U6: =SUMIFS(판매현황!$G$3:$G$1000,판매현황!$C$3:$C$1000,LEFT($B6,3),판매현황!$D$3:$D$1000,$C6,판매현황!$F$3:$F$1000,"전문몰") -> 2 | V6: =SUMIFS(판매현황!$G$3:$G$1000,판매현황!$C$3:$C$1000,LEFT($B6,3),판매현황!$D$3:$D$1000,$C6,판매현황!$F$3:$F$1000,"11번가") -> 0 | W6: =IF(G6<=0,"품절",IF(E6=0,"미판매","판매중")) -> 판매중 | X6: =아트지!G24 -> 4 | Y6: 전문몰 2롤 | Z6: =SUMIFS(판매현황!$G$3:$G$1000,판매현황!$C$3:$C$1000,LEFT($B6,3),판매현황!$D$3:$D$1000,$C6)-S6-T6-U6-V6 -> 0 | AA6: =E6-F6 -> 57
A7: 3 | B7: 아트지 | C7: 50*30 | D7: 120 | E7: =D7-G7 -> 78 | F7: =S7+T7+U7+V7+Z7 -> 0 | G7: 42 | H7: =COUNTIFS(판매현황!$C$3:$C$1000,LEFT($B7,3),판매현황!$D$3:$D$1000,$C7,판매현황!$G$3:$G$1000,">0") -> 0 | I7: =IF(E7=0,"",F7/E7) -> 0 | J7: =COUNTIFS($A$5:$A$30,">0",$G$5:$G$30,">"&G7)+1 -> 7 | K7: =COUNTIFS($A$5:$A$30,">0",$E$5:$E$30,">"&E7)+1 -> 2 | L7: 2000 | M7: 0.9 | N7: =L7*M7 -> 1800 | O7: 4000 | P7: =IF(O7="","",ROUNDDOWN(O7*(1+$C$3),-1)) -> 4400 | Q7: =IF(O7="","",O7-O7*$C$2-N7) -> 1984 | R7: =IF(O7="","",Q7/O7) -> 0.496 | S7: =SUMIFS(판매현황!$G$3:$G$1000,판매현황!$C$3:$C$1000,LEFT($B7,3),판매현황!$D$3:$D$1000,$C7,판매현황!$F$3:$F$1000,"쿠팡") -> 0 | T7: =SUMIFS(판매현황!$G$3:$G$1000,판매현황!$C$3:$C$1000,LEFT($B7,3),판매현황!$D$3:$D$1000,$C7,판매현황!$F$3:$F$1000,"지마켓") -> 0 | U7: =SUMIFS(판매현황!$G$3:$G$1000,판매현황!$C$3:$C$1000,LEFT($B7,3),판매현황!$D$3:$D$1000,$C7,판매현황!$F$3:$F$1000,"전문몰") -> 0 | V7: =SUMIFS(판매현황!$G$3:$G$1000,판매현황!$C$3:$C$1000,LEFT($B7,3),판매현황!$D$3:$D$1000,$C7,판매현황!$F$3:$F$1000,"11번가") -> 0 | W7: =IF(G7<=0,"품절",IF(E7=0,"미판매","판매중")) -> 판매중 | X7: =아트지!G25 -> 6 | Y7: 전문몰 1롤 | Z7: =SUMIFS(판매현황!$G$3:$G$1000,판매현황!$C$3:$C$1000,LEFT($B7,3),판매현황!$D$3:$D$1000,$C7)-S7-T7-U7-V7 -> 0 | AA7: =E7-F7 -> 78
A8: 4 | B8: 아트지 | C8: 50*50 | D8: 70 | E8: =D8-G8 -> 52 | F8: =S8+T8+U8+V8+Z8 -> 22 | G8: 18 | H8: =COUNTIFS(판매현황!$C$3:$C$1000,LEFT($B8,3),판매현황!$D$3:$D$1000,$C8,판매현황!$G$3:$G$1000,">0") -> 3 | I8: =IF(E8=0,"",F8/E8) -> 0.42307692 | J8: =COUNTIFS($A$5:$A$30,">0",$G$5:$G$30,">"&G8)+1 -> 13 | K8: =COUNTIFS($A$5:$A$30,">0",$E$5:$E$30,">"&E8)+1 -> 8 | L8: 1000 | M8: 1.8 | N8: =L8*M8 -> 1800 | O8: 3500 | P8: =IF(O8="","",ROUNDDOWN(O8*(1+$C$3),-1)) -> 3850 | Q8: =IF(O8="","",O8-O8*$C$2-N8) -> 1511 | R8: =IF(O8="","",Q8/O8) -> 0.43171429 | S8: =SUMIFS(판매현황!$G$3:$G$1000,판매현황!$C$3:$C$1000,LEFT($B8,3),판매현황!$D$3:$D$1000,$C8,판매현황!$F$3:$F$1000,"쿠팡") -> 2 | T8: =SUMIFS(판매현황!$G$3:$G$1000,판매현황!$C$3:$C$1000,LEFT($B8,3),판매현황!$D$3:$D$1000,$C8,판매현황!$F$3:$F$1000,"지마켓") -> 20 | U8: =SUMIFS(판매현황!$G$3:$G$1000,판매현황!$C$3:$C$1000,LEFT($B8,3),판매현황!$D$3:$D$1000,$C8,판매현황!$F$3:$F$1000,"전문몰") -> 0 | V8: =SUMIFS(판매현황!$G$3:$G$1000,판매현황!$C$3:$C$1000,LEFT($B8,3),판매현황!$D$3:$D$1000,$C8,판매현황!$F$3:$F$1000,"11번가") -> 0 | W8: =IF(G8<=0,"품절",IF(E8=0,"미판매","판매중")) -> 판매중 | X8: =아트지!G26 -> 7 | Y8: 지마켓 20롤 + 쿠팡 2롤 | Z8: =SUMIFS(판매현황!$G$3:$G$1000,판매현황!$C$3:$C$1000,LEFT($B8,3),판매현황!$D$3:$D$1000,$C8)-S8-T8-U8-V8 -> 0 | AA8: =E8-F8 -> 30
A9: 5 | B9: 아트지 | C9: 60*40 | D9: 100 | E9: =D9-G9 -> 9 | F9: =S9+T9+U9+V9+Z9 -> 9 | G9: 91 | H9: =COUNTIFS(판매현황!$C$3:$C$1000,LEFT($B9,3),판매현황!$D$3:$D$1000,$C9,판매현황!$G$3:$G$1000,">0") -> 5 | I9: =IF(E9=0,"",F9/E9) -> 1 | J9: =COUNTIFS($A$5:$A$30,">0",$G$5:$G$30,">"&G9)+1 -> 3 | K9: =COUNTIFS($A$5:$A$30,">0",$E$5:$E$30,">"&E9)+1 -> 22 | L9: 1400 | M9: 1.6 | N9: =L9*M9 -> 2240 | O9: 4482 | P9: =IF(O9="","",ROUNDDOWN(O9*(1+$C$3),-1)) -> 4930 | Q9: =IF(O9="","",O9-O9*$C$2-N9) -> 1999.972 | R9: =IF(O9="","",Q9/O9) -> 0.44622311 | S9: =SUMIFS(판매현황!$G$3:$G$1000,판매현황!$C$3:$C$1000,LEFT($B9,3),판매현황!$D$3:$D$1000,$C9,판매현황!$F$3:$F$1000,"쿠팡") -> 4 | T9: =SUMIFS(판매현황!$G$3:$G$1000,판매현황!$C$3:$C$1000,LEFT($B9,3),판매현황!$D$3:$D$1000,$C9,판매현황!$F$3:$F$1000,"지마켓") -> 0 | U9: =SUMIFS(판매현황!$G$3:$G$1000,판매현황!$C$3:$C$1000,LEFT($B9,3),판매현황!$D$3:$D$1000,$C9,판매현황!$F$3:$F$1000,"전문몰") -> 5 | V9: =SUMIFS(판매현황!$G$3:$G$1000,판매현황!$C$3:$C$1000,LEFT($B9,3),판매현황!$D$3:$D$1000,$C9,판매현황!$F$3:$F$1000,"11번가") -> 0 | W9: =IF(G9<=0,"품절",IF(E9=0,"미판매","판매중")) -> 판매중 | X9: =아트지!G27 -> 6 | Y9: 쿠팡 1롤+전문몰 6롤 | Z9: =SUMIFS(판매현황!$G$3:$G$1000,판매현황!$C$3:$C$1000,LEFT($B9,3),판매현황!$D$3:$D$1000,$C9)-S9-T9-U9-V9 -> 0 | AA9: =E9-F9 -> 0
A10: 6 | B10: 아트지/품절 | C10: 70*40 | D10: 50 | E10: =D10-G10 -> 50 | F10: =S10+T10+U10+V10+Z10 -> 0 | G10: 0 | H10: =COUNTIFS(판매현황!$C$3:$C$1000,LEFT($B10,3),판매현황!$D$3:$D$1000,$C10,판매현황!$G$3:$G$1000,">0") -> 0 | I10: =IF(E10=0,"",F10/E10) -> 0 | J10: =COUNTIFS($A$5:$A$30,">0",$G$5:$G$30,">"&G10)+1 -> 21 | K10: =COUNTIFS($A$5:$A$30,">0",$E$5:$E$30,">"&E10)+1 -> 9 | L10: 1250 | M10: 1.9 | N10: =L10*M10 -> 2375 | P10: =IF(O10="","",ROUNDDOWN(O10*(1+$C$3),-1)) | Q10: =IF(O10="","",O10-O10*$C$2-N10) | R10: =IF(O10="","",Q10/O10) | S10: =SUMIFS(판매현황!$G$3:$G$1000,판매현황!$C$3:$C$1000,LEFT($B10,3),판매현황!$D$3:$D$1000,$C10,판매현황!$F$3:$F$1000,"쿠팡") -> 0 | T10: =SUMIFS(판매현황!$G$3:$G$1000,판매현황!$C$3:$C$1000,LEFT($B10,3),판매현황!$D$3:$D$1000,$C10,판매현황!$F$3:$F$1000,"지마켓") -> 0 | U10: =SUMIFS(판매현황!$G$3:$G$1000,판매현황!$C$3:$C$1000,LEFT($B10,3),판매현황!$D$3:$D$1000,$C10,판매현황!$F$3:$F$1000,"전문몰") -> 0 | V10: =SUMIFS(판매현황!$G$3:$G$1000,판매현황!$C$3:$C$1000,LEFT($B10,3),판매현황!$D$3:$D$1000,$C10,판매현황!$F$3:$F$1000,"11번가") -> 0 | W10: =IF(G10<=0,"품절",IF(E10=0,"미판매","판매중")) -> 품절 | X10: =아트지!G28 -> 0 | Z10: =SUMIFS(판매현황!$G$3:$G$1000,판매현황!$C$3:$C$1000,LEFT($B10,3),판매현황!$D$3:$D$1000,$C10)-S10-T10-U10-V10 -> 0 | AA10: =E10-F10 -> 50
A11: 7 | B11: 아트지 | C11: 80*60 | D11: 100 | E11: =D11-G11 -> 87 | F11: =S11+T11+U11+V11+Z11 -> 2 | G11: 13 | H11: =COUNTIFS(판매현황!$C$3:$C$1000,LEFT($B11,3),판매현황!$D$3:$D$1000,$C11,판매현황!$G$3:$G$1000,">0") -> 2 | I11: =IF(E11=0,"",F11/E11) -> 0.022988506 | J11: =COUNTIFS($A$5:$A$30,">0",$G$5:$G$30,">"&G11)+1 -> 15 | K11: =COUNTIFS($A$5:$A$30,">0",$E$5:$E$30,">"&E11)+1 -> 1 | L11: 1000 | M11: 3.1 | N11: =L11*M11 -> 3100 | O11: 6500 | P11: =IF(O11="","",ROUNDDOWN(O11*(1+$C$3),-1)) -> 7150 | Q11: =IF(O11="","",O11-O11*$C$2-N11) -> 3049 | R11: =IF(O11="","",Q11/O11) -> 0.46907692 | S11: =SUMIFS(판매현황!$G$3:$G$1000,판매현황!$C$3:$C$1000,LEFT($B11,3),판매현황!$D$3:$D$1000,$C11,판매현황!$F$3:$F$1000,"쿠팡") -> 0 | T11: =SUMIFS(판매현황!$G$3:$G$1000,판매현황!$C$3:$C$1000,LEFT($B11,3),판매현황!$D$3:$D$1000,$C11,판매현황!$F$3:$F$1000,"지마켓") -> 0 | U11: =SUMIFS(판매현황!$G$3:$G$1000,판매현황!$C$3:$C$1000,LEFT($B11,3),판매현황!$D$3:$D$1000,$C11,판매현황!$F$3:$F$1000,"전문몰") -> 2 | V11: =SUMIFS(판매현황!$G$3:$G$1000,판매현황!$C$3:$C$1000,LEFT($B11,3),판매현황!$D$3:$D$1000,$C11,판매현황!$F$3:$F$1000,"11번가") -> 0 | W11: =IF(G11<=0,"품절",IF(E11=0,"미판매","판매중")) -> 판매중 | X11: =아트지!G29 -> 5 | Y11: 오픈마켓 판매 아님 | Z11: =SUMIFS(판매현황!$G$3:$G$1000,판매현황!$C$3:$C$1000,LEFT($B11,3),판매현황!$D$3:$D$1000,$C11)-S11-T11-U11-V11 -> 0 | AA11: =E11-F11 -> 85
A12: 8 | B12: 아트지 | C12: 100*60 | D12: 80 | E12: =D12-G12 -> 72 | F12: =S12+T12+U12+V12+Z12 -> 13 | G12: 8 | H12: =COUNTIFS(판매현황!$C$3:$C$1000,LEFT($B12,3),판매현황!$D$3:$D$1000,$C12,판매현황!$G$3:$G$1000,">0") -> 4 | I12: =IF(E12=0,"",F12/E12) -> 0.18055556 | J12: =COUNTIFS($A$5:$A$30,">0",$G$5:$G$30,">"&G12)+1 -> 16 | K12: =COUNTIFS($A$5:$A$30,">0",$E$5:$E$30,">"&E12)+1 -> 3 | L12: 1000 | M12: 3.8 | N12: =L12*M12 -> 3800 | O12: 6500 | P12: =IF(O12="","",ROUNDDOWN(O12*(1+$C$3),-1)) -> 7150 | Q12: =IF(O12="","",O12-O12*$C$2-N12) -> 2349 | R12: =IF(O12="","",Q12/O12) -> 0.36138462 | S12: =SUMIFS(판매현황!$G$3:$G$1000,판매현황!$C$3:$C$1000,LEFT($B12,3),판매현황!$D$3:$D$1000,$C12,판매현황!$F$3:$F$1000,"쿠팡") -> 2 | T12: =SUMIFS(판매현황!$G$3:$G$1000,판매현황!$C$3:$C$1000,LEFT($B12,3),판매현황!$D$3:$D$1000,$C12,판매현황!$F$3:$F$1000,"지마켓") -> 5 | U12: =SUMIFS(판매현황!$G$3:$G$1000,판매현황!$C$3:$C$1000,LEFT($B12,3),판매현황!$D$3:$D$1000,$C12,판매현황!$F$3:$F$1000,"전문몰") -> 6 | V12: =SUMIFS(판매현황!$G$3:$G$1000,판매현황!$C$3:$C$1000,LEFT($B12,3),판매현황!$D$3:$D$1000,$C12,판매현황!$F$3:$F$1000,"11번가") -> 0 | W12: =IF(G12<=0,"품절",IF(E12=0,"미판매","판매중")) -> 판매중 | X12: =아트지!G30 -> 5 | Y12: 지마켓 5롤 + 쿠팡 2롤+전문몰 6롤 | Z12: =SUMIFS(판매현황!$G$3:$G$1000,판매현황!$C$3:$C$1000,LEFT($B12,3),판매현황!$D$3:$D$1000,$C12)-S12-T12-U12-V12 -> 0 | AA12: =E12-F12 -> 59
A13: 9 | B13: 아트지 | C13: 100*70 | D13: 70 | E13: =D13-G13 -> 68 | F13: =S13+T13+U13+V13+Z13 -> 0 | G13: 2 | H13: =COUNTIFS(판매현황!$C$3:$C$1000,LEFT($B13,3),판매현황!$D$3:$D$1000,$C13,판매현황!$G$3:$G$1000,">0") -> 0 | I13: =IF(E13=0,"",F13/E13) -> 0 | J13: =COUNTIFS($A$5:$A$30,">0",$G$5:$G$30,">"&G13)+1 -> 18 | K13: =COUNTIFS($A$5:$A$30,">0",$E$5:$E$30,">"&E13)+1 -> 5 | L13: 850 | M13: 2.3 | N13: =L13*M13 -> 1955 | O13: 9782 | P13: =IF(O13="","",ROUNDDOWN(O13*(1+$C$3),-1)) -> 10760 | Q13: =IF(O13="","",O13-O13*$C$2-N13) -> 7298.772 | R13: =IF(O13="","",Q13/O13) -> 0.74614312 | S13: =SUMIFS(판매현황!$G$3:$G$1000,판매현황!$C$3:$C$1000,LEFT($B13,3),판매현황!$D$3:$D$1000,$C13,판매현황!$F$3:$F$1000,"쿠팡") -> 0 | T13: =SUMIFS(판매현황!$G$3:$G$1000,판매현황!$C$3:$C$1000,LEFT($B13,3),판매현황!$D$3:$D$1000,$C13,판매현황!$F$3:$F$1000,"지마켓") -> 0 | U13: =SUMIFS(판매현황!$G$3:$G$1000,판매현황!$C$3:$C$1000,LEFT($B13,3),판매현황!$D$3:$D$1000,$C13,판매현황!$F$3:$F$1000,"전문몰") -> 0 | V13: =SUMIFS(판매현황!$G$3:$G$1000,판매현황!$C$3:$C$1000,LEFT($B13,3),판매현황!$D$3:$D$1000,$C13,판매현황!$F$3:$F$1000,"11번가") -> 0 | W13: =IF(G13<=0,"품절",IF(E13=0,"미판매","판매중")) -> 판매중 | X13: =아트지!G31 -> 3 | Y13: 오픈마켓 판매 아님 | Z13: =SUMIFS(판매현황!$G$3:$G$1000,판매현황!$C$3:$C$1000,LEFT($B13,3),판매현황!$D$3:$D$1000,$C13)-S13-T13-U13-V13 -> 0 | AA13: =E13-F13 -> 68
A14: 10 | B14: 아트지 | C14: 100*100 | D14: 80 | E14: =D14-G14 -> 50 | F14: =S14+T14+U14+V14+Z14 -> 11 | G14: 30 | H14: =COUNTIFS(판매현황!$C$3:$C$1000,LEFT($B14,3),판매현황!$D$3:$D$1000,$C14,판매현황!$G$3:$G$1000,">0") -> 2 | I14: =IF(E14=0,"",F14/E14) -> 0.22 | J14: =COUNTIFS($A$5:$A$30,">0",$G$5:$G$30,">"&G14)+1 -> 10 | K14: =COUNTIFS($A$5:$A$30,">0",$E$5:$E$30,">"&E14)+1 -> 9 | L14: 500 | M14: 6.1 | N14: =L14*M14 -> 3050 | O14: 7000 | P14: =IF(O14="","",ROUNDDOWN(O14*(1+$C$3),-1)) -> 7700 | Q14: =IF(O14="","",O14-O14*$C$2-N14) -> 3572 | R14: =IF(O14="","",Q14/O14) -> 0.51028571 | S14: =SUMIFS(판매현황!$G$3:$G$1000,판매현황!$C$3:$C$1000,LEFT($B14,3),판매현황!$D$3:$D$1000,$C14,판매현황!$F$3:$F$1000,"쿠팡") -> 0 | T14: =SUMIFS(판매현황!$G$3:$G$1000,판매현황!$C$3:$C$1000,LEFT($B14,3),판매현황!$D$3:$D$1000,$C14,판매현황!$F$3:$F$1000,"지마켓") -> 0 | U14: =SUMIFS(판매현황!$G$3:$G$1000,판매현황!$C$3:$C$1000,LEFT($B14,3),판매현황!$D$3:$D$1000,$C14,판매현황!$F$3:$F$1000,"전문몰") -> 11 | V14: =SUMIFS(판매현황!$G$3:$G$1000,판매현황!$C$3:$C$1000,LEFT($B14,3),판매현황!$D$3:$D$1000,$C14,판매현황!$F$3:$F$1000,"11번가") -> 0 | W14: =IF(G14<=0,"품절",IF(E14=0,"미판매","판매중")) -> 판매중 | X14: =아트지!G32 -> 6 | Y14: 전문몰 11롤 | Z14: =SUMIFS(판매현황!$G$3:$G$1000,판매현황!$C$3:$C$1000,LEFT($B14,3),판매현황!$D$3:$D$1000,$C14)-S14-T14-U14-V14 -> 0 | AA14: =E14-F14 -> 39
B15: 아트지 소계 | D15: =SUM(D5:D14) -> 890 | E15: =SUM(E5:E14) -> 553 | F15: =SUM(F5:F14) -> 71 | G15: =SUM(G5:G14) -> 337 | H15: =SUM(H5:H14) -> 18 | S15: =SUM(S5:S14) -> 20 | T15: =SUM(T5:T14) -> 25 | U15: =SUM(U5:U14) -> 26 | V15: =SUM(V5:V14) -> 0 | Z15: =SUM(Z5:Z14) -> 0 | AA15: =SUM(AA5:AA14) -> 482
A16: 11 | B16: 유포지 | C16: 30*15 | D16: 80 | E16: =D16-G16 -> 12 | F16: =S16+T16+U16+V16+Z16 -> 12 | G16: 68 | H16: =COUNTIFS(판매현황!$C$3:$C$1000,LEFT($B16,3),판매현황!$D$3:$D$1000,$C16,판매현황!$G$3:$G$1000,">0") -> 6 | I16: =IF(E16=0,"",F16/E16) -> 1 | J16: =COUNTIFS($A$5:$A$30,">0",$G$5:$G$30,">"&G16)+1 -> 5 | K16: =COUNTIFS($A$5:$A$30,">0",$E$5:$E$30,">"&E16)+1 -> 21 | L16: 3120 | M16: 0.5 | N16: =L16*M16 -> 1560 | O16: 4564 | P16: =IF(O16="","",ROUNDDOWN(O16*(1+$C$3),-1)) -> 5020 | Q16: =IF(O16="","",O16-O16*$C$2-N16) -> 2757.544 | R16: =IF(O16="","",Q16/O16) -> 0.60419457 | S16: =SUMIFS(판매현황!$G$3:$G$1000,판매현황!$C$3:$C$1000,LEFT($B16,3),판매현황!$D$3:$D$1000,$C16,판매현황!$F$3:$F$1000,"쿠팡") -> 2 | T16: =SUMIFS(판매현황!$G$3:$G$1000,판매현황!$C$3:$C$1000,LEFT($B16,3),판매현황!$D$3:$D$1000,$C16,판매현황!$F$3:$F$1000,"지마켓") -> 0 | U16: =SUMIFS(판매현황!$G$3:$G$1000,판매현황!$C$3:$C$1000,LEFT($B16,3),판매현황!$D$3:$D$1000,$C16,판매현황!$F$3:$F$1000,"전문몰") -> 10 | V16: =SUMIFS(판매현황!$G$3:$G$1000,판매현황!$C$3:$C$1000,LEFT($B16,3),판매현황!$D$3:$D$1000,$C16,판매현황!$F$3:$F$1000,"11번가") -> 0 | W16: =IF(G16<=0,"품절",IF(E16=0,"미판매","판매중")) -> 판매중 | X16: =유포지!G25 -> 5 | Y16: 쿠팡 2롤 + 전문몰 8롤 | Z16: =SUMIFS(판매현황!$G$3:$G$1000,판매현황!$C$3:$C$1000,LEFT($B16,3),판매현황!$D$3:$D$1000,$C16)-S16-T16-U16-V16 -> 0 | AA16: =E16-F16 -> 0
A17: 12 | B17: 유포지 | C17: 40*20 | D17: 80 | E17: =D17-G17 -> 0 | F17: =S17+T17+U17+V17+Z17 -> 0 | G17: 80 | H17: =COUNTIFS(판매현황!$C$3:$C$1000,LEFT($B17,3),판매현황!$D$3:$D$1000,$C17,판매현황!$G$3:$G$1000,">0") -> 0 | I17: =IF(E17=0,"",F17/E17) | J17: =COUNTIFS($A$5:$A$30,">0",$G$5:$G$30,">"&G17)+1 -> 4 | K17: =COUNTIFS($A$5:$A$30,">0",$E$5:$E$30,">"&E17)+1 -> 23 | L17: 2500 | M17: 0.8 | N17: =L17*M17 -> 2000 | O17: 5582 | P17: =IF(O17="","",ROUNDDOWN(O17*(1+$C$3),-1)) -> 6140 | Q17: =IF(O17="","",O17-O17*$C$2-N17) -> 3280.572 | R17: =IF(O17="","",Q17/O17) -> 0.58770548 | S17: =SUMIFS(판매현황!$G$3:$G$1000,판매현황!$C$3:$C$1000,LEFT($B17,3),판매현황!$D$3:$D$1000,$C17,판매현황!$F$3:$F$1000,"쿠팡") -> 0 | T17: =SUMIFS(판매현황!$G$3:$G$1000,판매현황!$C$3:$C$1000,LEFT($B17,3),판매현황!$D$3:$D$1000,$C17,판매현황!$F$3:$F$1000,"지마켓") -> 0 | U17: =SUMIFS(판매현황!$G$3:$G$1000,판매현황!$C$3:$C$1000,LEFT($B17,3),판매현황!$D$3:$D$1000,$C17,판매현황!$F$3:$F$1000,"전문몰") -> 0 | V17: =SUMIFS(판매현황!$G$3:$G$1000,판매현황!$C$3:$C$1000,LEFT($B17,3),판매현황!$D$3:$D$1000,$C17,판매현황!$F$3:$F$1000,"11번가") -> 0 | W17: =IF(G17<=0,"품절",IF(E17=0,"미판매","판매중")) -> 미판매 | X17: =유포지!G26 -> 6 | Z17: =SUMIFS(판매현황!$G$3:$G$1000,판매현황!$C$3:$C$1000,LEFT($B17,3),판매현황!$D$3:$D$1000,$C17)-S17-T17-U17-V17 -> 0 | AA17: =E17-F17 -> 0
A18: 13 | B18: 유포지/품절 | C18: 50*30 | D18: 50 | E18: =D18-G18 -> 50 | F18: =S18+T18+U18+V18+Z18 -> 50 | G18: 0 | H18: =COUNTIFS(판매현황!$C$3:$C$1000,LEFT($B18,3),판매현황!$D$3:$D$1000,$C18,판매현황!$G$3:$G$1000,">0") -> 1 | I18: =IF(E18=0,"",F18/E18) -> 1 | J18: =COUNTIFS($A$5:$A$30,">0",$G$5:$G$30,">"&G18)+1 -> 21 | K18: =COUNTIFS($A$5:$A$30,">0",$E$5:$E$30,">"&E18)+1 -> 9 | L18: 2000 | M18: 1.4 | N18: =L18*M18 -> 2800 | P18: =IF(O18="","",ROUNDDOWN(O18*(1+$C$3),-1)) | Q18: =IF(O18="","",O18-O18*$C$2-N18) | R18: =IF(O18="","",Q18/O18) | S18: =SUMIFS(판매현황!$G$3:$G$1000,판매현황!$C$3:$C$1000,LEFT($B18,3),판매현황!$D$3:$D$1000,$C18,판매현황!$F$3:$F$1000,"쿠팡") -> 0 | T18: =SUMIFS(판매현황!$G$3:$G$1000,판매현황!$C$3:$C$1000,LEFT($B18,3),판매현황!$D$3:$D$1000,$C18,판매현황!$F$3:$F$1000,"지마켓") -> 0 | U18: =SUMIFS(판매현황!$G$3:$G$1000,판매현황!$C$3:$C$1000,LEFT($B18,3),판매현황!$D$3:$D$1000,$C18,판매현황!$F$3:$F$1000,"전문몰") -> 50 | V18: =SUMIFS(판매현황!$G$3:$G$1000,판매현황!$C$3:$C$1000,LEFT($B18,3),판매현황!$D$3:$D$1000,$C18,판매현황!$F$3:$F$1000,"11번가") -> 0 | W18: =IF(G18<=0,"품절",IF(E18=0,"미판매","판매중")) -> 품절 | X18: =유포지!G27 -> 0 | Y18: 전문몰 50롤 | Z18: =SUMIFS(판매현황!$G$3:$G$1000,판매현황!$C$3:$C$1000,LEFT($B18,3),판매현황!$D$3:$D$1000,$C18)-S18-T18-U18-V18 -> 0 | AA18: =E18-F18 -> 0
A19: 14 | B19: 유포지 | C19: 60*40 | D19: 50 | E19: =D19-G19 -> 48 | F19: =S19+T19+U19+V19+Z19 -> 5 | G19: 2 | H19: =COUNTIFS(판매현황!$C$3:$C$1000,LEFT($B19,3),판매현황!$D$3:$D$1000,$C19,판매현황!$G$3:$G$1000,">0") -> 1 | I19: =IF(E19=0,"",F19/E19) -> 0.10416667 | J19: =COUNTIFS($A$5:$A$30,">0",$G$5:$G$30,">"&G19)+1 -> 18 | K19: =COUNTIFS($A$5:$A$30,">0",$E$5:$E$30,">"&E19)+1 -> 12 | L19: 1400 | M19: 2.2 | N19: =L19*M19 -> 3080 | O19: 5255 | P19: =IF(O19="","",ROUNDDOWN(O19*(1+$C$3),-1)) -> 5780 | Q19: =IF(O19="","",O19-O19*$C$2-N19) -> 1891.23 | R19: =IF(O19="","",Q19/O19) -> 0.35989153 | S19: =SUMIFS(판매현황!$G$3:$G$1000,판매현황!$C$3:$C$1000,LEFT($B19,3),판매현황!$D$3:$D$1000,$C19,판매현황!$F$3:$F$1000,"쿠팡") -> 0 | T19: =SUMIFS(판매현황!$G$3:$G$1000,판매현황!$C$3:$C$1000,LEFT($B19,3),판매현황!$D$3:$D$1000,$C19,판매현황!$F$3:$F$1000,"지마켓") -> 0 | U19: =SUMIFS(판매현황!$G$3:$G$1000,판매현황!$C$3:$C$1000,LEFT($B19,3),판매현황!$D$3:$D$1000,$C19,판매현황!$F$3:$F$1000,"전문몰") -> 5 | V19: =SUMIFS(판매현황!$G$3:$G$1000,판매현황!$C$3:$C$1000,LEFT($B19,3),판매현황!$D$3:$D$1000,$C19,판매현황!$F$3:$F$1000,"11번가") -> 0 | W19: =IF(G19<=0,"품절",IF(E19=0,"미판매","판매중")) -> 판매중 | X19: =유포지!G28 -> 6 | Y19: 전문몰 5롤 | Z19: =SUMIFS(판매현황!$G$3:$G$1000,판매현황!$C$3:$C$1000,LEFT($B19,3),판매현황!$D$3:$D$1000,$C19)-S19-T19-U19-V19 -> 0 | AA19: =E19-F19 -> 43
A20: 15 | B20: 유포지 | C20: 70*50 | D20: 60 | E20: =D20-G20 -> 45 | F20: =S20+T20+U20+V20+Z20 -> 12 | G20: 15 | H20: =COUNTIFS(판매현황!$C$3:$C$1000,LEFT($B20,3),판매현황!$D$3:$D$1000,$C20,판매현황!$G$3:$G$1000,">0") -> 5 | I20: =IF(E20=0,"",F20/E20) -> 0.26666667 | J20: =COUNTIFS($A$5:$A$30,">0",$G$5:$G$30,">"&G20)+1 -> 14 | K20: =COUNTIFS($A$5:$A$30,">0",$E$5:$E$30,">"&E20)+1 -> 14 | L20: 1000 | M20: 3.1 | N20: =L20*M20 -> 3100 | O20: 5445 | P20: =IF(O20="","",ROUNDDOWN(O20*(1+$C$3),-1)) -> 5980 | Q20: =IF(O20="","",O20-O20*$C$2-N20) -> 2050.97 | R20: =IF(O20="","",Q20/O20) -> 0.37667034 | S20: =SUMIFS(판매현황!$G$3:$G$1000,판매현황!$C$3:$C$1000,LEFT($B20,3),판매현황!$D$3:$D$1000,$C20,판매현황!$F$3:$F$1000,"쿠팡") -> 1 | T20: =SUMIFS(판매현황!$G$3:$G$1000,판매현황!$C$3:$C$1000,LEFT($B20,3),판매현황!$D$3:$D$1000,$C20,판매현황!$F$3:$F$1000,"지마켓") -> 0 | U20: =SUMIFS(판매현황!$G$3:$G$1000,판매현황!$C$3:$C$1000,LEFT($B20,3),판매현황!$D$3:$D$1000,$C20,판매현황!$F$3:$F$1000,"전문몰") -> 11 | V20: =SUMIFS(판매현황!$G$3:$G$1000,판매현황!$C$3:$C$1000,LEFT($B20,3),판매현황!$D$3:$D$1000,$C20,판매현황!$F$3:$F$1000,"11번가") -> 0 | W20: =IF(G20<=0,"품절",IF(E20=0,"미판매","판매중")) -> 판매중 | X20: =유포지!G29 -> 6 | Y20: 쿠팡 1롤 + 전문몰 6롤 | Z20: =SUMIFS(판매현황!$G$3:$G$1000,판매현황!$C$3:$C$1000,LEFT($B20,3),판매현황!$D$3:$D$1000,$C20)-S20-T20-U20-V20 -> 0 | AA20: =E20-F20 -> 33
A21: 16 | B21: 유포지 | C21: 70*60 | D21: 50 | E21: =D21-G21 -> 0 | F21: =S21+T21+U21+V21+Z21 -> 0 | G21: 50 | H21: =COUNTIFS(판매현황!$C$3:$C$1000,LEFT($B21,3),판매현황!$D$3:$D$1000,$C21,판매현황!$G$3:$G$1000,">0") -> 0 | I21: =IF(E21=0,"",F21/E21) | J21: =COUNTIFS($A$5:$A$30,">0",$G$5:$G$30,">"&G21)+1 -> 6 | K21: =COUNTIFS($A$5:$A$30,">0",$E$5:$E$30,">"&E21)+1 -> 23 | L21: 1000 | M21: 3.7 | N21: =L21*M21 -> 3700 | O21: 6527 | P21: =IF(O21="","",ROUNDDOWN(O21*(1+$C$3),-1)) -> 7170 | Q21: =IF(O21="","",O21-O21*$C$2-N21) -> 2474.542 | R21: =IF(O21="","",Q21/O21) -> 0.37912395 | S21: =SUMIFS(판매현황!$G$3:$G$1000,판매현황!$C$3:$C$1000,LEFT($B21,3),판매현황!$D$3:$D$1000,$C21,판매현황!$F$3:$F$1000,"쿠팡") -> 0 | T21: =SUMIFS(판매현황!$G$3:$G$1000,판매현황!$C$3:$C$1000,LEFT($B21,3),판매현황!$D$3:$D$1000,$C21,판매현황!$F$3:$F$1000,"지마켓") -> 0 | U21: =SUMIFS(판매현황!$G$3:$G$1000,판매현황!$C$3:$C$1000,LEFT($B21,3),판매현황!$D$3:$D$1000,$C21,판매현황!$F$3:$F$1000,"전문몰") -> 0 | V21: =SUMIFS(판매현황!$G$3:$G$1000,판매현황!$C$3:$C$1000,LEFT($B21,3),판매현황!$D$3:$D$1000,$C21,판매현황!$F$3:$F$1000,"11번가") -> 0 | W21: =IF(G21<=0,"품절",IF(E21=0,"미판매","판매중")) -> 미판매 | X21: =유포지!G30 -> 8 | Z21: =SUMIFS(판매현황!$G$3:$G$1000,판매현황!$C$3:$C$1000,LEFT($B21,3),판매현황!$D$3:$D$1000,$C21)-S21-T21-U21-V21 -> 0 | AA21: =E21-F21 -> 0
A22: 17 | B22: 유포지 | C22: 100*35 | D22: 50 | E22: =D22-G22 -> 14 | F22: =S22+T22+U22+V22+Z22 -> 1 | G22: 36 | H22: =COUNTIFS(판매현황!$C$3:$C$1000,LEFT($B22,3),판매현황!$D$3:$D$1000,$C22,판매현황!$G$3:$G$1000,">0") -> 1 | I22: =IF(E22=0,"",F22/E22) -> 0.071428571 | J22: =COUNTIFS($A$5:$A$30,">0",$G$5:$G$30,">"&G22)+1 -> 9 | K22: =COUNTIFS($A$5:$A$30,">0",$E$5:$E$30,">"&E22)+1 -> 20 | L22: 1500 | M22: 3.1 | N22: =L22*M22 -> 4650 | O22: 12891 | P22: =IF(O22="","",ROUNDDOWN(O22*(1+$C$3),-1)) -> 14180 | Q22: =IF(O22="","",O22-O22*$C$2-N22) -> 7544.886 | R22: =IF(O22="","",Q22/O22) -> 0.58528322 | S22: =SUMIFS(판매현황!$G$3:$G$1000,판매현황!$C$3:$C$1000,LEFT($B22,3),판매현황!$D$3:$D$1000,$C22,판매현황!$F$3:$F$1000,"쿠팡") -> 0 | T22: =SUMIFS(판매현황!$G$3:$G$1000,판매현황!$C$3:$C$1000,LEFT($B22,3),판매현황!$D$3:$D$1000,$C22,판매현황!$F$3:$F$1000,"지마켓") -> 0 | U22: =SUMIFS(판매현황!$G$3:$G$1000,판매현황!$C$3:$C$1000,LEFT($B22,3),판매현황!$D$3:$D$1000,$C22,판매현황!$F$3:$F$1000,"전문몰") -> 1 | V22: =SUMIFS(판매현황!$G$3:$G$1000,판매현황!$C$3:$C$1000,LEFT($B22,3),판매현황!$D$3:$D$1000,$C22,판매현황!$F$3:$F$1000,"11번가") -> 0 | W22: =IF(G22<=0,"품절",IF(E22=0,"미판매","판매중")) -> 판매중 | X22: =유포지!G31 -> 4 | Y22: 전문몰 1롤 | Z22: =SUMIFS(판매현황!$G$3:$G$1000,판매현황!$C$3:$C$1000,LEFT($B22,3),판매현황!$D$3:$D$1000,$C22)-S22-T22-U22-V22 -> 0 | AA22: =E22-F22 -> 13
A23: 18 | B23: 유포지/품절 | C23: 100*70 | D23: 55 | E23: =D23-G23 -> 55 | F23: =S23+T23+U23+V23+Z23 -> 2 | G23: 0 | H23: =COUNTIFS(판매현황!$C$3:$C$1000,LEFT($B23,3),판매현황!$D$3:$D$1000,$C23,판매현황!$G$3:$G$1000,">0") -> 2 | I23: =IF(E23=0,"",F23/E23) -> 0.036363636 | J23: =COUNTIFS($A$5:$A$30,">0",$G$5:$G$30,">"&G23)+1 -> 21 | K23: =COUNTIFS($A$5:$A$30,">0",$E$5:$E$30,">"&E23)+1 -> 7 | L23: 850 | M23: 6 | N23: =L23*M23 -> 5100 | O23: 9636 | P23: =IF(O23="","",ROUNDDOWN(O23*(1+$C$3),-1)) -> 10590 | Q23: =IF(O23="","",O23-O23*$C$2-N23) -> 4015.656 | R23: =IF(O23="","",Q23/O23) -> 0.41673474 | S23: =SUMIFS(판매현황!$G$3:$G$1000,판매현황!$C$3:$C$1000,LEFT($B23,3),판매현황!$D$3:$D$1000,$C23,판매현황!$F$3:$F$1000,"쿠팡") -> 1 | T23: =SUMIFS(판매현황!$G$3:$G$1000,판매현황!$C$3:$C$1000,LEFT($B23,3),판매현황!$D$3:$D$1000,$C23,판매현황!$F$3:$F$1000,"지마켓") -> 0 | U23: =SUMIFS(판매현황!$G$3:$G$1000,판매현황!$C$3:$C$1000,LEFT($B23,3),판매현황!$D$3:$D$1000,$C23,판매현황!$F$3:$F$1000,"전문몰") -> 1 | V23: =SUMIFS(판매현황!$G$3:$G$1000,판매현황!$C$3:$C$1000,LEFT($B23,3),판매현황!$D$3:$D$1000,$C23,판매현황!$F$3:$F$1000,"11번가") -> 0 | W23: =IF(G23<=0,"품절",IF(E23=0,"미판매","판매중")) -> 품절 | X23: =유포지!G32 -> 8 | Y23: 전문몰 1롤 + 쿠팡 1롤 | Z23: =SUMIFS(판매현황!$G$3:$G$1000,판매현황!$C$3:$C$1000,LEFT($B23,3),판매현황!$D$3:$D$1000,$C23)-S23-T23-U23-V23 -> 0 | AA23: =E23-F23 -> 53
A24: 19 | B24: 유포지 | C24: 100*80 | D24: 50 | E24: =D24-G24 -> 42 | F24: =S24+T24+U24+V24+Z24 -> 19 | G24: 8 | H24: =COUNTIFS(판매현황!$C$3:$C$1000,LEFT($B24,3),판매현황!$D$3:$D$1000,$C24,판매현황!$G$3:$G$1000,">0") -> 1 | I24: =IF(E24=0,"",F24/E24) -> 0.45238095 | J24: =COUNTIFS($A$5:$A$30,">0",$G$5:$G$30,">"&G24)+1 -> 16 | K24: =COUNTIFS($A$5:$A$30,">0",$E$5:$E$30,">"&E24)+1 -> 15 | L24: 700 | M24: 7 | N24: =L24*M24 -> 4900 | O24: 8118 | P24: =IF(O24="","",ROUNDDOWN(O24*(1+$C$3),-1)) -> 8920 | Q24: =IF(O24="","",O24-O24*$C$2-N24) -> 2779.628 | R24: =IF(O24="","",Q24/O24) -> 0.34240305 | S24: =SUMIFS(판매현황!$G$3:$G$1000,판매현황!$C$3:$C$1000,LEFT($B24,3),판매현황!$D$3:$D$1000,$C24,판매현황!$F$3:$F$1000,"쿠팡") -> 0 | T24: =SUMIFS(판매현황!$G$3:$G$1000,판매현황!$C$3:$C$1000,LEFT($B24,3),판매현황!$D$3:$D$1000,$C24,판매현황!$F$3:$F$1000,"지마켓") -> 19 | U24: =SUMIFS(판매현황!$G$3:$G$1000,판매현황!$C$3:$C$1000,LEFT($B24,3),판매현황!$D$3:$D$1000,$C24,판매현황!$F$3:$F$1000,"전문몰") -> 0 | V24: =SUMIFS(판매현황!$G$3:$G$1000,판매현황!$C$3:$C$1000,LEFT($B24,3),판매현황!$D$3:$D$1000,$C24,판매현황!$F$3:$F$1000,"11번가") -> 0 | W24: =IF(G24<=0,"품절",IF(E24=0,"미판매","판매중")) -> 판매중 | X24: =유포지!G33 -> 8 | Y24: 지마켓 19롤 | Z24: =SUMIFS(판매현황!$G$3:$G$1000,판매현황!$C$3:$C$1000,LEFT($B24,3),판매현황!$D$3:$D$1000,$C24)-S24-T24-U24-V24 -> 0 | AA24: =E24-F24 -> 23
A25: 20 | B25: 유포지 | C25: 100*90 | D25: 50 | E25: =D25-G25 -> 23 | F25: =S25+T25+U25+V25+Z25 -> 3 | G25: 27 | H25: =COUNTIFS(판매현황!$C$3:$C$1000,LEFT($B25,3),판매현황!$D$3:$D$1000,$C25,판매현황!$G$3:$G$1000,">0") -> 2 | I25: =IF(E25=0,"",F25/E25) -> 0.13043478 | J25: =COUNTIFS($A$5:$A$30,">0",$G$5:$G$30,">"&G25)+1 -> 12 | K25: =COUNTIFS($A$5:$A$30,">0",$E$5:$E$30,">"&E25)+1 -> 17 | L25: 625 | M25: 7.9 | N25: =L25*M25 -> 4937.5 | O25: 12664 | P25: =IF(O25="","",ROUNDDOWN(O25*(1+$C$3),-1)) -> 13930 | Q25: =IF(O25="","",O25-O25*$C$2-N25) -> 7042.644 | R25: =IF(O25="","",Q25/O25) -> 0.55611529 | S25: =SUMIFS(판매현황!$G$3:$G$1000,판매현황!$C$3:$C$1000,LEFT($B25,3),판매현황!$D$3:$D$1000,$C25,판매현황!$F$3:$F$1000,"쿠팡") -> 1 | T25: =SUMIFS(판매현황!$G$3:$G$1000,판매현황!$C$3:$C$1000,LEFT($B25,3),판매현황!$D$3:$D$1000,$C25,판매현황!$F$3:$F$1000,"지마켓") -> 0 | U25: =SUMIFS(판매현황!$G$3:$G$1000,판매현황!$C$3:$C$1000,LEFT($B25,3),판매현황!$D$3:$D$1000,$C25,판매현황!$F$3:$F$1000,"전문몰") -> 2 | V25: =SUMIFS(판매현황!$G$3:$G$1000,판매현황!$C$3:$C$1000,LEFT($B25,3),판매현황!$D$3:$D$1000,$C25,판매현황!$F$3:$F$1000,"11번가") -> 0 | W25: =IF(G25<=0,"품절",IF(E25=0,"미판매","판매중")) -> 판매중 | X25: =유포지!G34 -> 4 | Y25: 쿠팡 1롤 + 전문몰 2롤 | Z25: =SUMIFS(판매현황!$G$3:$G$1000,판매현황!$C$3:$C$1000,LEFT($B25,3),판매현황!$D$3:$D$1000,$C25)-S25-T25-U25-V25 -> 0 | AA25: =E25-F25 -> 20
A26: 21 | B26: 유포지/품절 | C26: 100*100 | D26: 67 | E26: =D26-G26 -> 67 | F26: =S26+T26+U26+V26+Z26 -> 14 | G26: 0 | H26: =COUNTIFS(판매현황!$C$3:$C$1000,LEFT($B26,3),판매현황!$D$3:$D$1000,$C26,판매현황!$G$3:$G$1000,">0") -> 5 | I26: =IF(E26=0,"",F26/E26) -> 0.20895522 | J26: =COUNTIFS($A$5:$A$30,">0",$G$5:$G$30,">"&G26)+1 -> 21 | K26: =COUNTIFS($A$5:$A$30,">0",$E$5:$E$30,">"&E26)+1 -> 6 | L26: 500 | M26: 8.4 | N26: =L26*M26 -> 4200 | O26: 7727 | P26: =IF(O26="","",ROUNDDOWN(O26*(1+$C$3),-1)) -> 8490 | Q26: =IF(O26="","",O26-O26*$C$2-N26) -> 3109.742 | R26: =IF(O26="","",Q26/O26) -> 0.4024514 | S26: =SUMIFS(판매현황!$G$3:$G$1000,판매현황!$C$3:$C$1000,LEFT($B26,3),판매현황!$D$3:$D$1000,$C26,판매현황!$F$3:$F$1000,"쿠팡") -> 0 | T26: =SUMIFS(판매현황!$G$3:$G$1000,판매현황!$C$3:$C$1000,LEFT($B26,3),판매현황!$D$3:$D$1000,$C26,판매현황!$F$3:$F$1000,"지마켓") -> 0 | U26: =SUMIFS(판매현황!$G$3:$G$1000,판매현황!$C$3:$C$1000,LEFT($B26,3),판매현황!$D$3:$D$1000,$C26,판매현황!$F$3:$F$1000,"전문몰") -> 14 | V26: =SUMIFS(판매현황!$G$3:$G$1000,판매현황!$C$3:$C$1000,LEFT($B26,3),판매현황!$D$3:$D$1000,$C26,판매현황!$F$3:$F$1000,"11번가") -> 0 | W26: =IF(G26<=0,"품절",IF(E26=0,"미판매","판매중")) -> 품절 | X26: =유포지!G35 -> 9 | Y26: 전문몰 14롤 | Z26: =SUMIFS(판매현황!$G$3:$G$1000,판매현황!$C$3:$C$1000,LEFT($B26,3),판매현황!$D$3:$D$1000,$C26)-S26-T26-U26-V26 -> 0 | AA26: =E26-F26 -> 53
A27: 22 | B27: 유포지 | C27: 100*150 | D27: 50 | E27: =D27-G27 -> 48 | F27: =S27+T27+U27+V27+Z27 -> 5 | G27: 2 | H27: =COUNTIFS(판매현황!$C$3:$C$1000,LEFT($B27,3),판매현황!$D$3:$D$1000,$C27,판매현황!$G$3:$G$1000,">0") -> 1 | I27: =IF(E27=0,"",F27/E27) -> 0.10416667 | J27: =COUNTIFS($A$5:$A$30,">0",$G$5:$G$30,">"&G27)+1 -> 18 | K27: =COUNTIFS($A$5:$A$30,">0",$E$5:$E$30,">"&E27)+1 -> 12 | L27: 400 | M27: 12.6 | N27: =L27*M27 -> 5040 | O27: 9273 | P27: =IF(O27="","",ROUNDDOWN(O27*(1+$C$3),-1)) -> 10200 | Q27: =IF(O27="","",O27-O27*$C$2-N27) -> 3732.258 | R27: =IF(O27="","",Q27/O27) -> 0.40248657 | S27: =SUMIFS(판매현황!$G$3:$G$1000,판매현황!$C$3:$C$1000,LEFT($B27,3),판매현황!$D$3:$D$1000,$C27,판매현황!$F$3:$F$1000,"쿠팡") -> 0 | T27: =SUMIFS(판매현황!$G$3:$G$1000,판매현황!$C$3:$C$1000,LEFT($B27,3),판매현황!$D$3:$D$1000,$C27,판매현황!$F$3:$F$1000,"지마켓") -> 0 | U27: =SUMIFS(판매현황!$G$3:$G$1000,판매현황!$C$3:$C$1000,LEFT($B27,3),판매현황!$D$3:$D$1000,$C27,판매현황!$F$3:$F$1000,"전문몰") -> 5 | V27: =SUMIFS(판매현황!$G$3:$G$1000,판매현황!$C$3:$C$1000,LEFT($B27,3),판매현황!$D$3:$D$1000,$C27,판매현황!$F$3:$F$1000,"11번가") -> 0 | W27: =IF(G27<=0,"품절",IF(E27=0,"미판매","판매중")) -> 판매중 | X27: =유포지!G36 -> 7 | Y27: 전문몰 5롤 | Z27: =SUMIFS(판매현황!$G$3:$G$1000,판매현황!$C$3:$C$1000,LEFT($B27,3),판매현황!$D$3:$D$1000,$C27)-S27-T27-U27-V27 -> 0 | AA27: =E27-F27 -> 43
B28: 유포지 소계 | D28: =SUM(D16:D27) -> 692 | E28: =SUM(E16:E27) -> 404 | F28: =SUM(F16:F27) -> 123 | G28: =SUM(G16:G27) -> 288 | H28: =SUM(H16:H27) -> 25 | S28: =SUM(S16:S27) -> 5 | T28: =SUM(T16:T27) -> 19 | U28: =SUM(U16:U27) -> 99 | V28: =SUM(V16:V27) -> 0 | Z28: =SUM(Z16:Z27) -> 0 | AA28: =SUM(AA16:AA27) -> 281
A29: 23 | B29: 감열지 | C29: 80*70 | D29: 56 | E29: =D29-G29 -> 16 | F29: =S29+T29+U29+V29+Z29 -> 11 | G29: 40 | H29: =COUNTIFS(판매현황!$C$3:$C$1000,LEFT($B29,3),판매현황!$D$3:$D$1000,$C29,판매현황!$G$3:$G$1000,">0") -> 2 | I29: =IF(E29=0,"",F29/E29) -> 0.6875 | J29: =COUNTIFS($A$5:$A$30,">0",$G$5:$G$30,">"&G29)+1 -> 8 | K29: =COUNTIFS($A$5:$A$30,">0",$E$5:$E$30,">"&E29)+1 -> 18 | L29: 900 | M29: 5.2 | N29: =L29*M29 -> 4680 | O29: 5090 | P29: =IF(O29="","",ROUNDDOWN(O29*(1+$C$3),-1)) -> 5590 | Q29: =IF(O29="","",O29-O29*$C$2-N29) -> 135.14 | R29: =IF(O29="","",Q29/O29) -> 0.026550098 | S29: =SUMIFS(판매현황!$G$3:$G$1000,판매현황!$C$3:$C$1000,LEFT($B29,3),판매현황!$D$3:$D$1000,$C29,판매현황!$F$3:$F$1000,"쿠팡") -> 11 | T29: =SUMIFS(판매현황!$G$3:$G$1000,판매현황!$C$3:$C$1000,LEFT($B29,3),판매현황!$D$3:$D$1000,$C29,판매현황!$F$3:$F$1000,"지마켓") -> 0 | U29: =SUMIFS(판매현황!$G$3:$G$1000,판매현황!$C$3:$C$1000,LEFT($B29,3),판매현황!$D$3:$D$1000,$C29,판매현황!$F$3:$F$1000,"전문몰") -> 0 | V29: =SUMIFS(판매현황!$G$3:$G$1000,판매현황!$C$3:$C$1000,LEFT($B29,3),판매현황!$D$3:$D$1000,$C29,판매현황!$F$3:$F$1000,"11번가") -> 0 | W29: =IF(G29<=0,"품절",IF(E29=0,"미판매","판매중")) -> 판매중 | X29: ="" | Y29: 쿠팡 1롤 | Z29: =SUMIFS(판매현황!$G$3:$G$1000,판매현황!$C$3:$C$1000,LEFT($B29,3),판매현황!$D$3:$D$1000,$C29)-S29-T29-U29-V29 -> 0 | AA29: =E29-F29 -> 5
A30: 24 | B30: 감열지 | C30: 100*100 | D30: 360 | E30: =D30-G30 -> 31 | F30: =S30+T30+U30+V30+Z30 -> 23 | G30: 329 | H30: =COUNTIFS(판매현황!$C$3:$C$1000,LEFT($B30,3),판매현황!$D$3:$D$1000,$C30,판매현황!$G$3:$G$1000,">0") -> 3 | I30: =IF(E30=0,"",F30/E30) -> 0.74193548 | J30: =COUNTIFS($A$5:$A$30,">0",$G$5:$G$30,">"&G30)+1 -> 1 | K30: =COUNTIFS($A$5:$A$30,">0",$E$5:$E$30,">"&E30)+1 -> 16 | L30: 500 | M30: 9.7 | N30: =L30*M30 -> 4850 | O30: 6870 | P30: =IF(O30="","",ROUNDDOWN(O30*(1+$C$3),-1)) -> 7550 | Q30: =IF(O30="","",O30-O30*$C$2-N30) -> 1649.02 | R30: =IF(O30="","",Q30/O30) -> 0.24003202 | S30: =SUMIFS(판매현황!$G$3:$G$1000,판매현황!$C$3:$C$1000,LEFT($B30,3),판매현황!$D$3:$D$1000,$C30,판매현황!$F$3:$F$1000,"쿠팡") -> 0 | T30: =SUMIFS(판매현황!$G$3:$G$1000,판매현황!$C$3:$C$1000,LEFT($B30,3),판매현황!$D$3:$D$1000,$C30,판매현황!$F$3:$F$1000,"지마켓") -> 17 | U30: =SUMIFS(판매현황!$G$3:$G$1000,판매현황!$C$3:$C$1000,LEFT($B30,3),판매현황!$D$3:$D$1000,$C30,판매현황!$F$3:$F$1000,"전문몰") -> 0 | V30: =SUMIFS(판매현황!$G$3:$G$1000,판매현황!$C$3:$C$1000,LEFT($B30,3),판매현황!$D$3:$D$1000,$C30,판매현황!$F$3:$F$1000,"11번가") -> 0 | W30: =IF(G30<=0,"품절",IF(E30=0,"미판매","판매중")) -> 판매중 | X30: ="" | Y30: 지마켓 16롤 | Z30: =SUMIFS(판매현황!$G$3:$G$1000,판매현황!$C$3:$C$1000,LEFT($B30,3),판매현황!$D$3:$D$1000,$C30)-S30-T30-U30-V30 -> 6 | AA30: =E30-F30 -> 8
B31: 감열지 소계 | D31: =SUM(D29:D30) -> 416 | E31: =SUM(E29:E30) -> 47 | F31: =SUM(F29:F30) -> 34 | G31: =SUM(G29:G30) -> 369 | H31: =SUM(H29:H30) -> 5 | P31: =E31/D31 -> 0.11298077 | S31: =SUM(S29:S30) -> 11 | T31: =SUM(T29:T30) -> 17 | U31: =SUM(U29:U30) -> 0 | V31: =SUM(V29:V30) -> 0 | Z31: =SUM(Z29:Z30) -> 6 | AA31: =SUM(AA29:AA30) -> 13
B32: 전체 합계 | D32: =D15+D28+D31 -> 1998 | E32: =E15+E28+E31 -> 1004 | F32: =F15+F28+F31 -> 228 | G32: =G15+G28+G31 -> 994 | H32: =H15+H28+H31 -> 48 | S32: =S15+S28+S31 -> 36 | T32: =T15+T28+T31 -> 61 | U32: =U15+U28+U31 -> 125 | V32: =V15+V28+V31 -> 0 | Z32: =Z15+Z28+Z31 -> 6 | AA32: =AA15+AA28+AA31 -> 776
A33: 계산 방법: 재고(G, 파란 글씨) = 실재고(재고 프로그램 10/7) 입력 · 전체판매(E) = 입고(D) − 재고(G) · 채널별 판매(S~V, Z) = 판매현황 시트에서 재질·규격·판매처가 같은 수량 합계 · 오픈마켓 판매 합계(F) = 쿠팡+지마켓+전문몰+11번가+기타몰 · 일반 판매(AA) = 전체판매(E) − 오픈마켓 판매(F)
A34: 재고가 바뀌면 G열만 새 실재고로 고치고, 오픈마켓 판매는 판매현황 시트에 한 줄씩 추가하면 됩니다. 일반 판매(AA)가 빨갛게(음수) 나오면 판매현황 기록이 실재고보다 많다는 뜻이니 기록을 확인하세요. 원가(N) = 롤당 수량 × 장당 원가 · 등록가(P) = 판매가 × 1.1 (10원 미만 버림) · 이익(Q) = 판매가 − 판매가×수수료율 − 원가 · 마진율(R) = 이익 ÷ 판매가
A36: 라벨별 오픈마켓 판매 (롤)
A37: No | B37: 재질 | C37: 규격 | D37: 쿠팡 | E37: 지마켓 | F37: 11번가 | G37: 전문몰 | H37: 기타몰 | I37: 총 출고(롤)
A38: =A5 -> 1 | B38: =B5 -> 아트지 | C38: =C5 -> 35*20 | D38: =S5 -> 0 | E38: =T5 -> 0 | F38: =V5 -> 0 | G38: =U5 -> 0 | H38: =Z5 -> 0 | I38: =E5 -> 16
A39: =A6 -> 2 | B39: =B6 -> 아트지 | C39: =C6 -> 40*20 | D39: =S6 -> 12 | E39: =T6 -> 0 | F39: =V6 -> 0 | G39: =U6 -> 2 | H39: =Z6 -> 0 | I39: =E6 -> 71
A40: =A7 -> 3 | B40: =B7 -> 아트지 | C40: =C7 -> 50*30 | D40: =S7 -> 0 | E40: =T7 -> 0 | F40: =V7 -> 0 | G40: =U7 -> 0 | H40: =Z7 -> 0 | I40: =E7 -> 78
A41: =A8 -> 4 | B41: =B8 -> 아트지 | C41: =C8 -> 50*50 | D41: =S8 -> 2 | E41: =T8 -> 20 | F41: =V8 -> 0 | G41: =U8 -> 0 | H41: =Z8 -> 0 | I41: =E8 -> 52
...

Sheet 아트지
A1: 아트지 전체현황
A3: 규격 | B3: 입고수량 | C3: 전체판매수량 | D3: 재고수량 | E3: 오픈마켓판매수량 | F3: 기타채널판매수량 | G3: 판매가 (부가세별도) | H3: 판매가 (부가세포함) | I3: 마진율 | T3: 오픈마켓 판매건수 (판매현황 기준)
A4: =마스터!C8 -> 50*50 | B4: =마스터!D8 -> 70 | C4: =마스터!E8 -> 52 | D4: =마스터!G8 -> 18 | E4: =마스터!F8 -> 22 | F4: =마스터!E8-마스터!F8 -> 30 | G4: =IF(ISBLANK(마스터!O8),"미기재",마스터!O8) -> 3500 | H4: =IF(마스터!P8="","미기재",마스터!P8) -> 3850 | I4: =IF(마스터!R8="","계산불가",마스터!R8) -> 0.43171429 | T4: 3건(22롤)
A5: =마스터!C14 -> 100*100 | B5: =마스터!D14 -> 80 | C5: =마스터!E14 -> 50 | D5: =마스터!G14 -> 30 | E5: =마스터!F14 -> 11 | F5: =마스터!E14-마스터!F14 -> 39 | G5: =IF(ISBLANK(마스터!O14),"미기재",마스터!O14) -> 7000 | H5: =IF(마스터!P14="","미기재",마스터!P14) -> 7700 | I5: =IF(마스터!R14="","계산불가",마스터!R14) -> 0.51028571 | T5: 2건(11롤)
A6: =마스터!C9 -> 60*40 | B6: =마스터!D9 -> 100 | C6: =마스터!E9 -> 9 | D6: =마스터!G9 -> 91 | E6: =마스터!F9 -> 9 | F6: =마스터!E9-마스터!F9 -> 0 | G6: =IF(ISBLANK(마스터!O9),"미기재",마스터!O9) -> 4482 | H6: =IF(마스터!P9="","미기재",마스터!P9) -> 4930 | I6: =IF(마스터!R9="","계산불가",마스터!R9) -> 0.44622311 | T6: 2건(2롤)
A7: =마스터!C12 -> 100*60 | B7: =마스터!D12 -> 80 | C7: =마스터!E12 -> 72 | D7: =마스터!G12 -> 8 | E7: =마스터!F12 -> 13 | F7: =마스터!E12-마스터!F12 -> 59 | G7: =IF(ISBLANK(마스터!O12),"미기재",마스터!O12) -> 6500 | H7: =IF(마스터!P12="","미기재",마스터!P12) -> 7150 | I7: =IF(마스터!R12="","계산불가",마스터!R12) -> 0.36138462 | T7: 4건(13롤)
A8: =마스터!C7 -> 50*30 | B8: =마스터!D7 -> 120 | C8: =마스터!E7 -> 78 | D8: =마스터!G7 -> 42 | E8: =마스터!F7 -> 0 | F8: =마스터!E7-마스터!F7 -> 78 | G8: =IF(ISBLANK(마스터!O7),"미기재",마스터!O7) -> 4000 | H8: =IF(마스터!P7="","미기재",마스터!P7) -> 4400 | I8: =IF(마스터!R7="","계산불가",마스터!R7) -> 0.496 | T8: 0건
A9: =마스터!C5 -> 35*20 | B9: =마스터!D5 -> 120 | C9: =마스터!E5 -> 16 | D9: =마스터!G5 -> 104 | E9: =마스터!F5 -> 0 | F9: =마스터!E5-마스터!F5 -> 16 | G9: =IF(ISBLANK(마스터!O5),"미기재",마스터!O5) -> 2500 | H9: =IF(마스터!P5="","미기재",마스터!P5) -> 2750 | I9: =IF(마스터!R5="","계산불가",마스터!R5) -> 0.346 | T9: 0건
A10: =마스터!C11 -> 80*60 | B10: =마스터!D11 -> 100 | C10: =마스터!E11 -> 87 | D10: =마스터!G11 -> 13 | E10: =마스터!F11 -> 2 | F10: =마스터!E11-마스터!F11 -> 85 | G10: =IF(ISBLANK(마스터!O11),"미기재",마스터!O11) -> 6500 | H10: =IF(마스터!P11="","미기재",마스터!P11) -> 7150 | I10: =IF(마스터!R11="","계산불가",마스터!R11) -> 0.46907692 | T10: 1건(1롤)
A11: =마스터!C6 -> 40*20 | B11: =마스터!D6 -> 100 | C11: =마스터!E6 -> 71 | D11: =마스터!G6 -> 29 | E11: =마스터!F6 -> 14 | F11: =마스터!E6-마스터!F6 -> 57 | G11: =IF(ISBLANK(마스터!O6),"미기재",마스터!O6) -> 2500 | H11: =IF(마스터!P6="","미기재",마스터!P6) -> 2750 | I11: =IF(마스터!R6="","계산불가",마스터!R6) -> 0.346 | T11: 1건(2롤)
A12: =마스터!C10 -> 70*40 | B12: =마스터!D10 -> 50 | C12: =마스터!E10 -> 50 | D12: =마스터!G10 -> 0 | E12: =마스터!F10 -> 0 | F12: =마스터!E10-마스터!F10 -> 50 | G12: =IF(ISBLANK(마스터!O10),"미기재",마스터!O10) -> 미기재 | H12: =IF(마스터!P10="","미기재",마스터!P10) -> 미기재 | I12: =IF(마스터!R10="","계산불가",마스터!R10) -> 계산불가 | T12: 1건(0롤)
A13: =마스터!C13 -> 100*70 | B13: =마스터!D13 -> 70 | C13: =마스터!E13 -> 68 | D13: =마스터!G13 -> 2 | E13: =마스터!F13 -> 0 | F13: =마스터!E13-마스터!F13 -> 68 | G13: =IF(ISBLANK(마스터!O13),"미기재",마스터!O13) -> 9782 | H13: =IF(마스터!P13="","미기재",마스터!P13) -> 10760 | I13: =IF(마스터!R13="","계산불가",마스터!R13) -> 0.74614312 | T13: 1건(0롤)
A14: 합계 | B14: =SUM(B4:B13) -> 890 | C14: =SUM(C4:C13) -> 553 | D14: =SUM(D4:D13) -> 337 | E14: =SUM(E4:E13) -> 71 | F14: =SUM(F4:F13) -> 482 | T14: 16건
A17: 라벨별 옵션 구성 — 각 라벨을 대표가(기준)로 잡았을 때 옵션으로 함께 넣을 수 있는 사이즈 종류·개수
A18: 옵션추가금액 하한(대표가 대비) | F18: -0.5
A19: 옵션추가금액 상한(대표가 대비) | F19: 1
A20: 품절(재고 0) 사이즈 옵션 제외 (1=제외, 0=포함) | F20: 1
A22: No | B22: 재질 | C22: 규격 | D22: 대표가 (부가세 포함) | E22: 옵션가 하한 (최소 판매가) | F22: 옵션가 상한 (최대 판매가) | G22: 옵션 가능 수 (개) | H22: 옵션 종류 (옵션추가금액) | K22: =마스터!C14 -> 100*100 | L22: =마스터!C9 -> 60*40 | M22: =마스터!C12 -> 100*60 | N22: =마스터!C7 -> 50*30 | O22: =마스터!C5 -> 35*20 | P22: =마스터!C11 -> 80*60 | Q22: =마스터!C6 -> 40*20 | R22: =마스터!C10 -> 70*40 | S22: =마스터!C13 -> 100*70
A23: =마스터!A5 -> 1 | B23: =마스터!B5 -> 아트지 | C23: =마스터!C5 -> 35*20 | D23: =마스터!P5 -> 2750 | E23: =IF(ISNUMBER(D23),ROUNDDOWN(D23*(1+$F$18),-1),"") -> 1370 | F23: =IF(ISNUMBER(D23),ROUNDDOWN(D23*(1+$F$19),-1),"") -> 5500 | G23: =SUMPRODUCT(--(LEN(J23:AF23)>0)) -> 3 | H23: =IF(G23>0,_xlfn.TEXTJOIN(", ",TRUE(),J23:AF23),IF(ISNUMBER(D23),"옵션 가능한 사이즈 없음","가격 미정 — 판매가 입력 필요")) -> 60*40(+2,180), 50*30(+1,650), 40*20(+0) | K23: =IF(OR(NOT(ISNUMBER($E23)),NOT(ISNUMBER(마스터!$P$14))),"",IF(AND(마스터!$P$14>=$E23,마스터!$P$14<=$F23,OR($F$20=0,마스터!$G$14>0)),마스터!$C$14&"("&IF(마스터!$P$14-$D23>=0,"+","")&TEXT(마스터!$P$14-$D23,"#,##0")&")","")) | L23: =IF(OR(NOT(ISNUMBER($E23)),NOT(ISNUMBER(마스터!$P$9))),"",IF(AND(마스터!$P$9>=$E23,마스터!$P$9<=$F23,OR($F$20=0,마스터!$G$9>0)),마스터!$C$9&"("&IF(마스터!$P$9-$D23>=0,"+","")&TEXT(마스터!$P$9-$D23,"#,##0")&")","")) -> 60*40(+2,180) | M23: =IF(OR(NOT(ISNUMBER($E23)),NOT(ISNUMBER(마스터!$P$12))),"",IF(AND(마스터!$P$12>=$E23,마스터!$P$12<=$F23,OR($F$20=0,마스터!$G$12>0)),마스터!$C$12&"("&IF(마스터!$P$12-$D23>=0,"+","")&TEXT(마스터!$P$12-$D23,"#,##0")&")","")) | N23: =IF(OR(NOT(ISNUMBER($E23)),NOT(ISNUMBER(마스터!$P$7))),"",IF(AND(마스터!$P$7>=$E23,마스터!$P$7<=$F23,OR($F$20=0,마스터!$G$7>0)),마스터!$C$7&"("&IF(마스터!$P$7-$D23>=0,"+","")&TEXT(마스터!$P$7-$D23,"#,##0")&")","")) -> 50*30(+1,650) | P23: =IF(OR(NOT(ISNUMBER($E23)),NOT(ISNUMBER(마스터!$P$11))),"",IF(AND(마스터!$P$11>=$E23,마스터!$P$11<=$F23,OR($F$20=0,마스터!$G$11>0)),마스터!$C$11&"("&IF(마스터!$P$11-$D23>=0,"+","")&TEXT(마스터!$P$11-$D23,"#,##0")&")","")) | Q23: =IF(OR(NOT(ISNUMBER($E23)),NOT(ISNUMBER(마스터!$P$6))),"",IF(AND(마스터!$P$6>=$E23,마스터!$P$6<=$F23,OR($F$20=0,마스터!$G$6>0)),마스터!$C$6&"("&IF(마스터!$P$6-$D23>=0,"+","")&TEXT(마스터!$P$6-$D23,"#,##0")&")","")) -> 40*20(+0) | R23: =IF(OR(NOT(ISNUMBER($E23)),NOT(ISNUMBER(마스터!$P$10))),"",IF(AND(마스터!$P$10>=$E23,마스터!$P$10<=$F23,OR($F$20=0,마스터!$G$10>0)),마스터!$C$10&"("&IF(마스터!$P$10-$D23>=0,"+","")&TEXT(마스터!$P$10-$D23,"#,##0")&")","")) | S23: =IF(OR(NOT(ISNUMBER($E23)),NOT(ISNUMBER(마스터!$P$13))),"",IF(AND(마스터!$P$13>=$E23,마스터!$P$13<=$F23,OR($F$20=0,마스터!$G$13>0)),마스터!$C$13&"("&IF(마스터!$P$13-$D23>=0,"+","")&TEXT(마스터!$P$13-$D23,"#,##0")&")",""))
A24: =마스터!A6 -> 2 | B24: =마스터!B6 -> 아트지 | C24: =마스터!C6 -> 40*20 | D24: =마스터!P6 -> 2750 | E24: =IF(ISNUMBER(D24),ROUNDDOWN(D24*(1+$F$18),-1),"") -> 1370 | F24: =IF(ISNUMBER(D24),ROUNDDOWN(D24*(1+$F$19),-1),"") -> 5500 | G24: =SUMPRODUCT(--(LEN(J24:AF24)>0)) -> 4 | H24: =IF(G24>0,_xlfn.TEXTJOIN(", ",TRUE(),J24:AF24),IF(ISNUMBER(D24),"옵션 가능한 사이즈 없음","가격 미정 — 판매가 입력 필요")) -> 60*40(+2,180), 50*30(+1,650), 35*20(+0), 50*50 | K24: =IF(OR(NOT(ISNUMBER($E24)),NOT(ISNUMBER(마스터!$P$14))),"",IF(AND(마스터!$P$14>=$E24,마스터!$P$14<=$F24,OR($F$20=0,마스터!$G$14>0)),마스터!$C$14&"("&IF(마스터!$P$14-$D24>=0,"+","")&TEXT(마스터!$P$14-$D24,"#,##0")&")","")) | L24: =IF(OR(NOT(ISNUMBER($E24)),NOT(ISNUMBER(마스터!$P$9))),"",IF(AND(마스터!$P$9>=$E24,마스터!$P$9<=$F24,OR($F$20=0,마스터!$G$9>0)),마스터!$C$9&"("&IF(마스터!$P$9-$D24>=0,"+","")&TEXT(마스터!$P$9-$D24,"#,##0")&")","")) -> 60*40(+2,180) | M24: =IF(OR(NOT(ISNUMBER($E24)),NOT(ISNUMBER(마스터!$P$12))),"",IF(AND(마스터!$P$12>=$E24,마스터!$P$12<=$F24,OR($F$20=0,마스터!$G$12>0)),마스터!$C$12&"("&IF(마스터!$P$12-$D24>=0,"+","")&TEXT(마스터!$P$12-$D24,"#,##0")&")","")) | N24: =IF(OR(NOT(ISNUMBER($E24)),NOT(ISNUMBER(마스터!$P$7))),"",IF(AND(마스터!$P$7>=$E24,마스터!$P$7<=$F24,OR($F$20=0,마스터!$G$7>0)),마스터!$C$7&"("&IF(마스터!$P$7-$D24>=0,"+","")&TEXT(마스터!$P$7-$D24,"#,##0")&")","")) -> 50*30(+1,650) | O24: =IF(OR(NOT(ISNUMBER($E24)),NOT(ISNUMBER(마스터!$P$5))),"",IF(AND(마스터!$P$5>=$E24,마스터!$P$5<=$F24,OR($F$20=0,마스터!$G$5>0)),마스터!$C$5&"("&IF(마스터!$P$5-$D24>=0,"+","")&TEXT(마스터!$P$5-$D24,"#,##0")&")","")) -> 35*20(+0) | P24: =IF(OR(NOT(ISNUMBER($E24)),NOT(ISNUMBER(마스터!$P$11))),"",IF(AND(마스터!$P$11>=$E24,마스터!$P$11<=$F24,OR($F$20=0,마스터!$G$11>0)),마스터!$C$11&"("&IF(마스터!$P$11-$D24>=0,"+","")&TEXT(마스터!$P$11-$D24,"#,##0")&")","")) | R24: =IF(OR(NOT(ISNUMBER($E24)),NOT(ISNUMBER(마스터!$P$10))),"",IF(AND(마스터!$P$10>=$E24,마스터!$P$10<=$F24,OR($F$20=0,마스터!$G$10>0)),마스터!$C$10&"("&IF(마스터!$P$10-$D24>=0,"+","")&TEXT(마스터!$P$10-$D24,"#,##0")&")","")) | S24: =IF(OR(NOT(ISNUMBER($E24)),NOT(ISNUMBER(마스터!$P$13))),"",IF(AND(마스터!$P$13>=$E24,마스터!$P$13<=$F24,OR($F$20=0,마스터!$G$13>0)),마스터!$C$13&"("&IF(마스터!$P$13-$D24>=0,"+","")&TEXT(마스터!$P$13-$D24,"#,##0")&")","")) | AB24: =마스터!C8 -> 50*50
A25: =마스터!A7 -> 3 | B25: =마스터!B7 -> 아트지 | C25: =마스터!C7 -> 50*30 | D25: =마스터!P7 -> 4400 | E25: =IF(ISNUMBER(D25),ROUNDDOWN(D25*(1+$F$18),-1),"") -> 2200 | F25: =IF(ISNUMBER(D25),ROUNDDOWN(D25*(1+$F$19),-1),"") -> 8800 | G25: =SUMPRODUCT(--(LEN(J25:AF25)>0)) -> 6 | H25: =IF(G25>0,_xlfn.TEXTJOIN(", ",TRUE(),J25:AF25),IF(ISNUMBER(D25),"옵션 가능한 사이즈 없음","가격 미정 — 판매가 입력 필요")) -> 100*100(+3,300), 60*40(+530), 100*60(+2,750), 35*20(-1,650), 80*60(+2,750), 40*20(-1,650) | K25: =IF(OR(NOT(ISNUMBER($E25)),NOT(ISNUMBER(마스터!$P$14))),"",IF(AND(마스터!$P$14>=$E25,마스터!$P$14<=$F25,OR($F$20=0,마스터!$G$14>0)),마스터!$C$14&"("&IF(마스터!$P$14-$D25>=0,"+","")&TEXT(마스터!$P$14-$D25,"#,##0")&")","")) -> 100*100(+3,300) | L25: =IF(OR(NOT(ISNUMBER($E25)),NOT(ISNUMBER(마스터!$P$9))),"",IF(AND(마스터!$P$9>=$E25,마스터!$P$9<=$F25,OR($F$20=0,마스터!$G$9>0)),마스터!$C$9&"("&IF(마스터!$P$9-$D25>=0,"+","")&TEXT(마스터!$P$9-$D25,"#,##0")&")","")) -> 60*40(+530) | M25: =IF(OR(NOT(ISNUMBER($E25)),NOT(ISNUMBER(마스터!$P$12))),"",IF(AND(마스터!$P$12>=$E25,마스터!$P$12<=$F25,OR($F$20=0,마스터!$G$12>0)),마스터!$C$12&"("&IF(마스터!$P$12-$D25>=0,"+","")&TEXT(마스터!$P$12-$D25,"#,##0")&")","")) -> 100*60(+2,750) | O25: =IF(OR(NOT(ISNUMBER($E25)),NOT(ISNUMBER(마스터!$P$5))),"",IF(AND(마스터!$P$5>=$E25,마스터!$P$5<=$F25,OR($F$20=0,마스터!$G$5>0)),마스터!$C$5&"("&IF(마스터!$P$5-$D25>=0,"+","")&TEXT(마스터!$P$5-$D25,"#,##0")&")","")) -> 35*20(-1,650) | P25: =IF(OR(NOT(ISNUMBER($E25)),NOT(ISNUMBER(마스터!$P$11))),"",IF(AND(마스터!$P$11>=$E25,마스터!$P$11<=$F25,OR($F$20=0,마스터!$G$11>0)),마스터!$C$11&"("&IF(마스터!$P$11-$D25>=0,"+","")&TEXT(마스터!$P$11-$D25,"#,##0")&")","")) -> 80*60(+2,750) | Q25: =IF(OR(NOT(ISNUMBER($E25)),NOT(ISNUMBER(마스터!$P$6))),"",IF(AND(마스터!$P$6>=$E25,마스터!$P$6<=$F25,OR($F$20=0,마스터!$G$6>0)),마스터!$C$6&"("&IF(마스터!$P$6-$D25>=0,"+","")&TEXT(마스터!$P$6-$D25,"#,##0")&")","")) -> 40*20(-1,650) | R25: =IF(OR(NOT(ISNUMBER($E25)),NOT(ISNUMBER(마스터!$P$10))),"",IF(AND(마스터!$P$10>=$E25,마스터!$P$10<=$F25,OR($F$20=0,마스터!$G$10>0)),마스터!$C$10&"("&IF(마스터!$P$10-$D25>=0,"+","")&TEXT(마스터!$P$10-$D25,"#,##0")&")","")) | S25: =IF(OR(NOT(ISNUMBER($E25)),NOT(ISNUMBER(마스터!$P$13))),"",IF(AND(마스터!$P$13>=$E25,마스터!$P$13<=$F25,OR($F$20=0,마스터!$G$13>0)),마스터!$C$13&"("&IF(마스터!$P$13-$D25>=0,"+","")&TEXT(마스터!$P$13-$D25,"#,##0")&")",""))
A26: =마스터!A8 -> 4 | B26: =마스터!B8 -> 아트지 | C26: =마스터!C8 -> 50*50 | D26: =마스터!P8 -> 3850 | E26: =IF(ISNUMBER(D26),ROUNDDOWN(D26*(1+$F$18),-1),"") -> 1920 | F26: =IF(ISNUMBER(D26),ROUNDDOWN(D26*(1+$F$19),-1),"") -> 7700 | G26: =SUMPRODUCT(--(LEN(J26:AF26)>0)) -> 7 | H26: =IF(G26>0,_xlfn.TEXTJOIN(", ",TRUE(),J26:AF26),IF(ISNUMBER(D26),"옵션 가능한 사이즈 없음","가격 미정 — 판매가 입력 필요")) -> 100*100(+3,850), 60*40(+1,080), 100*60(+3,300), 50*30(+550), 35*20(-1,100), 80*60(+3,300), 40*20(-1,100) | K26: =IF(OR(NOT(ISNUMBER($E26)),NOT(ISNUMBER(마스터!$P$14))),"",IF(AND(마스터!$P$14>=$E26,마스터!$P$14<=$F26,OR($F$20=0,마스터!$G$14>0)),마스터!$C$14&"("&IF(마스터!$P$14-$D26>=0,"+","")&TEXT(마스터!$P$14-$D26,"#,##0")&")","")) -> 100*100(+3,850) | L26: =IF(OR(NOT(ISNUMBER($E26)),NOT(ISNUMBER(마스터!$P$9))),"",IF(AND(마스터!$P$9>=$E26,마스터!$P$9<=$F26,OR($F$20=0,마스터!$G$9>0)),마스터!$C$9&"("&IF(마스터!$P$9-$D26>=0,"+","")&TEXT(마스터!$P$9-$D26,"#,##0")&")","")) -> 60*40(+1,080) | M26: =IF(OR(NOT(ISNUMBER($E26)),NOT(ISNUMBER(마스터!$P$12))),"",IF(AND(마스터!$P$12>=$E26,마스터!$P$12<=$F26,OR($F$20=0,마스터!$G$12>0)),마스터!$C$12&"("&IF(마스터!$P$12-$D26>=0,"+","")&TEXT(마스터!$P$12-$D26,"#,##0")&")","")) -> 100*60(+3,300) | N26: =IF(OR(NOT(ISNUMBER($E26)),NOT(ISNUMBER(마스터!$P$7))),"",IF(AND(마스터!$P$7>=$E26,마스터!$P$7<=$F26,OR($F$20=0,마스터!$G$7>0)),마스터!$C$7&"("&IF(마스터!$P$7-$D26>=0,"+","")&TEXT(마스터!$P$7-$D26,"#,##0")&")","")) -> 50*30(+550) | O26: =IF(OR(NOT(ISNUMBER($E26)),NOT(ISNUMBER(마스터!$P$5))),"",IF(AND(마스터!$P$5>=$E26,마스터!$P$5<=$F26,OR($F$20=0,마스터!$G$5>0)),마스터!$C$5&"("&IF(마스터!$P$5-$D26>=0,"+","")&TEXT(마스터!$P$5-$D26,"#,##0")&")","")) -> 35*20(-1,100) | P26: =IF(OR(NOT(ISNUMBER($E26)),NOT(ISNUMBER(마스터!$P$11))),"",IF(AND(마스터!$P$11>=$E26,마스터!$P$11<=$F26,OR($F$20=0,마스터!$G$11>0)),마스터!$C$11&"("&IF(마스터!$P$11-$D26>=0,"+","")&TEXT(마스터!$P$11-$D26,"#,##0")&")","")) -> 80*60(+3,300) | Q26: =IF(OR(NOT(ISNUMBER($E26)),NOT(ISNUMBER(마스터!$P$6))),"",IF(AND(마스터!$P$6>=$E26,마스터!$P$6<=$F26,OR($F$20=0,마스터!$G$6>0)),마스터!$C$6&"("&IF(마스터!$P$6-$D26>=0,"+","")&TEXT(마스터!$P$6-$D26,"#,##0")&")","")) -> 40*20(-1,100) | R26: =IF(OR(NOT(ISNUMBER($E26)),NOT(ISNUMBER(마스터!$P$10))),"",IF(AND(마스터!$P$10>=$E26,마스터!$P$10<=$F26,OR($F$20=0,마스터!$G$10>0)),마스터!$C$10&"("&IF(마스터!$P$10-$D26>=0,"+","")&TEXT(마스터!$P$10-$D26,"#,##0")&")","")) | S26: =IF(OR(NOT(ISNUMBER($E26)),NOT(ISNUMBER(마스터!$P$13))),"",IF(AND(마스터!$P$13>=$E26,마스터!$P$13<=$F26,OR($F$20=0,마스터!$G$13>0)),마스터!$C$13&"("&IF(마스터!$P$13-$D26>=0,"+","")&TEXT(마스터!$P$13-$D26,"#,##0")&")",""))
A27: =마스터!A9 -> 5 | B27: =마스터!B9 -> 아트지 | C27: =마스터!C9 -> 60*40 | D27: =마스터!P9 -> 4930 | E27: =IF(ISNUMBER(D27),ROUNDDOWN(D27*(1+$F$18),-1),"") -> 2460 | F27: =IF(ISNUMBER(D27),ROUNDDOWN(D27*(1+$F$19),-1),"") -> 9860 | G27: =SUMPRODUCT(--(LEN(J27:AF27)>0)) -> 6 | H27: =IF(G27>0,_xlfn.TEXTJOIN(", ",TRUE(),J27:AF27),IF(ISNUMBER(D27),"옵션 가능한 사이즈 없음","가격 미정 — 판매가 입력 필요")) -> 100*100(+2,770), 100*60(+2,220), 50*30(-530), 35*20(-2,180), 80*60(+2,220), 40*20(-2,180) | K27: =IF(OR(NOT(ISNUMBER($E27)),NOT(ISNUMBER(마스터!$P$14))),"",IF(AND(마스터!$P$14>=$E27,마스터!$P$14<=$F27,OR($F$20=0,마스터!$G$14>0)),마스터!$C$14&"("&IF(마스터!$P$14-$D27>=0,"+","")&TEXT(마스터!$P$14-$D27,"#,##0")&")","")) -> 100*100(+2,770) | M27: =IF(OR(NOT(ISNUMBER($E27)),NOT(ISNUMBER(마스터!$P$12))),"",IF(AND(마스터!$P$12>=$E27,마스터!$P$12<=$F27,OR($F$20=0,마스터!$G$12>0)),마스터!$C$12&"("&IF(마스터!$P$12-$D27>=0,"+","")&TEXT(마스터!$P$12-$D27,"#,##0")&")","")) -> 100*60(+2,220) | N27: =IF(OR(NOT(ISNUMBER($E27)),NOT(ISNUMBER(마스터!$P$7))),"",IF(AND(마스터!$P$7>=$E27,마스터!$P$7<=$F27,OR($F$20=0,마스터!$G$7>0)),마스터!$C$7&"("&IF(마스터!$P$7-$D27>=0,"+","")&TEXT(마스터!$P$7-$D27,"#,##0")&")","")) -> 50*30(-530) | O27: =IF(OR(NOT(ISNUMBER($E27)),NOT(ISNUMBER(마스터!$P$5))),"",IF(AND(마스터!$P$5>=$E27,마스터!$P$5<=$F27,OR($F$20=0,마스터!$G$5>0)),마스터!$C$5&"("&IF(마스터!$P$5-$D27>=0,"+","")&TEXT(마스터!$P$5-$D27,"#,##0")&")","")) -> 35*20(-2,180) | P27: =IF(OR(NOT(ISNUMBER($E27)),NOT(ISNUMBER(마스터!$P$11))),"",IF(AND(마스터!$P$11>=$E27,마스터!$P$11<=$F27,OR($F$20=0,마스터!$G$11>0)),마스터!$C$11&"("&IF(마스터!$P$11-$D27>=0,"+","")&TEXT(마스터!$P$11-$D27,"#,##0")&")","")) -> 80*60(+2,220) | Q27: =IF(OR(NOT(ISNUMBER($E27)),NOT(ISNUMBER(마스터!$P$6))),"",IF(AND(마스터!$P$6>=$E27,마스터!$P$6<=$F27,OR($F$20=0,마스터!$G$6>0)),마스터!$C$6&"("&IF(마스터!$P$6-$D27>=0,"+","")&TEXT(마스터!$P$6-$D27,"#,##0")&")","")) -> 40*20(-2,180) | R27: =IF(OR(NOT(ISNUMBER($E27)),NOT(ISNUMBER(마스터!$P$10))),"",IF(AND(마스터!$P$10>=$E27,마스터!$P$10<=$F27,OR($F$20=0,마스터!$G$10>0)),마스터!$C$10&"("&IF(마스터!$P$10-$D27>=0,"+","")&TEXT(마스터!$P$10-$D27,"#,##0")&")","")) | S27: =IF(OR(NOT(ISNUMBER($E27)),NOT(ISNUMBER(마스터!$P$13))),"",IF(AND(마스터!$P$13>=$E27,마스터!$P$13<=$F27,OR($F$20=0,마스터!$G$13>0)),마스터!$C$13&"("&IF(마스터!$P$13-$D27>=0,"+","")&TEXT(마스터!$P$13-$D27,"#,##0")&")",""))
A28: =마스터!A10 -> 6 | B28: =마스터!B10 -> 아트지/품절 | C28: =마스터!C10 -> 70*40 | D28: =마스터!P10 | E28: =IF(ISNUMBER(D28),ROUNDDOWN(D28*(1+$F$18),-1),"") | F28: =IF(ISNUMBER(D28),ROUNDDOWN(D28*(1+$F$19),-1),"") | G28: =SUMPRODUCT(--(LEN(J28:AF28)>0)) -> 0 | H28: 품절 | K28: =IF(OR(NOT(ISNUMBER($E28)),NOT(ISNUMBER(마스터!$P$14))),"",IF(AND(마스터!$P$14>=$E28,마스터!$P$14<=$F28,OR($F$20=0,마스터!$G$14>0)),마스터!$C$14&"("&IF(마스터!$P$14-$D28>=0,"+","")&TEXT(마스터!$P$14-$D28,"#,##0")&")","")) | L28: =IF(OR(NOT(ISNUMBER($E28)),NOT(ISNUMBER(마스터!$P$9))),"",IF(AND(마스터!$P$9>=$E28,마스터!$P$9<=$F28,OR($F$20=0,마스터!$G$9>0)),마스터!$C$9&"("&IF(마스터!$P$9-$D28>=0,"+","")&TEXT(마스터!$P$9-$D28,"#,##0")&")","")) | M28: =IF(OR(NOT(ISNUMBER($E28)),NOT(ISNUMBER(마스터!$P$12))),"",IF(AND(마스터!$P$12>=$E28,마스터!$P$12<=$F28,OR($F$20=0,마스터!$G$12>0)),마스터!$C$12&"("&IF(마스터!$P$12-$D28>=0,"+","")&TEXT(마스터!$P$12-$D28,"#,##0")&")","")) | N28: =IF(OR(NOT(ISNUMBER($E28)),NOT(ISNUMBER(마스터!$P$7))),"",IF(AND(마스터!$P$7>=$E28,마스터!$P$7<=$F28,OR($F$20=0,마스터!$G$7>0)),마스터!$C$7&"("&IF(마스터!$P$7-$D28>=0,"+","")&TEXT(마스터!$P$7-$D28,"#,##0")&")","")) | O28: =IF(OR(NOT(ISNUMBER($E28)),NOT(ISNUMBER(마스터!$P$5))),"",IF(AND(마스터!$P$5>=$E28,마스터!$P$5<=$F28,OR($F$20=0,마스터!$G$5>0)),마스터!$C$5&"("&IF(마스터!$P$5-$D28>=0,"+","")&TEXT(마스터!$P$5-$D28,"#,##0")&")","")) | P28: =IF(OR(NOT(ISNUMBER($E28)),NOT(ISNUMBER(마스터!$P$11))),"",IF(AND(마스터!$P$11>=$E28,마스터!$P$11<=$F28,OR($F$20=0,마스터!$G$11>0)),마스터!$C$11&"("&IF(마스터!$P$11-$D28>=0,"+","")&TEXT(마스터!$P$11-$D28,"#,##0")&")","")) | Q28: =IF(OR(NOT(ISNUMBER($E28)),NOT(ISNUMBER(마스터!$P$6))),"",IF(AND(마스터!$P$6>=$E28,마스터!$P$6<=$F28,OR($F$20=0,마스터!$G$6>0)),마스터!$C$6&"("&IF(마스터!$P$6-$D28>=0,"+","")&TEXT(마스터!$P$6-$D28,"#,##0")&")","")) | S28: =IF(OR(NOT(ISNUMBER($E28)),NOT(ISNUMBER(마스터!$P$13))),"",IF(AND(마스터!$P$13>=$E28,마스터!$P$13<=$F28,OR($F$20=0,마스터!$G$13>0)),마스터!$C$13&"("&IF(마스터!$P$13-$D28>=0,"+","")&TEXT(마스터!$P$13-$D28,"#,##0")&")",""))
A29: =마스터!A11 -> 7 | B29: =마스터!B11 -> 아트지 | C29: =마스터!C11 -> 80*60 | D29: =마스터!P11 -> 7150 | E29: =IF(ISNUMBER(D29),ROUNDDOWN(D29*(1+$F$18),-1),"") -> 3570 | F29: =IF(ISNUMBER(D29),ROUNDDOWN(D29*(1+$F$19),-1),"") -> 14300 | G29: =SUMPRODUCT(--(LEN(J29:AF29)>0)) -> 5 | H29: =IF(G29>0,_xlfn.TEXTJOIN(", ",TRUE(),J29:AF29),IF(ISNUMBER(D29),"옵션 가능한 사이즈 없음","가격 미정 — 판매가 입력 필요")) -> 100*100(+550), 60*40(-2,220), 100*60(+0), 50*30(-2,750), 100*70(+3,610) | K29: =IF(OR(NOT(ISNUMBER($E29)),NOT(ISNUMBER(마스터!$P$14))),"",IF(AND(마스터!$P$14>=$E29,마스터!$P$14<=$F29,OR($F$20=0,마스터!$G$14>0)),마스터!$C$14&"("&IF(마스터!$P$14-$D29>=0,"+","")&TEXT(마스터!$P$14-$D29,"#,##0")&")","")) -> 100*100(+550) | L29: =IF(OR(NOT(ISNUMBER($E29)),NOT(ISNUMBER(마스터!$P$9))),"",IF(AND(마스터!$P$9>=$E29,마스터!$P$9<=$F29,OR($F$20=0,마스터!$G$9>0)),마스터!$C$9&"("&IF(마스터!$P$9-$D29>=0,"+","")&TEXT(마스터!$P$9-$D29,"#,##0")&")","")) -> 60*40(-2,220) | M29: =IF(OR(NOT(ISNUMBER($E29)),NOT(ISNUMBER(마스터!$P$12))),"",IF(AND(마스터!$P$12>=$E29,마스터!$P$12<=$F29,OR($F$20=0,마스터!$G$12>0)),마스터!$C$12&"("&IF(마스터!$P$12-$D29>=0,"+","")&TEXT(마스터!$P$12-$D29,"#,##0")&")","")) -> 100*60(+0) | N29: =IF(OR(NOT(ISNUMBER($E29)),NOT(ISNUMBER(마스터!$P$7))),"",IF(AND(마스터!$P$7>=$E29,마스터!$P$7<=$F29,OR($F$20=0,마스터!$G$7>0)),마스터!$C$7&"("&IF(마스터!$P$7-$D29>=0,"+","")&TEXT(마스터!$P$7-$D29,"#,##0")&")","")) -> 50*30(-2,750) | O29: =IF(OR(NOT(ISNUMBER($E29)),NOT(ISNUMBER(마스터!$P$5))),"",IF(AND(마스터!$P$5>=$E29,마스터!$P$5<=$F29,OR($F$20=0,마스터!$G$5>0)),마스터!$C$5&"("&IF(마스터!$P$5-$D29>=0,"+","")&TEXT(마스터!$P$5-$D29,"#,##0")&")","")) | Q29: =IF(OR(NOT(ISNUMBER($E29)),NOT(ISNUMBER(마스터!$P$6))),"",IF(AND(마스터!$P$6>=$E29,마스터!$P$6<=$F29,OR($F$20=0,마스터!$G$6>0)),마스터!$C$6&"("&IF(마스터!$P$6-$D29>=0,"+","")&TEXT(마스터!$P$6-$D29,"#,##0")&")","")) | R29: =IF(OR(NOT(ISNUMBER($E29)),NOT(ISNUMBER(마스터!$P$10))),"",IF(AND(마스터!$P$10>=$E29,마스터!$P$10<=$F29,OR($F$20=0,마스터!$G$10>0)),마스터!$C$10&"("&IF(마스터!$P$10-$D29>=0,"+","")&TEXT(마스터!$P$10-$D29,"#,##0")&")","")) | S29: =IF(OR(NOT(ISNUMBER($E29)),NOT(ISNUMBER(마스터!$P$13))),"",IF(AND(마스터!$P$13>=$E29,마스터!$P$13<=$F29,OR($F$20=0,마스터!$G$13>0)),마스터!$C$13&"("&IF(마스터!$P$13-$D29>=0,"+","")&TEXT(마스터!$P$13-$D29,"#,##0")&")","")) -> 100*70(+3,610)
A30: =마스터!A12 -> 8 | B30: =마스터!B12 -> 아트지 | C30: =마스터!C12 -> 100*60 | D30: =마스터!P12 -> 7150 | E30: =IF(ISNUMBER(D30),ROUNDDOWN(D30*(1+$F$18),-1),"") -> 3570 | F30: =IF(ISNUMBER(D30),ROUNDDOWN(D30*(1+$F$19),-1),"") -> 14300 | G30: =SUMPRODUCT(--(LEN(J30:AF30)>0)) -> 5 | H30: =IF(G30>0,_xlfn.TEXTJOIN(", ",TRUE(),J30:AF30),IF(ISNUMBER(D30),"옵션 가능한 사이즈 없음","가격 미정 — 판매가 입력 필요")) -> 100*100(+550), 60*40(-2,220), 50*30(-2,750), 80*60(+0), 100*70(+3,610) | K30: =IF(OR(NOT(ISNUMBER($E30)),NOT(ISNUMBER(마스터!$P$14))),"",IF(AND(마스터!$P$14>=$E30,마스터!$P$14<=$F30,OR($F$20=0,마스터!$G$14>0)),마스터!$C$14&"("&IF(마스터!$P$14-$D30>=0,"+","")&TEXT(마스터!$P$14-$D30,"#,##0")&")","")) -> 100*100(+550) | L30: =IF(OR(NOT(ISNUMBER($E30)),NOT(ISNUMBER(마스터!$P$9))),"",IF(AND(마스터!$P$9>=$E30,마스터!$P$9<=$F30,OR($F$20=0,마스터!$G$9>0)),마스터!$C$9&"("&IF(마스터!$P$9-$D30>=0,"+","")&TEXT(마스터!$P$9-$D30,"#,##0")&")","")) -> 60*40(-2,220) | N30: =IF(OR(NOT(ISNUMBER($E30)),NOT(ISNUMBER(마스터!$P$7))),"",IF(AND(마스터!$P$7>=$E30,마스터!$P$7<=$F30,OR($F$20=0,마스터!$G$7>0)),마스터!$C$7&"("&IF(마스터!$P$7-$D30>=0,"+","")&TEXT(마스터!$P$7-$D30,"#,##0")&")","")) -> 50*30(-2,750) | O30: =IF(OR(NOT(ISNUMBER($E30)),NOT(ISNUMBER(마스터!$P$5))),"",IF(AND(마스터!$P$5>=$E30,마스터!$P$5<=$F30,OR($F$20=0,마스터!$G$5>0)),마스터!$C$5&"("&IF(마스터!$P$5-$D30>=0,"+","")&TEXT(마스터!$P$5-$D30,"#,##0")&")","")) | P30: =IF(OR(NOT(ISNUMBER($E30)),NOT(ISNUMBER(마스터!$P$11))),"",IF(AND(마스터!$P$11>=$E30,마스터!$P$11<=$F30,OR($F$20=0,마스터!$G$11>0)),마스터!$C$11&"("&IF(마스터!$P$11-$D30>=0,"+","")&TEXT(마스터!$P$11-$D30,"#,##0")&")","")) -> 80*60(+0) | Q30: =IF(OR(NOT(ISNUMBER($E30)),NOT(ISNUMBER(마스터!$P$6))),"",IF(AND(마스터!$P$6>=$E30,마스터!$P$6<=$F30,OR($F$20=0,마스터!$G$6>0)),마스터!$C$6&"("&IF(마스터!$P$6-$D30>=0,"+","")&TEXT(마스터!$P$6-$D30,"#,##0")&")","")) | R30: =IF(OR(NOT(ISNUMBER($E30)),NOT(ISNUMBER(마스터!$P$10))),"",IF(AND(마스터!$P$10>=$E30,마스터!$P$10<=$F30,OR($F$20=0,마스터!$G$10>0)),마스터!$C$10&"("&IF(마스터!$P$10-$D30>=0,"+","")&TEXT(마스터!$P$10-$D30,"#,##0")&")","")) | S30: =IF(OR(NOT(ISNUMBER($E30)),NOT(ISNUMBER(마스터!$P$13))),"",IF(AND(마스터!$P$13>=$E30,마스터!$P$13<=$F30,OR($F$20=0,마스터!$G$13>0)),마스터!$C$13&"("&IF(마스터!$P$13-$D30>=0,"+","")&TEXT(마스터!$P$13-$D30,"#,##0")&")","")) -> 100*70(+3,610)
A31: =마스터!A13 -> 9 | B31: =마스터!B13 -> 아트지 | C31: =마스터!C13 -> 100*70 | D31: =마스터!P13 -> 10760 | E31: =IF(ISNUMBER(D31),ROUNDDOWN(D31*(1+$F$18),-1),"") -> 5380 | F31: =IF(ISNUMBER(D31),ROUNDDOWN(D31*(1+$F$19),-1),"") -> 21520 | G31: =SUMPRODUCT(--(LEN(J31:AF31)>0)) -> 3 | H31: =IF(G31>0,_xlfn.TEXTJOIN(", ",TRUE(),J31:AF31),IF(ISNUMBER(D31),"옵션 가능한 사이즈 없음","가격 미정 — 판매가 입력 필요")) -> 100*100(-3,060), 100*60(-3,610), 80*60(-3,610) | J31: =IF(OR(NOT(ISNUMBER($E31)),NOT(ISNUMBER(마스터!$P$8))),"",IF(AND(마스터!$P$8>=$E31,마스터!$P$8<=$F31,OR($F$20=0,마스터!$G$8>0)),마스터!$C$8&"("&IF(마스터!$P$8-$D31>=0,"+","")&TEXT(마스터!$P$8-$D31,"#,##0")&")","")) | K31: =IF(OR(NOT(ISNUMBER($E31)),NOT(ISNUMBER(마스터!$P$14))),"",IF(AND(마스터!$P$14>=$E31,마스터!$P$14<=$F31,OR($F$20=0,마스터!$G$14>0)),마스터!$C$14&"("&IF(마스터!$P$14-$D31>=0,"+","")&TEXT(마스터!$P$14-$D31,"#,##0")&")","")) -> 100*100(-3,060) | L31: =IF(OR(NOT(ISNUMBER($E31)),NOT(ISNUMBER(마스터!$P$9))),"",IF(AND(마스터!$P$9>=$E31,마스터!$P$9<=$F31,OR($F$20=0,마스터!$G$9>0)),마스터!$C$9&"("&IF(마스터!$P$9-$D31>=0,"+","")&TEXT(마스터!$P$9-$D31,"#,##0")&")","")) | M31: =IF(OR(NOT(ISNUMBER($E31)),NOT(ISNUMBER(마스터!$P$12))),"",IF(AND(마스터!$P$12>=$E31,마스터!$P$12<=$F31,OR($F$20=0,마스터!$G$12>0)),마스터!$C$12&"("&IF(마스터!$P$12-$D31>=0,"+","")&TEXT(마스터!$P$12-$D31,"#,##0")&")","")) -> 100*60(-3,610) | N31: =IF(OR(NOT(ISNUMBER($E31)),NOT(ISNUMBER(마스터!$P$7))),"",IF(AND(마스터!$P$7>=$E31,마스터!$P$7<=$F31,OR($F$20=0,마스터!$G$7>0)),마스터!$C$7&"("&IF(마스터!$P$7-$D31>=0,"+","")&TEXT(마스터!$P$7-$D31,"#,##0")&")","")) | O31: =IF(OR(NOT(ISNUMBER($E31)),NOT(ISNUMBER(마스터!$P$5))),"",IF(AND(마스터!$P$5>=$E31,마스터!$P$5<=$F31,OR($F$20=0,마스터!$G$5>0)),마스터!$C$5&"("&IF(마스터!$P$5-$D31>=0,"+","")&TEXT(마스터!$P$5-$D31,"#,##0")&")","")) | P31: =IF(OR(NOT(ISNUMBER($E31)),NOT(ISNUMBER(마스터!$P$11))),"",IF(AND(마스터!$P$11>=$E31,마스터!$P$11<=$F31,OR($F$20=0,마스터!$G$11>0)),마스터!$C$11&"("&IF(마스터!$P$11-$D31>=0,"+","")&TEXT(마스터!$P$11-$D31,"#,##0")&")","")) -> 80*60(-3,610) | Q31: =IF(OR(NOT(ISNUMBER($E31)),NOT(ISNUMBER(마스터!$P$6))),"",IF(AND(마스터!$P$6>=$E31,마스터!$P$6<=$F31,OR($F$20=0,마스터!$G$6>0)),마스터!$C$6&"("&IF(마스터!$P$6-$D31>=0,"+","")&TEXT(마스터!$P$6-$D31,"#,##0")&")","")) | R31: =IF(OR(NOT(ISNUMBER($E31)),NOT(ISNUMBER(마스터!$P$10))),"",IF(AND(마스터!$P$10>=$E31,마스터!$P$10<=$F31,OR($F$20=0,마스터!$G$10>0)),마스터!$C$10&"("&IF(마스터!$P$10-$D31>=0,"+","")&TEXT(마스터!$P$10-$D31,"#,##0")&")",""))
A32: =마스터!A14 -> 10 | B32: =마스터!B14 -> 아트지 | C32: =마스터!C14 -> 100*100 | D32: =마스터!P14 -> 7700 | E32: =IF(ISNUMBER(D32),ROUNDDOWN(D32*(1+$F$18),-1),"") -> 3850 | F32: =IF(ISNUMBER(D32),ROUNDDOWN(D32*(1+$F$19),-1),"") -> 15400 | G32: =SUMPRODUCT(--(LEN(J32:AF32)>0)) -> 6 | H32: =IF(G32>0,_xlfn.TEXTJOIN(", ",TRUE(),J32:AF32),IF(ISNUMBER(D32),"옵션 가능한 사이즈 없음","가격 미정 — 판매가 입력 필요")) -> 60*40(-2,770), 100*60(-550), 50*30(-3,300), 80*60(-550), 100*70(+3,060), 50*50(-3,850) | L32: =IF(OR(NOT(ISNUMBER($E32)),NOT(ISNUMBER(마스터!$P$9))),"",IF(AND(마스터!$P$9>=$E32,마스터!$P$9<=$F32,OR($F$20=0,마스터!$G$9>0)),마스터!$C$9&"("&IF(마스터!$P$9-$D32>=0,"+","")&TEXT(마스터!$P$9-$D32,"#,##0")&")","")) -> 60*40(-2,770) | M32: =IF(OR(NOT(ISNUMBER($E32)),NOT(ISNUMBER(마스터!$P$12))),"",IF(AND(마스터!$P$12>=$E32,마스터!$P$12<=$F32,OR($F$20=0,마스터!$G$12>0)),마스터!$C$12&"("&IF(마스터!$P$12-$D32>=0,"+","")&TEXT(마스터!$P$12-$D32,"#,##0")&")","")) -> 100*60(-550) | N32: =IF(OR(NOT(ISNUMBER($E32)),NOT(ISNUMBER(마스터!$P$7))),"",IF(AND(마스터!$P$7>=$E32,마스터!$P$7<=$F32,OR($F$20=0,마스터!$G$7>0)),마스터!$C$7&"("&IF(마스터!$P$7-$D32>=0,"+","")&TEXT(마스터!$P$7-$D32,"#,##0")&")","")) -> 50*30(-3,300) | O32: =IF(OR(NOT(ISNUMBER($E32)),NOT(ISNUMBER(마스터!$P$5))),"",IF(AND(마스터!$P$5>=$E32,마스터!$P$5<=$F32,OR($F$20=0,마스터!$G$5>0)),마스터!$C$5&"("&IF(마스터!$P$5-$D32>=0,"+","")&TEXT(마스터!$P$5-$D32,"#,##0")&")","")) | P32: =IF(OR(NOT(ISNUMBER($E32)),NOT(ISNUMBER(마스터!$P$11))),"",IF(AND(마스터!$P$11>=$E32,마스터!$P$11<=$F32,OR($F$20=0,마스터!$G$11>0)),마스터!$C$11&"("&IF(마스터!$P$11-$D32>=0,"+","")&TEXT(마스터!$P$11-$D32,"#,##0")&")","")) -> 80*60(-550) | Q32: =IF(OR(NOT(ISNUMBER($E32)),NOT(ISNUMBER(마스터!$P$6))),"",IF(AND(마스터!$P$6>=$E32,마스터!$P$6<=$F32,OR($F$20=0,마스터!$G$6>0)),마스터!$C$6&"("&IF(마스터!$P$6-$D32>=0,"+","")&TEXT(마스터!$P$6-$D32,"#,##0")&")","")) | R32: =IF(OR(NOT(ISNUMBER($E32)),NOT(ISNUMBER(마스터!$P$10))),"",IF(AND(마스터!$P$10>=$E32,마스터!$P$10<=$F32,OR($F$20=0,마스터!$G$10>0)),마스터!$C$10&"("&IF(마스터!$P$10-$D32>=0,"+","")&TEXT(마스터!$P$10-$D32,"#,##0")&")","")) | S32: =IF(OR(NOT(ISNUMBER($E32)),NOT(ISNUMBER(마스터!$P$13))),"",IF(AND(마스터!$P$13>=$E32,마스터!$P$13<=$F32,OR($F$20=0,마스터!$G$13>0)),마스터!$C$13&"("&IF(마스터!$P$13-$D32>=0,"+","")&TEXT(마스터!$P$13-$D32,"#,##0")&")","")) -> 100*70(+3,060) | AB32: =IF(OR(NOT(ISNUMBER($E32)),NOT(ISNUMBER(마스터!$P$8))),"",IF(AND(마스터!$P$8>=$E32,마스터!$P$8<=$F32,OR($F$20=0,마스터!$G$8>0)),마스터!$C$8&"("&IF(마스터!$P$8-$D32>=0,"+","")&TEXT(마스터!$P$8-$D32,"#,##0")&")","")) -> 50*50(-3,850)
AB33: =IF(OR(NOT(ISNUMBER($E27)),NOT(ISNUMBER(마스터!$P$8))),"",IF(AND(마스터!$P$8>=$E27,마스터!$P$8<=$F27,OR($F$20=0,마스터!$G$8>0)),마스터!$C$8&"("&IF(마스터!$P$8-$D27>=0,"+","")&TEXT(마스터!$P$8-$D27,"#,##0")&")","")) -> 50*50(-1,080)
AB34: =IF(OR(NOT(ISNUMBER($E30)),NOT(ISNUMBER(마스터!$P$8))),"",IF(AND(마스터!$P$8>=$E30,마스터!$P$8<=$F30,OR($F$20=0,마스터!$G$8>0)),마스터!$C$8&"("&IF(마스터!$P$8-$D30>=0,"+","")&TEXT(마스터!$P$8-$D30,"#,##0")&")","")) -> 50*50(-3,300)
AB35: =IF(OR(NOT(ISNUMBER($E25)),NOT(ISNUMBER(마스터!$P$8))),"",IF(AND(마스터!$P$8>=$E25,마스터!$P$8<=$F25,OR($F$20=0,마스터!$G$8>0)),마스터!$C$8&"("&IF(마스터!$P$8-$D25>=0,"+","")&TEXT(마스터!$P$8-$D25,"#,##0")&")","")) -> 50*50(-550)
AB36: =IF(OR(NOT(ISNUMBER($E28)),NOT(ISNUMBER(마스터!$P$8))),"",IF(AND(마스터!$P$8>=$E28,마스터!$P$8<=$F28,OR($F$20=0,마스터!$G$8>0)),마스터!$C$8&"("&IF(마스터!$P$8-$D28>=0,"+","")&TEXT(마스터!$P$8-$D28,"#,##0")&")",""))
AB37: =IF(OR(NOT(ISNUMBER($E29)),NOT(ISNUMBER(마스터!$P$8))),"",IF(AND(마스터!$P$8>=$E29,마스터!$P$8<=$F29,OR($F$20=0,마스터!$G$8>0)),마스터!$C$8&"("&IF(마스터!$P$8-$D29>=0,"+","")&TEXT(마스터!$P$8-$D29,"#,##0")&")","")) -> 50*50(-3,300)
AB38: =IF(OR(NOT(ISNUMBER($E30)),NOT(ISNUMBER(마스터!$P$8))),"",IF(AND(마스터!$P$8>=$E30,마스터!$P$8<=$F30,OR($F$20=0,마스터!$G$8>0)),마스터!$C$8&"("&IF(마스터!$P$8-$D30>=0,"+","")&TEXT(마스터!$P$8-$D30,"#,##0")&")","")) -> 50*50(-3,300)
