Workbook

Sheet 1.쇼핑검색 테스트
A1: 쇼핑검색 광고 입찰가 테스트 현황
A2: 네이버 쇼핑검색 · 키워드별 입찰가에 따른 메인페이지 / 가격비교탭 순위 · 우리 판매처: 전문몰 | 출처: 바코드프린터 네이버쇼핑 광고 입찰 관리 엑셀 ‘02_입찰조사_RAW’
A4: 테스트 기간 | C4: 2026-09-28 ~ 2026-10-06 (조사 33회)
A5: 우리 판매처 | C5: 전문몰
A6: 우선 목표 | C6: 메인페이지 1~3위 (가격비교탭보다 우선)
A7: 키워드 · 광고 상품 | C7: 유포라벨 → 유포지 30*15 · 감열라벨 → 감열지 100*100 · 아트라벨 → 아트지 60*40
A9: 핵심 정리 (10/7 작성, 아래 기록 기준)
A10: • 아트라벨: 2,300원으로 메인 1위(10/6 오전). 2,800원도 1위(10/2 오전). 같은 2,300원이 10/2 오후에는 2위 → 2,300~2,800원이면 메인 1~2위.
A11: • 유포라벨: 메인 1위는 3,500원(10/6 오전)·4,000원(10/1). 2,800~3,100원은 2위. 3,500원도 10/2 오후에는 3위 → 메인 1위를 노리면 3,500원 이상.
A12: • 감열라벨: 2,500~3,900원으로 7번 조사했지만 메인은 2~3위만 나옴. 1위는 매번 디엘에스피(2,000원 상품, 우리 5,090원) → 입찰가보다 판매가 차이가 큼. 2,500~2,800원으로 2위 유지가 효율적.
A13: • 가격비교탭: 1위는 아트라벨 3,000원(9/29), 감열라벨 2,500원(10/1) 한 번씩. 유포라벨은 3,000~6,000원을 넣어도 2위가 최고 → 가격비교탭에 입찰가를 더 쓰는 효과는 작음.
A14: • 같은 입찰가라도 시간대에 따라 순위가 1~2단계 바뀝니다. 조사 횟수가 적으니 권장 입찰가로 며칠 더 같은 시간대에 확인해 보세요.
A16: ① 키워드별 목표 순위 최저 입찰가 (③ 기록에서 자동 계산)
A17: 해당 순위 이내로 노출된 기록 중 가장 낮은 입찰가입니다. 기록이 없으면 "기록 없음".
A18: 키워드 | B18: 메인 1위 | C18: 메인 2위 이내 | D18: 메인 3위 이내 | E18: 가격비교 1위 | F18: 가격비교 2위 이내 | G18: 가격비교 3위 이내 | H18: 조사 수 | I18: 메인 최고 순위 | J18: 메인 평균 순위 | K18: 가격비교 최고 순위 | L18: 메인 1위 업체 (가장 많이) | M18: 권장 입찰가 (메인 기준)
A19: 유포라벨 | B19: =IF(COUNTIFS($D$39:$D$91,$A19,$H$39:$H$91,"<=1",$H$39:$H$91,">0",$F$39:$F$91,">0")=0,"기록 없음",_xlfn.MINIFS($F$39:$F$91,$D$39:$D$91,$A19,$H$39:$H$91,"<=1",$H$39:$H$91,">0",$F$39:$F$91,">0")) -> 3500 | C19: =IF(COUNTIFS($D$39:$D$91,$A19,$H$39:$H$91,"<=2",$H$39:$H$91,">0",$F$39:$F$91,">0")=0,"기록 없음",_xlfn.MINIFS($F$39:$F$91,$D$39:$D$91,$A19,$H$39:$H$91,"<=2",$H$39:$H$91,">0",$F$39:$F$91,">0")) -> 2800 | D19: =IF(COUNTIFS($D$39:$D$91,$A19,$H$39:$H$91,"<=3",$H$39:$H$91,">0",$F$39:$F$91,">0")=0,"기록 없음",_xlfn.MINIFS($F$39:$F$91,$D$39:$D$91,$A19,$H$39:$H$91,"<=3",$H$39:$H$91,">0",$F$39:$F$91,">0")) -> 2800 | E19: =IF(COUNTIFS($D$39:$D$91,$A19,$G$39:$G$91,"<=1",$G$39:$G$91,">0",$F$39:$F$91,">0")=0,"기록 없음",_xlfn.MINIFS($F$39:$F$91,$D$39:$D$91,$A19,$G$39:$G$91,"<=1",$G$39:$G$91,">0",$F$39:$F$91,">0")) -> 기록 없음 | F19: =IF(COUNTIFS($D$39:$D$91,$A19,$G$39:$G$91,"<=2",$G$39:$G$91,">0",$F$39:$F$91,">0")=0,"기록 없음",_xlfn.MINIFS($F$39:$F$91,$D$39:$D$91,$A19,$G$39:$G$91,"<=2",$G$39:$G$91,">0",$F$39:$F$91,">0")) -> 3000 | G19: =IF(COUNTIFS($D$39:$D$91,$A19,$G$39:$G$91,"<=3",$G$39:$G$91,">0",$F$39:$F$91,">0")=0,"기록 없음",_xlfn.MINIFS($F$39:$F$91,$D$39:$D$91,$A19,$G$39:$G$91,"<=3",$G$39:$G$91,">0",$F$39:$F$91,">0")) -> 3000 | H19: =COUNTIF($D$39:$D$91,$A19) -> 16 | I19: =IF(COUNTIFS($D$39:$D$91,$A19,$H$39:$H$91,">0")=0,"노출 없음",_xlfn.MINIFS($H$39:$H$91,$D$39:$D$91,$A19,$H$39:$H$91,">0")&"위") -> 1위 | J19: =IF(COUNTIFS($D$39:$D$91,$A19,$H$39:$H$91,">0")=0,"-",AVERAGEIFS($H$39:$H$91,$D$39:$D$91,$A19,$H$39:$H$91,">0")) -> 1.8 | K19: =IF(COUNTIFS($D$39:$D$91,$A19,$G$39:$G$91,">0")=0,"노출 없음",_xlfn.MINIFS($G$39:$G$91,$D$39:$D$91,$A19,$G$39:$G$91,">0")&"위") -> 2위 | L19: 디엘에스피 | M19: 3,500원 (메인 1위 목표)
A20: 감열라벨 | B20: =IF(COUNTIFS($D$39:$D$91,$A20,$H$39:$H$91,"<=1",$H$39:$H$91,">0",$F$39:$F$91,">0")=0,"기록 없음",_xlfn.MINIFS($F$39:$F$91,$D$39:$D$91,$A20,$H$39:$H$91,"<=1",$H$39:$H$91,">0",$F$39:$F$91,">0")) -> 기록 없음 | C20: =IF(COUNTIFS($D$39:$D$91,$A20,$H$39:$H$91,"<=2",$H$39:$H$91,">0",$F$39:$F$91,">0")=0,"기록 없음",_xlfn.MINIFS($F$39:$F$91,$D$39:$D$91,$A20,$H$39:$H$91,"<=2",$H$39:$H$91,">0",$F$39:$F$91,">0")) -> 2500 | D20: =IF(COUNTIFS($D$39:$D$91,$A20,$H$39:$H$91,"<=3",$H$39:$H$91,">0",$F$39:$F$91,">0")=0,"기록 없음",_xlfn.MINIFS($F$39:$F$91,$D$39:$D$91,$A20,$H$39:$H$91,"<=3",$H$39:$H$91,">0",$F$39:$F$91,">0")) -> 2500 | E20: =IF(COUNTIFS($D$39:$D$91,$A20,$G$39:$G$91,"<=1",$G$39:$G$91,">0",$F$39:$F$91,">0")=0,"기록 없음",_xlfn.MINIFS($F$39:$F$91,$D$39:$D$91,$A20,$G$39:$G$91,"<=1",$G$39:$G$91,">0",$F$39:$F$91,">0")) -> 2500 | F20: =IF(COUNTIFS($D$39:$D$91,$A20,$G$39:$G$91,"<=2",$G$39:$G$91,">0",$F$39:$F$91,">0")=0,"기록 없음",_xlfn.MINIFS($F$39:$F$91,$D$39:$D$91,$A20,$G$39:$G$91,"<=2",$G$39:$G$91,">0",$F$39:$F$91,">0")) -> 2500 | G20: =IF(COUNTIFS($D$39:$D$91,$A20,$G$39:$G$91,"<=3",$G$39:$G$91,">0",$F$39:$F$91,">0")=0,"기록 없음",_xlfn.MINIFS($F$39:$F$91,$D$39:$D$91,$A20,$G$39:$G$91,"<=3",$G$39:$G$91,">0",$F$39:$F$91,">0")) -> 2500 | H20: =COUNTIF($D$39:$D$91,$A20) -> 9 | I20: =IF(COUNTIFS($D$39:$D$91,$A20,$H$39:$H$91,">0")=0,"노출 없음",_xlfn.MINIFS($H$39:$H$91,$D$39:$D$91,$A20,$H$39:$H$91,">0")&"위") -> 2위 | J20: =IF(COUNTIFS($D$39:$D$91,$A20,$H$39:$H$91,">0")=0,"-",AVERAGEIFS($H$39:$H$91,$D$39:$D$91,$A20,$H$39:$H$91,">0")) -> 2.2857143 | K20: =IF(COUNTIFS($D$39:$D$91,$A20,$G$39:$G$91,">0")=0,"노출 없음",_xlfn.MINIFS($G$39:$G$91,$D$39:$D$91,$A20,$G$39:$G$91,">0")&"위") -> 1위 | L20: 디엘에스피 | M20: 2,500~2,800원 (메인 2위 유지)
A21: 아트라벨 | B21: =IF(COUNTIFS($D$39:$D$91,$A21,$H$39:$H$91,"<=1",$H$39:$H$91,">0",$F$39:$F$91,">0")=0,"기록 없음",_xlfn.MINIFS($F$39:$F$91,$D$39:$D$91,$A21,$H$39:$H$91,"<=1",$H$39:$H$91,">0",$F$39:$F$91,">0")) -> 2300 | C21: =IF(COUNTIFS($D$39:$D$91,$A21,$H$39:$H$91,"<=2",$H$39:$H$91,">0",$F$39:$F$91,">0")=0,"기록 없음",_xlfn.MINIFS($F$39:$F$91,$D$39:$D$91,$A21,$H$39:$H$91,"<=2",$H$39:$H$91,">0",$F$39:$F$91,">0")) -> 2300 | D21: =IF(COUNTIFS($D$39:$D$91,$A21,$H$39:$H$91,"<=3",$H$39:$H$91,">0",$F$39:$F$91,">0")=0,"기록 없음",_xlfn.MINIFS($F$39:$F$91,$D$39:$D$91,$A21,$H$39:$H$91,"<=3",$H$39:$H$91,">0",$F$39:$F$91,">0")) -> 2300 | E21: =IF(COUNTIFS($D$39:$D$91,$A21,$G$39:$G$91,"<=1",$G$39:$G$91,">0",$F$39:$F$91,">0")=0,"기록 없음",_xlfn.MINIFS($F$39:$F$91,$D$39:$D$91,$A21,$G$39:$G$91,"<=1",$G$39:$G$91,">0",$F$39:$F$91,">0")) -> 3000 | F21: =IF(COUNTIFS($D$39:$D$91,$A21,$G$39:$G$91,"<=2",$G$39:$G$91,">0",$F$39:$F$91,">0")=0,"기록 없음",_xlfn.MINIFS($F$39:$F$91,$D$39:$D$91,$A21,$G$39:$G$91,"<=2",$G$39:$G$91,">0",$F$39:$F$91,">0")) -> 2000 | G21: =IF(COUNTIFS($D$39:$D$91,$A21,$G$39:$G$91,"<=3",$G$39:$G$91,">0",$F$39:$F$91,">0")=0,"기록 없음",_xlfn.MINIFS($F$39:$F$91,$D$39:$D$91,$A21,$G$39:$G$91,"<=3",$G$39:$G$91,">0",$F$39:$F$91,">0")) -> 2000 | H21: =COUNTIF($D$39:$D$91,$A21) -> 8 | I21: =IF(COUNTIFS($D$39:$D$91,$A21,$H$39:$H$91,">0")=0,"노출 없음",_xlfn.MINIFS($H$39:$H$91,$D$39:$D$91,$A21,$H$39:$H$91,">0")&"위") -> 1위 | J21: =IF(COUNTIFS($D$39:$D$91,$A21,$H$39:$H$91,">0")=0,"-",AVERAGEIFS($H$39:$H$91,$D$39:$D$91,$A21,$H$39:$H$91,">0")) -> 1.4 | K21: =IF(COUNTIFS($D$39:$D$91,$A21,$G$39:$G$91,">0")=0,"노출 없음",_xlfn.MINIFS($G$39:$G$91,$D$39:$D$91,$A21,$G$39:$G$91,">0")&"위") -> 1위 | L21: 전문몰 (우리) | M21: 2,300~2,800원 (메인 1~2위)
A22: 권장 입찰가는 위 기록을 보고 정한 값(10/7 작성)입니다. 같은 입찰가에서도 순위가 바뀌므로 2~3번 같은 결과가 나온 값을 쓰세요.
A23: ② 주로 광고 중인 타업체 (③ 기록의 1~3위 업체에서 자동 집계)
A24: 메인 순위 업체는 10/2부터 조사했습니다. 그 전 기록의 업체는 가격비교탭 순위입니다. 업체를 추가하려면 노란 칸에 이름을 적으세요.
A25: 업체명 | B25: 유포라벨 메인 | C25: 유포라벨 가격비교 | D25: 감열라벨 메인 | E25: 감열라벨 가격비교 | F25: 아트라벨 메인 | G25: 아트라벨 가격비교 | H25: 합계 | I25: 메인 1위 횟수 | J25: 확인된 판매가 / 메모
A26: 전문몰 (우리) | B26: =IF($A26="","",COUNTIFS($D$39:$D$91,"유포라벨",$I$39:$I$91,"메인",$J$39:$J$91,"전문몰")+COUNTIFS($D$39:$D$91,"유포라벨",$I$39:$I$91,"메인",$K$39:$K$91,"전문몰")+COUNTIFS($D$39:$D$91,"유포라벨",$I$39:$I$91,"메인",$L$39:$L$91,"전문몰")) -> 4 | C26: =IF($A26="","",COUNTIFS($D$39:$D$91,"유포라벨",$I$39:$I$91,"가격비교",$J$39:$J$91,"전문몰")+COUNTIFS($D$39:$D$91,"유포라벨",$I$39:$I$91,"가격비교",$K$39:$K$91,"전문몰")+COUNTIFS($D$39:$D$91,"유포라벨",$I$39:$I$91,"가격비교",$L$39:$L$91,"전문몰")) -> 1 | D26: =IF($A26="","",COUNTIFS($D$39:$D$91,"감열라벨",$I$39:$I$91,"메인",$J$39:$J$91,"전문몰")+COUNTIFS($D$39:$D$91,"감열라벨",$I$39:$I$91,"메인",$K$39:$K$91,"전문몰")+COUNTIFS($D$39:$D$91,"감열라벨",$I$39:$I$91,"메인",$L$39:$L$91,"전문몰")) -> 5 | E26: =IF($A26="","",COUNTIFS($D$39:$D$91,"감열라벨",$I$39:$I$91,"가격비교",$J$39:$J$91,"전문몰")+COUNTIFS($D$39:$D$91,"감열라벨",$I$39:$I$91,"가격비교",$K$39:$K$91,"전문몰")+COUNTIFS($D$39:$D$91,"감열라벨",$I$39:$I$91,"가격비교",$L$39:$L$91,"전문몰")) -> 0 | F26: =IF($A26="","",COUNTIFS($D$39:$D$91,"아트라벨",$I$39:$I$91,"메인",$J$39:$J$91,"전문몰")+COUNTIFS($D$39:$D$91,"아트라벨",$I$39:$I$91,"메인",$K$39:$K$91,"전문몰")+COUNTIFS($D$39:$D$91,"아트라벨",$I$39:$I$91,"메인",$L$39:$L$91,"전문몰")) -> 4 | G26: =IF($A26="","",COUNTIFS($D$39:$D$91,"아트라벨",$I$39:$I$91,"가격비교",$J$39:$J$91,"전문몰")+COUNTIFS($D$39:$D$91,"아트라벨",$I$39:$I$91,"가격비교",$K$39:$K$91,"전문몰")+COUNTIFS($D$39:$D$91,"아트라벨",$I$39:$I$91,"가격비교",$L$39:$L$91,"전문몰")) -> 0 | H26: =IF($A26="","",B26+C26+D26+E26+F26+G26) -> 14 | I26: =IF($A26="","",COUNTIFS($I$39:$I$91,"메인",$J$39:$J$91,"전문몰")) -> 3
A27: 디엘에스피 | B27: =IF($A27="","",COUNTIFS($D$39:$D$91,"유포라벨",$I$39:$I$91,"메인",$J$39:$J$91,"디엘에스피")+COUNTIFS($D$39:$D$91,"유포라벨",$I$39:$I$91,"메인",$K$39:$K$91,"디엘에스피")+COUNTIFS($D$39:$D$91,"유포라벨",$I$39:$I$91,"메인",$L$39:$L$91,"디엘에스피")) -> 6 | C27: =IF($A27="","",COUNTIFS($D$39:$D$91,"유포라벨",$I$39:$I$91,"가격비교",$J$39:$J$91,"디엘에스피")+COUNTIFS($D$39:$D$91,"유포라벨",$I$39:$I$91,"가격비교",$K$39:$K$91,"디엘에스피")+COUNTIFS($D$39:$D$91,"유포라벨",$I$39:$I$91,"가격비교",$L$39:$L$91,"디엘에스피")) -> 3 | D27: =IF($A27="","",COUNTIFS($D$39:$D$91,"감열라벨",$I$39:$I$91,"메인",$J$39:$J$91,"디엘에스피")+COUNTIFS($D$39:$D$91,"감열라벨",$I$39:$I$91,"메인",$K$39:$K$91,"디엘에스피")+COUNTIFS($D$39:$D$91,"감열라벨",$I$39:$I$91,"메인",$L$39:$L$91,"디엘에스피")) -> 6 | E27: =IF($A27="","",COUNTIFS($D$39:$D$91,"감열라벨",$I$39:$I$91,"가격비교",$J$39:$J$91,"디엘에스피")+COUNTIFS($D$39:$D$91,"감열라벨",$I$39:$I$91,"가격비교",$K$39:$K$91,"디엘에스피")+COUNTIFS($D$39:$D$91,"감열라벨",$I$39:$I$91,"가격비교",$L$39:$L$91,"디엘에스피")) -> 0 | F27: =IF($A27="","",COUNTIFS($D$39:$D$91,"아트라벨",$I$39:$I$91,"메인",$J$39:$J$91,"디엘에스피")+COUNTIFS($D$39:$D$91,"아트라벨",$I$39:$I$91,"메인",$K$39:$K$91,"디엘에스피")+COUNTIFS($D$39:$D$91,"아트라벨",$I$39:$I$91,"메인",$L$39:$L$91,"디엘에스피")) -> 1 | G27: =IF($A27="","",COUNTIFS($D$39:$D$91,"아트라벨",$I$39:$I$91,"가격비교",$J$39:$J$91,"디엘에스피")+COUNTIFS($D$39:$D$91,"아트라벨",$I$39:$I$91,"가격비교",$K$39:$K$91,"디엘에스피")+COUNTIFS($D$39:$D$91,"아트라벨",$I$39:$I$91,"가격비교",$L$39:$L$91,"디엘에스피")) -> 0 | H27: =IF($A27="","",B27+C27+D27+E27+F27+G27) -> 16 | I27: =IF($A27="","",COUNTIFS($I$39:$I$91,"메인",$J$39:$J$91,"디엘에스피")) -> 10 | J27: 감열 2,000원 · 유포 2,000원/5,500원 (10/6)
A28: 포스틱라벨스토어 | B28: =IF($A28="","",COUNTIFS($D$39:$D$91,"유포라벨",$I$39:$I$91,"메인",$J$39:$J$91,"포스틱라벨스토어")+COUNTIFS($D$39:$D$91,"유포라벨",$I$39:$I$91,"메인",$K$39:$K$91,"포스틱라벨스토어")+COUNTIFS($D$39:$D$91,"유포라벨",$I$39:$I$91,"메인",$L$39:$L$91,"포스틱라벨스토어")) -> 2 | C28: =IF($A28="","",COUNTIFS($D$39:$D$91,"유포라벨",$I$39:$I$91,"가격비교",$J$39:$J$91,"포스틱라벨스토어")+COUNTIFS($D$39:$D$91,"유포라벨",$I$39:$I$91,"가격비교",$K$39:$K$91,"포스틱라벨스토어")+COUNTIFS($D$39:$D$91,"유포라벨",$I$39:$I$91,"가격비교",$L$39:$L$91,"포스틱라벨스토어")) -> 2 | D28: =IF($A28="","",COUNTIFS($D$39:$D$91,"감열라벨",$I$39:$I$91,"메인",$J$39:$J$91,"포스틱라벨스토어")+COUNTIFS($D$39:$D$91,"감열라벨",$I$39:$I$91,"메인",$K$39:$K$91,"포스틱라벨스토어")+COUNTIFS($D$39:$D$91,"감열라벨",$I$39:$I$91,"메인",$L$39:$L$91,"포스틱라벨스토어")) -> 0 | E28: =IF($A28="","",COUNTIFS($D$39:$D$91,"감열라벨",$I$39:$I$91,"가격비교",$J$39:$J$91,"포스틱라벨스토어")+COUNTIFS($D$39:$D$91,"감열라벨",$I$39:$I$91,"가격비교",$K$39:$K$91,"포스틱라벨스토어")+COUNTIFS($D$39:$D$91,"감열라벨",$I$39:$I$91,"가격비교",$L$39:$L$91,"포스틱라벨스토어")) -> 0 | F28: =IF($A28="","",COUNTIFS($D$39:$D$91,"아트라벨",$I$39:$I$91,"메인",$J$39:$J$91,"포스틱라벨스토어")+COUNTIFS($D$39:$D$91,"아트라벨",$I$39:$I$91,"메인",$K$39:$K$91,"포스틱라벨스토어")+COUNTIFS($D$39:$D$91,"아트라벨",$I$39:$I$91,"메인",$L$39:$L$91,"포스틱라벨스토어")) -> 3 | G28: =IF($A28="","",COUNTIFS($D$39:$D$91,"아트라벨",$I$39:$I$91,"가격비교",$J$39:$J$91,"포스틱라벨스토어")+COUNTIFS($D$39:$D$91,"아트라벨",$I$39:$I$91,"가격비교",$K$39:$K$91,"포스틱라벨스토어")+COUNTIFS($D$39:$D$91,"아트라벨",$I$39:$I$91,"가격비교",$L$39:$L$91,"포스틱라벨스토어")) -> 0 | H28: =IF($A28="","",B28+C28+D28+E28+F28+G28) -> 7 | I28: =IF($A28="","",COUNTIFS($I$39:$I$91,"메인",$J$39:$J$91,"포스틱라벨스토어")) -> 1 | J28: 아트 4,400원 (10/2·10/6)
A29: 우주사무기 | B29: =IF($A29="","",COUNTIFS($D$39:$D$91,"유포라벨",$I$39:$I$91,"메인",$J$39:$J$91,"우주사무기")+COUNTIFS($D$39:$D$91,"유포라벨",$I$39:$I$91,"메인",$K$39:$K$91,"우주사무기")+COUNTIFS($D$39:$D$91,"유포라벨",$I$39:$I$91,"메인",$L$39:$L$91,"우주사무기")) -> 0 | C29: =IF($A29="","",COUNTIFS($D$39:$D$91,"유포라벨",$I$39:$I$91,"가격비교",$J$39:$J$91,"우주사무기")+COUNTIFS($D$39:$D$91,"유포라벨",$I$39:$I$91,"가격비교",$K$39:$K$91,"우주사무기")+COUNTIFS($D$39:$D$91,"유포라벨",$I$39:$I$91,"가격비교",$L$39:$L$91,"우주사무기")) -> 0 | D29: =IF($A29="","",COUNTIFS($D$39:$D$91,"감열라벨",$I$39:$I$91,"메인",$J$39:$J$91,"우주사무기")+COUNTIFS($D$39:$D$91,"감열라벨",$I$39:$I$91,"메인",$K$39:$K$91,"우주사무기")+COUNTIFS($D$39:$D$91,"감열라벨",$I$39:$I$91,"메인",$L$39:$L$91,"우주사무기")) -> 6 | E29: =IF($A29="","",COUNTIFS($D$39:$D$91,"감열라벨",$I$39:$I$91,"가격비교",$J$39:$J$91,"우주사무기")+COUNTIFS($D$39:$D$91,"감열라벨",$I$39:$I$91,"가격비교",$K$39:$K$91,"우주사무기")+COUNTIFS($D$39:$D$91,"감열라벨",$I$39:$I$91,"가격비교",$L$39:$L$91,"우주사무기")) -> 0 | F29: =IF($A29="","",COUNTIFS($D$39:$D$91,"아트라벨",$I$39:$I$91,"메인",$J$39:$J$91,"우주사무기")+COUNTIFS($D$39:$D$91,"아트라벨",$I$39:$I$91,"메인",$K$39:$K$91,"우주사무기")+COUNTIFS($D$39:$D$91,"아트라벨",$I$39:$I$91,"메인",$L$39:$L$91,"우주사무기")) -> 0 | G29: =IF($A29="","",COUNTIFS($D$39:$D$91,"아트라벨",$I$39:$I$91,"가격비교",$J$39:$J$91,"우주사무기")+COUNTIFS($D$39:$D$91,"아트라벨",$I$39:$I$91,"가격비교",$K$39:$K$91,"우주사무기")+COUNTIFS($D$39:$D$91,"아트라벨",$I$39:$I$91,"가격비교",$L$39:$L$91,"우주사무기")) -> 0 | H29: =IF($A29="","",B29+C29+D29+E29+F29+G29) -> 6 | I29: =IF($A29="","",COUNTIFS($I$39:$I$91,"메인",$J$39:$J$91,"우주사무기")) -> 0 | J29: 감열 2,000원 (10/6)
A30: 아이플랜스토어 | B30: =IF($A30="","",COUNTIFS($D$39:$D$91,"유포라벨",$I$39:$I$91,"메인",$J$39:$J$91,"아이플랜스토어")+COUNTIFS($D$39:$D$91,"유포라벨",$I$39:$I$91,"메인",$K$39:$K$91,"아이플랜스토어")+COUNTIFS($D$39:$D$91,"유포라벨",$I$39:$I$91,"메인",$L$39:$L$91,"아이플랜스토어")) -> 0 | C30: =IF($A30="","",COUNTIFS($D$39:$D$91,"유포라벨",$I$39:$I$91,"가격비교",$J$39:$J$91,"아이플랜스토어")+COUNTIFS($D$39:$D$91,"유포라벨",$I$39:$I$91,"가격비교",$K$39:$K$91,"아이플랜스토어")+COUNTIFS($D$39:$D$91,"유포라벨",$I$39:$I$91,"가격비교",$L$39:$L$91,"아이플랜스토어")) -> 0 | D30: =IF($A30="","",COUNTIFS($D$39:$D$91,"감열라벨",$I$39:$I$91,"메인",$J$39:$J$91,"아이플랜스토어")+COUNTIFS($D$39:$D$91,"감열라벨",$I$39:$I$91,"메인",$K$39:$K$91,"아이플랜스토어")+COUNTIFS($D$39:$D$91,"감열라벨",$I$39:$I$91,"메인",$L$39:$L$91,"아이플랜스토어")) -> 0 | E30: =IF($A30="","",COUNTIFS($D$39:$D$91,"감열라벨",$I$39:$I$91,"가격비교",$J$39:$J$91,"아이플랜스토어")+COUNTIFS($D$39:$D$91,"감열라벨",$I$39:$I$91,"가격비교",$K$39:$K$91,"아이플랜스토어")+COUNTIFS($D$39:$D$91,"감열라벨",$I$39:$I$91,"가격비교",$L$39:$L$91,"아이플랜스토어")) -> 0 | F30: =IF($A30="","",COUNTIFS($D$39:$D$91,"아트라벨",$I$39:$I$91,"메인",$J$39:$J$91,"아이플랜스토어")+COUNTIFS($D$39:$D$91,"아트라벨",$I$39:$I$91,"메인",$K$39:$K$91,"아이플랜스토어")+COUNTIFS($D$39:$D$91,"아트라벨",$I$39:$I$91,"메인",$L$39:$L$91,"아이플랜스토어")) -> 2 | G30: =IF($A30="","",COUNTIFS($D$39:$D$91,"아트라벨",$I$39:$I$91,"가격비교",$J$39:$J$91,"아이플랜스토어")+COUNTIFS($D$39:$D$91,"아트라벨",$I$39:$I$91,"가격비교",$K$39:$K$91,"아이플랜스토어")+COUNTIFS($D$39:$D$91,"아트라벨",$I$39:$I$91,"가격비교",$L$39:$L$91,"아이플랜스토어")) -> 0 | H30: =IF($A30="","",B30+C30+D30+E30+F30+G30) -> 2 | I30: =IF($A30="","",COUNTIFS($I$39:$I$91,"메인",$J$39:$J$91,"아이플랜스토어")) -> 0 | J30: 아트 7,000원 (10/6)
A31: 하이하이몰 | B31: =IF($A31="","",COUNTIFS($D$39:$D$91,"유포라벨",$I$39:$I$91,"메인",$J$39:$J$91,"하이하이몰")+COUNTIFS($D$39:$D$91,"유포라벨",$I$39:$I$91,"메인",$K$39:$K$91,"하이하이몰")+COUNTIFS($D$39:$D$91,"유포라벨",$I$39:$I$91,"메인",$L$39:$L$91,"하이하이몰")) -> 0 | C31: =IF($A31="","",COUNTIFS($D$39:$D$91,"유포라벨",$I$39:$I$91,"가격비교",$J$39:$J$91,"하이하이몰")+COUNTIFS($D$39:$D$91,"유포라벨",$I$39:$I$91,"가격비교",$K$39:$K$91,"하이하이몰")+COUNTIFS($D$39:$D$91,"유포라벨",$I$39:$I$91,"가격비교",$L$39:$L$91,"하이하이몰")) -> 0 | D31: =IF($A31="","",COUNTIFS($D$39:$D$91,"감열라벨",$I$39:$I$91,"메인",$J$39:$J$91,"하이하이몰")+COUNTIFS($D$39:$D$91,"감열라벨",$I$39:$I$91,"메인",$K$39:$K$91,"하이하이몰")+COUNTIFS($D$39:$D$91,"감열라벨",$I$39:$I$91,"메인",$L$39:$L$91,"하이하이몰")) -> 0 | E31: =IF($A31="","",COUNTIFS($D$39:$D$91,"감열라벨",$I$39:$I$91,"가격비교",$J$39:$J$91,"하이하이몰")+COUNTIFS($D$39:$D$91,"감열라벨",$I$39:$I$91,"가격비교",$K$39:$K$91,"하이하이몰")+COUNTIFS($D$39:$D$91,"감열라벨",$I$39:$I$91,"가격비교",$L$39:$L$91,"하이하이몰")) -> 0 | F31: =IF($A31="","",COUNTIFS($D$39:$D$91,"아트라벨",$I$39:$I$91,"메인",$J$39:$J$91,"하이하이몰")+COUNTIFS($D$39:$D$91,"아트라벨",$I$39:$I$91,"메인",$K$39:$K$91,"하이하이몰")+COUNTIFS($D$39:$D$91,"아트라벨",$I$39:$I$91,"메인",$L$39:$L$91,"하이하이몰")) -> 2 | G31: =IF($A31="","",COUNTIFS($D$39:$D$91,"아트라벨",$I$39:$I$91,"가격비교",$J$39:$J$91,"하이하이몰")+COUNTIFS($D$39:$D$91,"아트라벨",$I$39:$I$91,"가격비교",$K$39:$K$91,"하이하이몰")+COUNTIFS($D$39:$D$91,"아트라벨",$I$39:$I$91,"가격비교",$L$39:$L$91,"하이하이몰")) -> 0 | H31: =IF($A31="","",B31+C31+D31+E31+F31+G31) -> 2 | I31: =IF($A31="","",COUNTIFS($I$39:$I$91,"메인",$J$39:$J$91,"하이하이몰")) -> 0
A32: 조타라벨 | B32: =IF($A32="","",COUNTIFS($D$39:$D$91,"유포라벨",$I$39:$I$91,"메인",$J$39:$J$91,"조타라벨")+COUNTIFS($D$39:$D$91,"유포라벨",$I$39:$I$91,"메인",$K$39:$K$91,"조타라벨")+COUNTIFS($D$39:$D$91,"유포라벨",$I$39:$I$91,"메인",$L$39:$L$91,"조타라벨")) -> 0 | C32: =IF($A32="","",COUNTIFS($D$39:$D$91,"유포라벨",$I$39:$I$91,"가격비교",$J$39:$J$91,"조타라벨")+COUNTIFS($D$39:$D$91,"유포라벨",$I$39:$I$91,"가격비교",$K$39:$K$91,"조타라벨")+COUNTIFS($D$39:$D$91,"유포라벨",$I$39:$I$91,"가격비교",$L$39:$L$91,"조타라벨")) -> 0 | D32: =IF($A32="","",COUNTIFS($D$39:$D$91,"감열라벨",$I$39:$I$91,"메인",$J$39:$J$91,"조타라벨")+COUNTIFS($D$39:$D$91,"감열라벨",$I$39:$I$91,"메인",$K$39:$K$91,"조타라벨")+COUNTIFS($D$39:$D$91,"감열라벨",$I$39:$I$91,"메인",$L$39:$L$91,"조타라벨")) -> 1 | E32: =IF($A32="","",COUNTIFS($D$39:$D$91,"감열라벨",$I$39:$I$91,"가격비교",$J$39:$J$91,"조타라벨")+COUNTIFS($D$39:$D$91,"감열라벨",$I$39:$I$91,"가격비교",$K$39:$K$91,"조타라벨")+COUNTIFS($D$39:$D$91,"감열라벨",$I$39:$I$91,"가격비교",$L$39:$L$91,"조타라벨")) -> 0 | F32: =IF($A32="","",COUNTIFS($D$39:$D$91,"아트라벨",$I$39:$I$91,"메인",$J$39:$J$91,"조타라벨")+COUNTIFS($D$39:$D$91,"아트라벨",$I$39:$I$91,"메인",$K$39:$K$91,"조타라벨")+COUNTIFS($D$39:$D$91,"아트라벨",$I$39:$I$91,"메인",$L$39:$L$91,"조타라벨")) -> 0 | G32: =IF($A32="","",COUNTIFS($D$39:$D$91,"아트라벨",$I$39:$I$91,"가격비교",$J$39:$J$91,"조타라벨")+COUNTIFS($D$39:$D$91,"아트라벨",$I$39:$I$91,"가격비교",$K$39:$K$91,"조타라벨")+COUNTIFS($D$39:$D$91,"아트라벨",$I$39:$I$91,"가격비교",$L$39:$L$91,"조타라벨")) -> 0 | H32: =IF($A32="","",B32+C32+D32+E32+F32+G32) -> 1 | I32: =IF($A32="","",COUNTIFS($I$39:$I$91,"메인",$J$39:$J$91,"조타라벨")) -> 0
B33: =IF($A33="","",COUNTIFS($D$39:$D$91,"유포라벨",$I$39:$I$91,"메인",$J$39:$J$91,$A33)+COUNTIFS($D$39:$D$91,"유포라벨",$I$39:$I$91,"메인",$K$39:$K$91,$A33)+COUNTIFS($D$39:$D$91,"유포라벨",$I$39:$I$91,"메인",$L$39:$L$91,$A33)) | C33: =IF($A33="","",COUNTIFS($D$39:$D$91,"유포라벨",$I$39:$I$91,"가격비교",$J$39:$J$91,$A33)+COUNTIFS($D$39:$D$91,"유포라벨",$I$39:$I$91,"가격비교",$K$39:$K$91,$A33)+COUNTIFS($D$39:$D$91,"유포라벨",$I$39:$I$91,"가격비교",$L$39:$L$91,$A33)) | D33: =IF($A33="","",COUNTIFS($D$39:$D$91,"감열라벨",$I$39:$I$91,"메인",$J$39:$J$91,$A33)+COUNTIFS($D$39:$D$91,"감열라벨",$I$39:$I$91,"메인",$K$39:$K$91,$A33)+COUNTIFS($D$39:$D$91,"감열라벨",$I$39:$I$91,"메인",$L$39:$L$91,$A33)) | E33: =IF($A33="","",COUNTIFS($D$39:$D$91,"감열라벨",$I$39:$I$91,"가격비교",$J$39:$J$91,$A33)+COUNTIFS($D$39:$D$91,"감열라벨",$I$39:$I$91,"가격비교",$K$39:$K$91,$A33)+COUNTIFS($D$39:$D$91,"감열라벨",$I$39:$I$91,"가격비교",$L$39:$L$91,$A33)) | F33: =IF($A33="","",COUNTIFS($D$39:$D$91,"아트라벨",$I$39:$I$91,"메인",$J$39:$J$91,$A33)+COUNTIFS($D$39:$D$91,"아트라벨",$I$39:$I$91,"메인",$K$39:$K$91,$A33)+COUNTIFS($D$39:$D$91,"아트라벨",$I$39:$I$91,"메인",$L$39:$L$91,$A33)) | G33: =IF($A33="","",COUNTIFS($D$39:$D$91,"아트라벨",$I$39:$I$91,"가격비교",$J$39:$J$91,$A33)+COUNTIFS($D$39:$D$91,"아트라벨",$I$39:$I$91,"가격비교",$K$39:$K$91,$A33)+COUNTIFS($D$39:$D$91,"아트라벨",$I$39:$I$91,"가격비교",$L$39:$L$91,$A33)) | H33: =IF($A33="","",B33+C33+D33+E33+F33+G33) | I33: =IF($A33="","",COUNTIFS($I$39:$I$91,"메인",$J$39:$J$91,$A33))
B34: =IF($A34="","",COUNTIFS($D$39:$D$91,"유포라벨",$I$39:$I$91,"메인",$J$39:$J$91,$A34)+COUNTIFS($D$39:$D$91,"유포라벨",$I$39:$I$91,"메인",$K$39:$K$91,$A34)+COUNTIFS($D$39:$D$91,"유포라벨",$I$39:$I$91,"메인",$L$39:$L$91,$A34)) | C34: =IF($A34="","",COUNTIFS($D$39:$D$91,"유포라벨",$I$39:$I$91,"가격비교",$J$39:$J$91,$A34)+COUNTIFS($D$39:$D$91,"유포라벨",$I$39:$I$91,"가격비교",$K$39:$K$91,$A34)+COUNTIFS($D$39:$D$91,"유포라벨",$I$39:$I$91,"가격비교",$L$39:$L$91,$A34)) | D34: =IF($A34="","",COUNTIFS($D$39:$D$91,"감열라벨",$I$39:$I$91,"메인",$J$39:$J$91,$A34)+COUNTIFS($D$39:$D$91,"감열라벨",$I$39:$I$91,"메인",$K$39:$K$91,$A34)+COUNTIFS($D$39:$D$91,"감열라벨",$I$39:$I$91,"메인",$L$39:$L$91,$A34)) | E34: =IF($A34="","",COUNTIFS($D$39:$D$91,"감열라벨",$I$39:$I$91,"가격비교",$J$39:$J$91,$A34)+COUNTIFS($D$39:$D$91,"감열라벨",$I$39:$I$91,"가격비교",$K$39:$K$91,$A34)+COUNTIFS($D$39:$D$91,"감열라벨",$I$39:$I$91,"가격비교",$L$39:$L$91,$A34)) | F34: =IF($A34="","",COUNTIFS($D$39:$D$91,"아트라벨",$I$39:$I$91,"메인",$J$39:$J$91,$A34)+COUNTIFS($D$39:$D$91,"아트라벨",$I$39:$I$91,"메인",$K$39:$K$91,$A34)+COUNTIFS($D$39:$D$91,"아트라벨",$I$39:$I$91,"메인",$L$39:$L$91,$A34)) | G34: =IF($A34="","",COUNTIFS($D$39:$D$91,"아트라벨",$I$39:$I$91,"가격비교",$J$39:$J$91,$A34)+COUNTIFS($D$39:$D$91,"아트라벨",$I$39:$I$91,"가격비교",$K$39:$K$91,$A34)+COUNTIFS($D$39:$D$91,"아트라벨",$I$39:$I$91,"가격비교",$L$39:$L$91,$A34)) | H34: =IF($A34="","",B34+C34+D34+E34+F34+G34) | I34: =IF($A34="","",COUNTIFS($I$39:$I$91,"메인",$J$39:$J$91,$A34))
A36: ③ 입찰 조사 기록 (9/28~10/6 · 유포/감열/아트라벨)
A37: 파란 글씨 = 원본 조사 기록. 순위가 숫자로 안 적힌 조사(예: “1페이지 중단”)는 순위 칸을 비우고 메모에 원문을 남겼습니다. 새 조사는 아래 노란 줄에 이어서 적으면 됩니다.
A38: 날짜 | B38: 시각 | C38: 시간대 | D38: 키워드 | E38: 광고 상품 | F38: 입찰가(원) | G38: 가격비교 순위 | H38: 메인 순위 | I38: 업체 순위 지면 | J38: 1위 업체 | K38: 2위 업체 | L38: 3위 업체 | M38: 메모
A39: 46293 | B39: 13:42 | C39: 점심(12~14) | D39: 유포라벨 | E39: 중국라벨 유포지 30*15 | F39: 1500 | I39: 가격비교 | J39: 디엘에스피 | K39: 디엘에스피 | L39: 포스틱라벨스토어 | M39: 가격비교: 1페이지 중단
A40: 46293 | B40: 15:37 | C40: 오후(14~18) | D40: 유포라벨 | E40: 중국라벨 유포지 30*15 | F40: 2000 | M40: 가격비교: 1페이지 중단
A41: 46293 | B41: 15:50 | C41: 오후(14~18) | D41: 유포라벨 | E41: 중국라벨 유포지 30*15 | F41: 2500 | M41: 가격비교: 1페이지 중단
A42: 46293 | B42: 15:56 | C42: 오후(14~18) | D42: 유포라벨 | E42: 중국라벨 유포지 30*15 | F42: 3000 | G42: 2 | I42: 가격비교 | J42: 디엘에스피 | K42: 전문몰 | L42: 포스틱라벨스토어
A43: 46293 | C43: 오후(14~18) | D43: 유포라벨 | E43: 중국라벨 유포지 30*15 | F43: 3500 | G43: 2
A44: 46294 | B44: 10:40 | C44: 오전(09~13) | D44: 유포라벨 | E44: 중국라벨 유포지 30*15 | F44: 3500 | G44: 2
...

Sheet 2.중국라벨 판매현황
A1: 중국라벨 판매현황
A2: 재고 · 쇼핑검색 광고 효과 · 9/22 가격 수정 효과 | 출처: 재고 프로그램 실재고(10/7) · 라벨 마스터 판매현황(10/6까지)
A4: 기준값 (노란 칸을 바꾸면 아래 표가 다시 계산됩니다)
A5: 실재고 기준일 | C5: 46302 | D5: 재고 프로그램 실재고 (2026-10-07 파일)
A6: 집계 마지막 날 | C6: 46301 | D6: 판매현황의 마지막 판매일
A7: 광고 테스트 시작 | C7: 46293 | D7: 요청 내용 기준. 실제 시작일과 다르면 고쳐 주세요
A8: 광고 테스트 종료 | C8: 46301
A9: 가격 수정일 | C9: 46287 | D9: 아트지 35*20, 아트지 100*100
A10: 부족 기준(롤 이하) | C10: 10 | D10: 현재고가 이 값 이하이면 “부족”
A12: 요약
A13: 현재 재고 합계 | C13: =F53 -> 994 | E13: ="규격 "&B53&"개 · 품절 "&G53&"개 · 부족 "&H53&"개 (현재고 "&$C$10&"롤 이하)" -> 규격 24개 · 품절 4개 · 부족 5개 (현재고 10롤 이하)
A14: 광고 중 전문몰 판매 | C14: =E62&"건 · "&F62&"롤" -> 4건 · 8롤 | E14: ="광고 전 같은 기간 "&C62&"건 · "&D62&"롤 / 평소 수준 "&TEXT(I62,"0.0")&"건 · "&TEXT(J62,"0.0")&"롤" -> 광고 전 같은 기간 1건 · 5롤 / 평소 수준 2.8건 · 6.4롤
A15: 광고 효과 판단 | C15: =IF(E62>I62,"건수 증가 (초기 신호)",IF(E62<I62,"건수 감소","변화 없음")) -> 건수 증가 (초기 신호) | E15: ="테스트 기간 "&$E$58&"일, 건수가 적어 우연일 가능성이 있습니다. 2~4주 더 보고 판단하는 것이 안전합니다." -> 테스트 기간 9일, 건수가 적어 우연일 가능성이 있습니다. 2~4주 더 보고 판단하는 것이 안전합니다.
A16: 35*20 가격 수정 후 판매 | C16: =H90&"건 · "&I90&"롤" -> 0건 · 0롤 | E16: =K90 -> 전·후 판매 없음 · 효과 미확인
A17: 100*100 가격 수정 후 판매 | C17: =H91&"건 · "&I91&"롤" -> 0건 · 0롤 | E17: =K91 -> 수정 후 판매 없음 · 아직 효과 없음
A20: 1. 재고 현황
A21: 실재고 = 재고 프로그램 10/7 재고. 전체 출고 = 총 입고 − 실재고 · 오픈마켓 판매 = 판매현황 합계 · 일반 판매 = 전체 출고 − 오픈마켓 판매 (라벨 마스터 V16과 같은 계산)
A22: 재질 | B22: 규격 | C22: 총 입고 | D22: 전체 출고 (입고−실재고) | E22: 오픈마켓 판매 (판매현황) | F22: 실재고 (10/7) | G22: 상태 | H22: 최근 4주 오픈마켓 판매 | I22: 소진 예상 (주) | J22: 판매가 (VAT 포함) | K22: 일반 판매 (출고−오픈마켓) | L22: 비고
A23: 아트지 | B23: 35*20 | C23: 120 | D23: =C23-F23 -> 16 | E23: =SUMIFS(원본_판매현황!$E$2:$E$500,원본_판매현황!$B$2:$B$500,$A23,원본_판매현황!$C$2:$C$500,$B23,원본_판매현황!$A$2:$A$500,"<="&$C$6) -> 0 | F23: 104 | G23: =IF(F23<=0,"품절",IF(F23<=$C$10,"부족","여유")) -> 여유 | H23: =SUMIFS(원본_판매현황!$E$2:$E$500,원본_판매현황!$B$2:$B$500,$A23,원본_판매현황!$C$2:$C$500,$B23,원본_판매현황!$A$2:$A$500,">"&($C$6-28),원본_판매현황!$A$2:$A$500,"<="&$C$6) -> 0 | I23: =IF(OR(H23=0,F23<=0),"-",F23/(H23/4)) -> - | J23: 2750 | K23: =D23-E23 -> 16 | L23: 오픈마켓 판매 아님
A24: 아트지 | B24: 40*20 | C24: 100 | D24: =C24-F24 -> 71 | E24: =SUMIFS(원본_판매현황!$E$2:$E$500,원본_판매현황!$B$2:$B$500,$A24,원본_판매현황!$C$2:$C$500,$B24,원본_판매현황!$A$2:$A$500,"<="&$C$6) -> 14 | F24: 29 | G24: =IF(F24<=0,"품절",IF(F24<=$C$10,"부족","여유")) -> 여유 | H24: =SUMIFS(원본_판매현황!$E$2:$E$500,원본_판매현황!$B$2:$B$500,$A24,원본_판매현황!$C$2:$C$500,$B24,원본_판매현황!$A$2:$A$500,">"&($C$6-28),원본_판매현황!$A$2:$A$500,"<="&$C$6) -> 12 | I24: =IF(OR(H24=0,F24<=0),"-",F24/(H24/4)) -> 9.6666667 | J24: 2750 | K24: =D24-E24 -> 57 | L24: 전문몰 2롤
A25: 아트지 | B25: 50*30 | C25: 120 | D25: =C25-F25 -> 78 | E25: =SUMIFS(원본_판매현황!$E$2:$E$500,원본_판매현황!$B$2:$B$500,$A25,원본_판매현황!$C$2:$C$500,$B25,원본_판매현황!$A$2:$A$500,"<="&$C$6) -> 0 | F25: 42 | G25: =IF(F25<=0,"품절",IF(F25<=$C$10,"부족","여유")) -> 여유 | H25: =SUMIFS(원본_판매현황!$E$2:$E$500,원본_판매현황!$B$2:$B$500,$A25,원본_판매현황!$C$2:$C$500,$B25,원본_판매현황!$A$2:$A$500,">"&($C$6-28),원본_판매현황!$A$2:$A$500,"<="&$C$6) -> 0 | I25: =IF(OR(H25=0,F25<=0),"-",F25/(H25/4)) -> - | J25: 4400 | K25: =D25-E25 -> 78 | L25: 전문몰 1롤
A26: 아트지 | B26: 50*50 | C26: 70 | D26: =C26-F26 -> 52 | E26: =SUMIFS(원본_판매현황!$E$2:$E$500,원본_판매현황!$B$2:$B$500,$A26,원본_판매현황!$C$2:$C$500,$B26,원본_판매현황!$A$2:$A$500,"<="&$C$6) -> 22 | F26: 18 | G26: =IF(F26<=0,"품절",IF(F26<=$C$10,"부족","여유")) -> 여유 | H26: =SUMIFS(원본_판매현황!$E$2:$E$500,원본_판매현황!$B$2:$B$500,$A26,원본_판매현황!$C$2:$C$500,$B26,원본_판매현황!$A$2:$A$500,">"&($C$6-28),원본_판매현황!$A$2:$A$500,"<="&$C$6) -> 1 | I26: =IF(OR(H26=0,F26<=0),"-",F26/(H26/4)) -> 72 | J26: 3850 | K26: =D26-E26 -> 30 | L26: 지마켓 20롤 + 쿠팡 2롤
A27: 아트지 | B27: 60*40 | C27: 100 | D27: =C27-F27 -> 9 | E27: =SUMIFS(원본_판매현황!$E$2:$E$500,원본_판매현황!$B$2:$B$500,$A27,원본_판매현황!$C$2:$C$500,$B27,원본_판매현황!$A$2:$A$500,"<="&$C$6) -> 9 | F27: 91 | G27: =IF(F27<=0,"품절",IF(F27<=$C$10,"부족","여유")) -> 여유 | H27: =SUMIFS(원본_판매현황!$E$2:$E$500,원본_판매현황!$B$2:$B$500,$A27,원본_판매현황!$C$2:$C$500,$B27,원본_판매현황!$A$2:$A$500,">"&($C$6-28),원본_판매현황!$A$2:$A$500,"<="&$C$6) -> 8 | I27: =IF(OR(H27=0,F27<=0),"-",F27/(H27/4)) -> 45.5 | J27: 4930 | K27: =D27-E27 -> 0 | L27: 쿠팡 1롤+전문몰 6롤
A28: 아트지 | B28: 70*40 | C28: 50 | D28: =C28-F28 -> 50 | E28: =SUMIFS(원본_판매현황!$E$2:$E$500,원본_판매현황!$B$2:$B$500,$A28,원본_판매현황!$C$2:$C$500,$B28,원본_판매현황!$A$2:$A$500,"<="&$C$6) -> 0 | F28: 0 | G28: =IF(F28<=0,"품절",IF(F28<=$C$10,"부족","여유")) -> 품절 | H28: =SUMIFS(원본_판매현황!$E$2:$E$500,원본_판매현황!$B$2:$B$500,$A28,원본_판매현황!$C$2:$C$500,$B28,원본_판매현황!$A$2:$A$500,">"&($C$6-28),원본_판매현황!$A$2:$A$500,"<="&$C$6) -> 0 | I28: =IF(OR(H28=0,F28<=0),"-",F28/(H28/4)) -> - | K28: =D28-E28 -> 50
A29: 아트지 | B29: 80*60 | C29: 100 | D29: =C29-F29 -> 87 | E29: =SUMIFS(원본_판매현황!$E$2:$E$500,원본_판매현황!$B$2:$B$500,$A29,원본_판매현황!$C$2:$C$500,$B29,원본_판매현황!$A$2:$A$500,"<="&$C$6) -> 3 | F29: 13 | G29: =IF(F29<=0,"품절",IF(F29<=$C$10,"부족","여유")) -> 여유 | H29: =SUMIFS(원본_판매현황!$E$2:$E$500,원본_판매현황!$B$2:$B$500,$A29,원본_판매현황!$C$2:$C$500,$B29,원본_판매현황!$A$2:$A$500,">"&($C$6-28),원본_판매현황!$A$2:$A$500,"<="&$C$6) -> 2 | I29: =IF(OR(H29=0,F29<=0),"-",F29/(H29/4)) -> 26 | J29: 7150 | K29: =D29-E29 -> 84 | L29: 오픈마켓 판매 아님
A30: 아트지 | B30: 100*60 | C30: 80 | D30: =C30-F30 -> 72 | E30: =SUMIFS(원본_판매현황!$E$2:$E$500,원본_판매현황!$B$2:$B$500,$A30,원본_판매현황!$C$2:$C$500,$B30,원본_판매현황!$A$2:$A$500,"<="&$C$6) -> 13 | F30: 8 | G30: =IF(F30<=0,"품절",IF(F30<=$C$10,"부족","여유")) -> 부족 | H30: =SUMIFS(원본_판매현황!$E$2:$E$500,원본_판매현황!$B$2:$B$500,$A30,원본_판매현황!$C$2:$C$500,$B30,원본_판매현황!$A$2:$A$500,">"&($C$6-28),원본_판매현황!$A$2:$A$500,"<="&$C$6) -> 0 | I30: =IF(OR(H30=0,F30<=0),"-",F30/(H30/4)) -> - | J30: 7150 | K30: =D30-E30 -> 59 | L30: 지마켓 5롤 + 쿠팡 2롤+전문몰 6롤
A31: 아트지 | B31: 100*70 | C31: 70 | D31: =C31-F31 -> 68 | E31: =SUMIFS(원본_판매현황!$E$2:$E$500,원본_판매현황!$B$2:$B$500,$A31,원본_판매현황!$C$2:$C$500,$B31,원본_판매현황!$A$2:$A$500,"<="&$C$6) -> 0 | F31: 2 | G31: =IF(F31<=0,"품절",IF(F31<=$C$10,"부족","여유")) -> 부족 | H31: =SUMIFS(원본_판매현황!$E$2:$E$500,원본_판매현황!$B$2:$B$500,$A31,원본_판매현황!$C$2:$C$500,$B31,원본_판매현황!$A$2:$A$500,">"&($C$6-28),원본_판매현황!$A$2:$A$500,"<="&$C$6) -> 0 | I31: =IF(OR(H31=0,F31<=0),"-",F31/(H31/4)) -> - | J31: 10760 | K31: =D31-E31 -> 68 | L31: 오픈마켓 판매 아님
A32: 아트지 | B32: 100*100 | C32: 80 | D32: =C32-F32 -> 50 | E32: =SUMIFS(원본_판매현황!$E$2:$E$500,원본_판매현황!$B$2:$B$500,$A32,원본_판매현황!$C$2:$C$500,$B32,원본_판매현황!$A$2:$A$500,"<="&$C$6) -> 11 | F32: 30 | G32: =IF(F32<=0,"품절",IF(F32<=$C$10,"부족","여유")) -> 여유 | H32: =SUMIFS(원본_판매현황!$E$2:$E$500,원본_판매현황!$B$2:$B$500,$A32,원본_판매현황!$C$2:$C$500,$B32,원본_판매현황!$A$2:$A$500,">"&($C$6-28),원본_판매현황!$A$2:$A$500,"<="&$C$6) -> 0 | I32: =IF(OR(H32=0,F32<=0),"-",F32/(H32/4)) -> - | J32: 7700 | K32: =D32-E32 -> 39 | L32: 전문몰 11롤
A33: 유포지 | B33: 30*15 | C33: 80 | D33: =C33-F33 -> 12 | E33: =SUMIFS(원본_판매현황!$E$2:$E$500,원본_판매현황!$B$2:$B$500,$A33,원본_판매현황!$C$2:$C$500,$B33,원본_판매현황!$A$2:$A$500,"<="&$C$6) -> 12 | F33: 68 | G33: =IF(F33<=0,"품절",IF(F33<=$C$10,"부족","여유")) -> 여유 | H33: =SUMIFS(원본_판매현황!$E$2:$E$500,원본_판매현황!$B$2:$B$500,$A33,원본_판매현황!$C$2:$C$500,$B33,원본_판매현황!$A$2:$A$500,">"&($C$6-28),원본_판매현황!$A$2:$A$500,"<="&$C$6) -> 2 | I33: =IF(OR(H33=0,F33<=0),"-",F33/(H33/4)) -> 136 | J33: 5020 | K33: =D33-E33 -> 0 | L33: 쿠팡 2롤 + 전문몰 8롤
A34: 유포지 | B34: 40*20 | C34: 80 | D34: =C34-F34 -> 0 | E34: =SUMIFS(원본_판매현황!$E$2:$E$500,원본_판매현황!$B$2:$B$500,$A34,원본_판매현황!$C$2:$C$500,$B34,원본_판매현황!$A$2:$A$500,"<="&$C$6) -> 0 | F34: 80 | G34: =IF(F34<=0,"품절",IF(F34<=$C$10,"부족","여유")) -> 여유 | H34: =SUMIFS(원본_판매현황!$E$2:$E$500,원본_판매현황!$B$2:$B$500,$A34,원본_판매현황!$C$2:$C$500,$B34,원본_판매현황!$A$2:$A$500,">"&($C$6-28),원본_판매현황!$A$2:$A$500,"<="&$C$6) -> 0 | I34: =IF(OR(H34=0,F34<=0),"-",F34/(H34/4)) -> - | J34: 6140 | K34: =D34-E34 -> 0
A35: 유포지 | B35: 50*30 | C35: 50 | D35: =C35-F35 -> 50 | E35: =SUMIFS(원본_판매현황!$E$2:$E$500,원본_판매현황!$B$2:$B$500,$A35,원본_판매현황!$C$2:$C$500,$B35,원본_판매현황!$A$2:$A$500,"<="&$C$6) -> 50 | F35: 0 | G35: =IF(F35<=0,"품절",IF(F35<=$C$10,"부족","여유")) -> 품절 | H35: =SUMIFS(원본_판매현황!$E$2:$E$500,원본_판매현황!$B$2:$B$500,$A35,원본_판매현황!$C$2:$C$500,$B35,원본_판매현황!$A$2:$A$500,">"&($C$6-28),원본_판매현황!$A$2:$A$500,"<="&$C$6) -> 0 | I35: =IF(OR(H35=0,F35<=0),"-",F35/(H35/4)) -> - | K35: =D35-E35 -> 0 | L35: 전문몰 50롤
A36: 유포지 | B36: 60*40 | C36: 50 | D36: =C36-F36 -> 48 | E36: =SUMIFS(원본_판매현황!$E$2:$E$500,원본_판매현황!$B$2:$B$500,$A36,원본_판매현황!$C$2:$C$500,$B36,원본_판매현황!$A$2:$A$500,"<="&$C$6) -> 5 | F36: 2 | G36: =IF(F36<=0,"품절",IF(F36<=$C$10,"부족","여유")) -> 부족 | H36: =SUMIFS(원본_판매현황!$E$2:$E$500,원본_판매현황!$B$2:$B$500,$A36,원본_판매현황!$C$2:$C$500,$B36,원본_판매현황!$A$2:$A$500,">"&($C$6-28),원본_판매현황!$A$2:$A$500,"<="&$C$6) -> 0 | I36: =IF(OR(H36=0,F36<=0),"-",F36/(H36/4)) -> - | J36: 5780 | K36: =D36-E36 -> 43 | L36: 전문몰 5롤
A37: 유포지 | B37: 70*50 | C37: 60 | D37: =C37-F37 -> 45 | E37: =SUMIFS(원본_판매현황!$E$2:$E$500,원본_판매현황!$B$2:$B$500,$A37,원본_판매현황!$C$2:$C$500,$B37,원본_판매현황!$A$2:$A$500,"<="&$C$6) -> 12 | F37: 15 | G37: =IF(F37<=0,"품절",IF(F37<=$C$10,"부족","여유")) -> 여유 | H37: =SUMIFS(원본_판매현황!$E$2:$E$500,원본_판매현황!$B$2:$B$500,$A37,원본_판매현황!$C$2:$C$500,$B37,원본_판매현황!$A$2:$A$500,">"&($C$6-28),원본_판매현황!$A$2:$A$500,"<="&$C$6) -> 5 | I37: =IF(OR(H37=0,F37<=0),"-",F37/(H37/4)) -> 12 | J37: 5980 | K37: =D37-E37 -> 33 | L37: 쿠팡 1롤 + 전문몰 6롤
A38: 유포지 | B38: 70*60 | C38: 50 | D38: =C38-F38 -> 0 | E38: =SUMIFS(원본_판매현황!$E$2:$E$500,원본_판매현황!$B$2:$B$500,$A38,원본_판매현황!$C$2:$C$500,$B38,원본_판매현황!$A$2:$A$500,"<="&$C$6) -> 0 | F38: 50 | G38: =IF(F38<=0,"품절",IF(F38<=$C$10,"부족","여유")) -> 여유 | H38: =SUMIFS(원본_판매현황!$E$2:$E$500,원본_판매현황!$B$2:$B$500,$A38,원본_판매현황!$C$2:$C$500,$B38,원본_판매현황!$A$2:$A$500,">"&($C$6-28),원본_판매현황!$A$2:$A$500,"<="&$C$6) -> 0 | I38: =IF(OR(H38=0,F38<=0),"-",F38/(H38/4)) -> - | J38: 7170 | K38: =D38-E38 -> 0
A39: 유포지 | B39: 100*35 | C39: 50 | D39: =C39-F39 -> 14 | E39: =SUMIFS(원본_판매현황!$E$2:$E$500,원본_판매현황!$B$2:$B$500,$A39,원본_판매현황!$C$2:$C$500,$B39,원본_판매현황!$A$2:$A$500,"<="&$C$6) -> 1 | F39: 36 | G39: =IF(F39<=0,"품절",IF(F39<=$C$10,"부족","여유")) -> 여유 | H39: =SUMIFS(원본_판매현황!$E$2:$E$500,원본_판매현황!$B$2:$B$500,$A39,원본_판매현황!$C$2:$C$500,$B39,원본_판매현황!$A$2:$A$500,">"&($C$6-28),원본_판매현황!$A$2:$A$500,"<="&$C$6) -> 0 | I39: =IF(OR(H39=0,F39<=0),"-",F39/(H39/4)) -> - | J39: 14180 | K39: =D39-E39 -> 13 | L39: 전문몰 1롤
A40: 유포지 | B40: 100*70 | C40: 55 | D40: =C40-F40 -> 55 | E40: =SUMIFS(원본_판매현황!$E$2:$E$500,원본_판매현황!$B$2:$B$500,$A40,원본_판매현황!$C$2:$C$500,$B40,원본_판매현황!$A$2:$A$500,"<="&$C$6) -> 2 | F40: 0 | G40: =IF(F40<=0,"품절",IF(F40<=$C$10,"부족","여유")) -> 품절 | H40: =SUMIFS(원본_판매현황!$E$2:$E$500,원본_판매현황!$B$2:$B$500,$A40,원본_판매현황!$C$2:$C$500,$B40,원본_판매현황!$A$2:$A$500,">"&($C$6-28),원본_판매현황!$A$2:$A$500,"<="&$C$6) -> 1 | I40: =IF(OR(H40=0,F40<=0),"-",F40/(H40/4)) -> - | J40: 10590 | K40: =D40-E40 -> 53 | L40: 전문몰 1롤 + 쿠팡 1롤
A41: 유포지 | B41: 100*80 | C41: 50 | D41: =C41-F41 -> 42 | E41: =SUMIFS(원본_판매현황!$E$2:$E$500,원본_판매현황!$B$2:$B$500,$A41,원본_판매현황!$C$2:$C$500,$B41,원본_판매현황!$A$2:$A$500,"<="&$C$6) -> 19 | F41: 8 | G41: =IF(F41<=0,"품절",IF(F41<=$C$10,"부족","여유")) -> 부족 | H41: =SUMIFS(원본_판매현황!$E$2:$E$500,원본_판매현황!$B$2:$B$500,$A41,원본_판매현황!$C$2:$C$500,$B41,원본_판매현황!$A$2:$A$500,">"&($C$6-28),원본_판매현황!$A$2:$A$500,"<="&$C$6) -> 0 | I41: =IF(OR(H41=0,F41<=0),"-",F41/(H41/4)) -> - | J41: 8920 | K41: =D41-E41 -> 23 | L41: 지마켓 19롤
A42: 유포지 | B42: 100*90 | C42: 50 | D42: =C42-F42 -> 23 | E42: =SUMIFS(원본_판매현황!$E$2:$E$500,원본_판매현황!$B$2:$B$500,$A42,원본_판매현황!$C$2:$C$500,$B42,원본_판매현황!$A$2:$A$500,"<="&$C$6) -> 3 | F42: 27 | G42: =IF(F42<=0,"품절",IF(F42<=$C$10,"부족","여유")) -> 여유 | H42: =SUMIFS(원본_판매현황!$E$2:$E$500,원본_판매현황!$B$2:$B$500,$A42,원본_판매현황!$C$2:$C$500,$B42,원본_판매현황!$A$2:$A$500,">"&($C$6-28),원본_판매현황!$A$2:$A$500,"<="&$C$6) -> 0 | I42: =IF(OR(H42=0,F42<=0),"-",F42/(H42/4)) -> - | J42: 13930 | K42: =D42-E42 -> 20 | L42: 쿠팡 1롤 + 전문몰 2롤
A43: 유포지 | B43: 100*100 | C43: 67 | D43: =C43-F43 -> 67 | E43: =SUMIFS(원본_판매현황!$E$2:$E$500,원본_판매현황!$B$2:$B$500,$A43,원본_판매현황!$C$2:$C$500,$B43,원본_판매현황!$A$2:$A$500,"<="&$C$6) -> 14 | F43: 0 | G43: =IF(F43<=0,"품절",IF(F43<=$C$10,"부족","여유")) -> 품절 | H43: =SUMIFS(원본_판매현황!$E$2:$E$500,원본_판매현황!$B$2:$B$500,$A43,원본_판매현황!$C$2:$C$500,$B43,원본_판매현황!$A$2:$A$500,">"&($C$6-28),원본_판매현황!$A$2:$A$500,"<="&$C$6) -> 0 | I43: =IF(OR(H43=0,F43<=0),"-",F43/(H43/4)) -> - | J43: 8490 | K43: =D43-E43 -> 53 | L43: 전문몰 14롤
A44: 유포지 | B44: 100*150 | C44: 50 | D44: =C44-F44 -> 48 | E44: =SUMIFS(원본_판매현황!$E$2:$E$500,원본_판매현황!$B$2:$B$500,$A44,원본_판매현황!$C$2:$C$500,$B44,원본_판매현황!$A$2:$A$500,"<="&$C$6) -> 5 | F44: 2 | G44: =IF(F44<=0,"품절",IF(F44<=$C$10,"부족","여유")) -> 부족 | H44: =SUMIFS(원본_판매현황!$E$2:$E$500,원본_판매현황!$B$2:$B$500,$A44,원본_판매현황!$C$2:$C$500,$B44,원본_판매현황!$A$2:$A$500,">"&($C$6-28),원본_판매현황!$A$2:$A$500,"<="&$C$6) -> 0 | I44: =IF(OR(H44=0,F44<=0),"-",F44/(H44/4)) -> - | J44: 10200 | K44: =D44-E44 -> 43 | L44: 전문몰 5롤
...

Sheet 원본_판매현황
A1: 판매일자 | B1: 재질 | C1: 규격 | D1: 판매처 | E1: 판매수량(롤) | F1: 판매가격(원) | G1: 비고
A2: 46168 | B2: 유포지 | C2: 50*30 | D2: 전문몰 | E2: 50 | F2: 4950 | G2: 품절/광고안함
A3: 46169 | B3: 아트지 | C3: 50*50 | D3: 지마켓 | E3: 20 | F3: 3850
A4: 46183 | B4: 유포지 | C4: 30*15 | D4: 전문몰 | E4: 5 | F4: 5020 | G4: 왁스레진 함께 출고
A5: 46184 | B5: 유포지 | C5: 100*70 | D5: 전문몰 | E5: 1
A6: 46185 | B6: 유포지 | C6: 30*15 | D6: 전문몰 | E6: 1 | F6: 5020
A7: 46191 | B7: 아트지 | C7: 100*100 | D7: 전문몰 | E7: 10 | F7: 7980 | G7: 오픈몰x재고 없어서/퀵
A8: 46195 | B8: 유포지 | C8: 60*40 | D8: 전문몰 | E8: 5 | F8: 5780 | G8: 레진과 함께 출고
A9: 46203 | B9: 유포지 | C9: 100*150 | D9: 전문몰 | E9: 5 | F9: 10200
A10: 46211 | B10: 유포지 | C10: 70*50 | D10: 쿠팡 | E10: 1 | F10: 5990
A11: 46234 | B11: 유포지 | C11: 100*90 | D11: 쿠팡 | E11: 1
A12: 46237 | B12: 아트지 | C12: 60*40 | D12: 쿠팡 | E12: 1 | F12: 4930
A13: 46238 | B13: 유포지 | C13: 100*90 | D13: 전문몰 | E13: 2
A14: 46241 | B14: 유포지 | C14: 100*35 | D14: 전문몰 | E14: 1
A15: 46247 | B15: 유포지 | C15: 100*100 | D15: 전문몰 | E15: 2
A16: 46247 | B16: 유포지 | C16: 100*100 | D16: 전문몰 | E16: 5
A17: 46254 | B17: 아트지 | C17: 100*60 | D17: 지마켓 | E17: 5 | F17: 7150
A18: 46255 | B18: 유포지 | C18: 100*100 | D18: 전문몰 | E18: 1
A19: 46255 | B19: 유포지 | C19: 100*100 | D19: 전문몰 | E19: 5
A20: 46255 | B20: 유포지 | C20: 100*100 | D20: 전문몰 | E20: 1
A21: 46255 | B21: 감열지 | C21: 100*100 | D21: 지마켓 | E21: 16 | F21: 9350
A22: 46258 | B22: 유포지 | C22: 70*50 | D22: 전문몰 | E22: 4
A23: 46260 | B23: 유포지 | C23: 70*50 | D23: 전문몰 | E23: 1 | G23: 전문몰 총 99롤
A24: 46261 | B24: 유포지 | C24: 100*80 | D24: 지마켓 | E24: 19 | G24: 지마켓 총 63롤
A25: 46261 | B25: 감열지 | C25: 80*70 | D25: 쿠팡 | E25: 1 | F25: 6930
A26: 46261 | B26: 유포지 | C26: 30*15 | D26: 쿠팡 | E26: 2 | F26: 5030 | G26: 쿠팡 총 14롤
A27: 46261 | B27: 아트지 | C27: 100*60 | D27: 쿠팡 | E27: 2 | F27: 7150
A28: 46267 | B28: 아트지 | C28: 100*60 | D28: 전문몰 | E28: 5
A29: 46268 | B29: 아트지 | C29: 100*60 | D29: 전문몰 | E29: 1
A30: 46268 | B30: 아트지 | C30: 80*60 | D30: 전문몰 | E30: 1
A31: 46269 | B31: 유포지 | C31: 30*15 | D31: 전문몰 | E31: 2
A32: 46269 | B32: 유포지 | C32: 70*50 | D32: 전문몰 | E32: 1
A33: 46272 | B33: 아트지 | C33: 100*100 | D33: 전문몰 | E33: 1
A34: 46272 | B34: 아트지 | C34: 40*20 | D34: 전문몰 | E34: 2
A35: 46272 | B35: 아트지 | C35: 50*50 | D35: 쿠팡 | E35: 1
A36: 46274 | B36: 아트지 | C36: 50*50 | D36: 쿠팡 | E36: 1
A37: 46275 | B37: 유포지 | C37: 100*70 | D37: 쿠팡 | E37: 1
A38: 46275 | B38: 아트지 | C38: 80*60 | D38: 전문몰 | E38: 1
A39: 46279 | B39: 아트지 | C39: 60*40 | D39: 쿠팡 | E39: 1
... A50: 46301 | B50: 감열지 | C50: 100*100 | D50: 코스모스몰 | E50: 6
...
