Workbook

Sheet 요약
A1: 타업체 최저가 대비 가격 이상 모델 정리
A2: 기준: 원본 visible 시트(PDA/프린터/스캐너-코스모스몰상품목록)의 "10월 최저가" 확인 모델 · 숨김 열/숨김 시트 미사용
A3: 판정 기준 (차이율 = (우리가-최저가)/최저가)
B4: 낮음 (우리가 최저가보다 이만큼 이상 저렴) | C4: -0.05 | D4: ← 파란 숫자 수정 시 각 시트 판정 자동 변경
B5: 다소 높음 (이상) | C5: 0.1
B6: 높음 (이상) | C6: 0.15
B7: 매우 높음 (이상) | C7: 0.3
A9: 카테고리 | B9: 낮음 | C9: 다소 높음 | D9: 높음 | E9: 매우 높음 | F9: 합계
A10: PDA | B10: =COUNTIF(PDA!$I$2:$I$2,"낮음") -> 0 | C10: =COUNTIF(PDA!$I$2:$I$2,"다소 높음") -> 0 | D10: =COUNTIF(PDA!$I$2:$I$2,"높음") -> 1 | E10: =COUNTIF(PDA!$I$2:$I$2,"매우 높음") -> 0 | F10: =SUM(B10:E10) -> 1
A11: 프린터 | B11: =COUNTIF(프린터!$I$2:$I$55,"낮음") -> 1 | C11: =COUNTIF(프린터!$I$2:$I$55,"다소 높음") -> 10 | D11: =COUNTIF(프린터!$I$2:$I$55,"높음") -> 28 | E11: =COUNTIF(프린터!$I$2:$I$55,"매우 높음") -> 15 | F11: =SUM(B11:E11) -> 54
A12: 스캐너 | B12: =COUNTIF(스캐너!$I$2:$I$5,"낮음") -> 1 | C12: =COUNTIF(스캐너!$I$2:$I$5,"다소 높음") -> 1 | D12: =COUNTIF(스캐너!$I$2:$I$5,"높음") -> 0 | E12: =COUNTIF(스캐너!$I$2:$I$5,"매우 높음") -> 2 | F12: =SUM(B12:E12) -> 4
A13: 합계 | B13: =SUM(B10:B12) -> 2 | C13: =SUM(C10:C12) -> 11 | D13: =SUM(D10:D12) -> 29 | E13: =SUM(E10:E12) -> 17 | F13: =SUM(F10:F12) -> 59
A15: 참고
A16: · 최저가 업체가 코스모스몰/전문몰(자사)인 모델, 차이율 -5%~+10% 사이(적정) 모델은 제외
A17: · 최저가 칸에 "타업체없음" 등 숫자가 없는 모델은 비교 불가로 제외
A18: · 각 시트는 차이율 높은 순 정렬, "비고"에 원본 행번호·데이터 이상 의심 내용 기재
A19: · 스캐너 SB7700, 프린터 XD5-40tR은 원본 최저가 입력 오류로 보여 재확인 필요

Sheet PDA
A1: No | B1: 분류 | C1: 상품명 | D1: 우리 판매가 | E1: 타업체 최저가 | F1: 최저가 업체 | G1: 차액(우리-최저) | H1: 차이율 | I1: 판정 | J1: 시중가격대 | K1: 경쟁정도 | L1: 비고
A2: 1 | B2: 안드로이드OS | C2: TC53 | D2: 3300000 | E2: 2639000 | F2: 더원시스 | G2: =D2-E2 -> 661000 | H2: =IF(E2=0,"",G2/E2) -> 0.25047366 | I2: =IF(H2<=요약!$C$4,"낮음",IF(H2>=요약!$C$7,"매우 높음",IF(H2>=요약!$C$6,"높음",IF(H2>=요약!$C$5,"다소 높음","적정")))) -> 높음 | L2: 원본 18행

Sheet 프린터
A1: No | B1: 분류 | C1: 상품명 | D1: 우리 판매가 | E1: 타업체 최저가 | F1: 최저가 업체 | G1: 차액(우리-최저) | H1: 차이율 | I1: 판정 | J1: 시중가격대 | K1: 경쟁정도 | L1: 비고
A2: 1 | B2: 소형(데스크탑) | C2: G500 | D2: 451000 | E2: 291900 | F2: 글로비잇 | G2: =D2-E2 -> 159100 | H2: =IF(E2=0,"",G2/E2) -> 0.54504967 | I2: =IF(H2<=요약!$C$4,"낮음",IF(H2>=요약!$C$7,"매우 높음",IF(H2>=요약!$C$6,"높음",IF(H2>=요약!$C$5,"다소 높음","적정")))) -> 매우 높음 | J2: 295000 | K2: 높음 | L2: 원본 27행
A3: 2 | B3: 산업용 | C3: B-EX4T1 | D3: 1500000 | E3: 979000 | F3: 더원시스 | G3: =D3-E3 -> 521000 | H3: =IF(E3=0,"",G3/E3) -> 0.53217569 | I3: =IF(H3<=요약!$C$4,"낮음",IF(H3>=요약!$C$7,"매우 높음",IF(H3>=요약!$C$6,"높음",IF(H3>=요약!$C$5,"다소 높음","적정")))) -> 매우 높음 | J3: 990000 | K3: 중간 | L3: 원본 40행
A4: 3 | B4: 휴대용 | C4: PT-P300BT | D4: 109000 | E4: 73730 | F4: 바오 | G4: =D4-E4 -> 35270 | H4: =IF(E4=0,"",G4/E4) -> 0.47836701 | I4: =IF(H4<=요약!$C$4,"낮음",IF(H4>=요약!$C$7,"매우 높음",IF(H4>=요약!$C$6,"높음",IF(H4>=요약!$C$5,"다소 높음","적정")))) -> 매우 높음 | J4: 76000 | K4: 높음 | L4: 원본 93행
A5: 4 | B5: 영수증 | C5: TM-T88VII | D5: 343000 | E5: 232300 | F5: 엠스타샵 | G5: =D5-E5 -> 110700 | H5: =IF(E5=0,"",G5/E5) -> 0.47653896 | I5: =IF(H5<=요약!$C$4,"낮음",IF(H5>=요약!$C$7,"매우 높음",IF(H5>=요약!$C$6,"높음",IF(H5>=요약!$C$5,"다소 높음","적정")))) -> 매우 높음 | J5: 234300~ | K5: 중간 | L5: 원본 291행
A6: 5 | B6: 산업용 | C6: ZT421 | D6: 3300000 | E6: 2280000 | F6: EarthWide Mark | G6: =D6-E6 -> 1020000 | H6: =IF(E6=0,"",G6/E6) -> 0.44736842 | I6: =IF(H6<=요약!$C$4,"낮음",IF(H6>=요약!$C$7,"매우 높음",IF(H6>=요약!$C$6,"높음",IF(H6>=요약!$C$5,"다소 높음","적정")))) -> 매우 높음 | J6: 2300000 | K6: 높음 | L6: 원본 6행
A7: 6 | B7: 소형(데스크탑) | C7: RT230i | D7: 635250 | E7: 445000 | F7: 바코드다판다 | G7: =D7-E7 -> 190250 | H7: =IF(E7=0,"",G7/E7) -> 0.42752809 | I7: =IF(H7<=요약!$C$4,"낮음",IF(H7>=요약!$C$7,"매우 높음",IF(H7>=요약!$C$6,"높음",IF(H7>=요약!$C$5,"다소 높음","적정")))) -> 매우 높음 | J7: 500000 | K7: 중간 | L7: 원본 359행
A8: 7 | B8: 산업용 | C8: PX45 | D8: 4620000 | E8: 3350000 | F8: 우주사무기 | G8: =D8-E8 -> 1270000 | H8: =IF(E8=0,"",G8/E8) -> 0.37910448 | I8: =IF(H8<=요약!$C$4,"낮음",IF(H8>=요약!$C$7,"매우 높음",IF(H8>=요약!$C$6,"높음",IF(H8>=요약!$C$5,"다소 높음","적정")))) -> 매우 높음 | J8: 350만원~ | K8: 중간 | L8: 원본 221행
A9: 8 | B9: 소형(데스크탑) | C9: RT200i/최저가고민 | D9: 554400 | E9: 407000 | F9: 아크메시스(확인필요) | G9: =D9-E9 -> 147400 | H9: =IF(E9=0,"",G9/E9) -> 0.36216216 | I9: =IF(H9<=요약!$C$4,"낮음",IF(H9>=요약!$C$7,"매우 높음",IF(H9>=요약!$C$6,"높음",IF(H9>=요약!$C$5,"다소 높음","적정")))) -> 매우 높음 | J9: 435000~ | K9: 주간 | L9: 원본 403행
A10: 9 | B10: 산업용 | C10: ZT610 | D10: 3927000 | E10: 2900000 | F10: 디앤에스테크 | G10: =D10-E10 -> 1027000 | H10: =IF(E10=0,"",G10/E10) -> 0.35413793 | I10: =IF(H10<=요약!$C$4,"낮음",IF(H10>=요약!$C$7,"매우 높음",IF(H10>=요약!$C$6,"높음",IF(H10>=요약!$C$5,"다소 높음","적정")))) -> 매우 높음 | J10: 3500000~ | K10: 높음 | L10: 원본 14행
A11: 10 | B11: 감열 | C11: ZD421D | D11: 550000 | E11: 410000 | F11: 우주사무기 | G11: =D11-E11 -> 140000 | H11: =IF(E11=0,"",G11/E11) -> 0.34146341 | I11: =IF(H11<=요약!$C$4,"낮음",IF(H11>=요약!$C$7,"매우 높음",IF(H11>=요약!$C$6,"높음",IF(H11>=요약!$C$5,"다소 높음","적정")))) -> 매우 높음 | J11: 410000 | K11: 높음 | L11: 원본 407행
A12: 11 | B12: 감열 | C12: SLP-DL410 | D12: 380000 | E12: 285000 | F12: 에이원바코드 | G12: =D12-E12 -> 95000 | H12: =IF(E12=0,"",G12/E12) -> 0.33333333 | I12: =IF(H12<=요약!$C$4,"낮음",IF(H12>=요약!$C$7,"매우 높음",IF(H12>=요약!$C$6,"높음",IF(H12>=요약!$C$5,"다소 높음","적정")))) -> 매우 높음 | K12: 높음 | L12: 원본 154행
A13: 12 | B13: 휴대용 | C13: QL-800 | D13: 220000 | E13: 166070 | F13: 바오 | G13: =D13-E13 -> 53930 | H13: =IF(E13=0,"",G13/E13) -> 0.32474258 | I13: =IF(H13<=요약!$C$4,"낮음",IF(H13>=요약!$C$7,"매우 높음",IF(H13>=요약!$C$6,"높음",IF(H13>=요약!$C$5,"다소 높음","적정")))) -> 매우 높음 | J13: 176000 | K13: 높음 | L13: 원본 89행
A14: 13 | B14: 산업용 | C14: B-EX6T1-TS | D14: 2816000 | E14: 2127500 | F14: 바코드랩 | G14: =D14-E14 -> 688500 | H14: =IF(E14=0,"",G14/E14) -> 0.32361927 | I14: =IF(H14<=요약!$C$4,"낮음",IF(H14>=요약!$C$7,"매우 높음",IF(H14>=요약!$C$6,"높음",IF(H14>=요약!$C$5,"다소 높음","적정")))) -> 매우 높음 | K14: 낮음 | L14: 원본 53행
A15: 14 | B15: 소형(데스크탑) | C15: RT730i | D15: 889350 | E15: 681000 | F15: 컴퓨존 | G15: =D15-E15 -> 208350 | H15: =IF(E15=0,"",G15/E15) -> 0.30594714 | I15: =IF(H15<=요약!$C$4,"낮음",IF(H15>=요약!$C$7,"매우 높음",IF(H15>=요약!$C$6,"높음",IF(H15>=요약!$C$5,"다소 높음","적정")))) -> 매우 높음 | J15: 803000~ | K15: 높음 | L15: 원본 358행
A16: 15 | B16: 소형(데스크탑) | C16: G500+ | D16: 495000 | E16: 380000 | F16: 하우포유 | G16: =D16-E16 -> 115000 | H16: =IF(E16=0,"",G16/E16) -> 0.30263158 | I16: =IF(H16<=요약!$C$4,"낮음",IF(H16>=요약!$C$7,"매우 높음",IF(H16>=요약!$C$6,"높음",IF(H16>=요약!$C$5,"다소 높음","적정")))) -> 매우 높음 | J16: 380000 | K16: 높음 | L16: 원본 212행
A17: 16 | B17: 산업용 | C17: ZT510 | D17: 2640000 | E17: 2040000 | F17: 디앤에스테크 | G17: =D17-E17 -> 600000 | H17: =IF(E17=0,"",G17/E17) -> 0.29411765 | I17: =IF(H17<=요약!$C$4,"낮음",IF(H17>=요약!$C$7,"매우 높음",IF(H17>=요약!$C$6,"높음",IF(H17>=요약!$C$5,"다소 높음","적정")))) -> 높음 | J17: 2099000~ | K17: 높음 | L17: 원본 49행
A18: 17 | B18: 소형(데스크탑) | C18: TTP247 | D18: 450000 | E18: 354000 | F18: 트로닉스샵 | G18: =D18-E18 -> 96000 | H18: =IF(E18=0,"",G18/E18) -> 0.27118644 | I18: =IF(H18<=요약!$C$4,"낮음",IF(H18>=요약!$C$7,"매우 높음",IF(H18>=요약!$C$6,"높음",IF(H18>=요약!$C$5,"다소 높음","적정")))) -> 높음 | J18: 354000 | K18: 높음 | L18: 원본 25행
A19: 18 | B19: 산업용 | C19: TTE-72FX | D19: 11500000 | E19: 9100000 | F19: 다나와바코드 | G19: =D19-E19 -> 2400000 | H19: =IF(E19=0,"",G19/E19) -> 0.26373626 | I19: =IF(H19<=요약!$C$4,"낮음",IF(H19>=요약!$C$7,"매우 높음",IF(H19>=요약!$C$6,"높음",IF(H19>=요약!$C$5,"다소 높음","적정")))) -> 높음 | J19: 11500000 | K19: 중간 | L19: 원본 20행
A20: 19 | B20: 산업용 | C20: ZT411 | D20: 1450000 | E20: 1160000 | F20: 쿠쿠루마 | G20: =D20-E20 -> 290000 | H20: =IF(E20=0,"",G20/E20) -> 0.25 | I20: =IF(H20<=요약!$C$4,"낮음",IF(H20>=요약!$C$7,"매우 높음",IF(H20>=요약!$C$6,"높음",IF(H20>=요약!$C$5,"다소 높음","적정")))) -> 높음 | J20: 1390000 | K20: 높음 | L20: 원본 2행
A21: 20 | B21: 감열 | C21: DA220 | D21: 275000 | E21: 220000 | F21: 포스총판 | G21: =D21-E21 -> 55000 | H21: =IF(E21=0,"",G21/E21) -> 0.25 | I21: =IF(H21<=요약!$C$4,"낮음",IF(H21>=요약!$C$7,"매우 높음",IF(H21>=요약!$C$6,"높음",IF(H21>=요약!$C$5,"다소 높음","적정")))) -> 높음 | J21: 220000!~ | K21: 중간 | L21: 원본 398행
A22: 21 | B22: 소형(데스크탑) | C22: ZD421T 200DPI | D22: 473000 | E22: 380000 | F22: BA인터네셔널 | G22: =D22-E22 -> 93000 | H22: =IF(E22=0,"",G22/E22) -> 0.24473684 | I22: =IF(H22<=요약!$C$4,"낮음",IF(H22>=요약!$C$7,"매우 높음",IF(H22>=요약!$C$6,"높음",IF(H22>=요약!$C$5,"다소 높음","적정")))) -> 높음 | J22: 410000 | K22: 높음 | L22: 원본 370행
A23: 22 | B23: 산업용 | C23: TTP-384MT | D23: 3465000 | E23: 2800000 | F23: 더원시스 | G23: =D23-E23 -> 665000 | H23: =IF(E23=0,"",G23/E23) -> 0.2375 | I23: =IF(H23<=요약!$C$4,"낮음",IF(H23>=요약!$C$7,"매우 높음",IF(H23>=요약!$C$6,"높음",IF(H23>=요약!$C$5,"다소 높음","적정")))) -> 높음 | J23: 2800000 | K23: 높음 | L23: 원본 228행
A24: 23 | B24: 소형(데스크탑) | C24: RT200/최저가고민 | D24: 407000 | E24: 330000 | F24: 하우포유,전문몰 | G24: =D24-E24 -> 77000 | H24: =IF(E24=0,"",G24/E24) -> 0.23333333 | I24: =IF(H24<=요약!$C$4,"낮음",IF(H24>=요약!$C$7,"매우 높음",IF(H24>=요약!$C$6,"높음",IF(H24>=요약!$C$5,"다소 높음","적정")))) -> 높음 | J24: 330000~ | K24: 중간 | L24: 원본 404행
A25: 24 | B25: 영수증 | C25: SLK-TS100 | D25: 90000 | E25: 73000 | F25: 신화정보시스템 | G25: =D25-E25 -> 17000 | H25: =IF(E25=0,"",G25/E25) -> 0.23287671 | I25: =IF(H25<=요약!$C$4,"낮음",IF(H25>=요약!$C$7,"매우 높음",IF(H25>=요약!$C$6,"높음",IF(H25>=요약!$C$5,"다소 높음","적정")))) -> 높음 | J25: 75000 | K25: 높음 | L25: 원본 186행
A26: 25 | B26: 산업용 | C26: PX65 | D26: 5148000 | E26: 4200000 | F26: 우주사무기 | G26: =D26-E26 -> 948000 | H26: =IF(E26=0,"",G26/E26) -> 0.22571429 | I26: =IF(H26<=요약!$C$4,"낮음",IF(H26>=요약!$C$7,"매우 높음",IF(H26>=요약!$C$6,"높음",IF(H26>=요약!$C$5,"다소 높음","적정")))) -> 높음 | J26: 420만원~ | K26: 중간 | L26: 원본 220행
A27: 26 | B27: 산업용 | C27: ZX1200i | D27: 1540000 | E27: 1265000 | F27: 지오바코드,전문몰 | G27: =D27-E27 -> 275000 | H27: =IF(E27=0,"",G27/E27) -> 0.2173913 | I27: =IF(H27<=요약!$C$4,"낮음",IF(H27>=요약!$C$7,"매우 높음",IF(H27>=요약!$C$6,"높음",IF(H27>=요약!$C$5,"다소 높음","적정")))) -> 높음 | J27: 1265000 | K27: 중간 | L27: 원본 19행
A28: 27 | B28: 감열 | C28: DT2x/최저가 고민 | D28: 392700 | E28: 323000 | F28: 올인원솔루션 | G28: =D28-E28 -> 69700 | H28: =IF(E28=0,"",G28/E28) -> 0.21578947 | I28: =IF(H28<=요약!$C$4,"낮음",IF(H28>=요약!$C$7,"매우 높음",IF(H28>=요약!$C$6,"높음",IF(H28>=요약!$C$5,"다소 높음","적정")))) -> 높음 | J28: 324000~ | K28: 중간 | L28: 원본 406행
A29: 28 | B29: 휴대용 | C29: PT-P950NW | D29: 660000 | E29: 546390 | F29: 하르덴 | G29: =D29-E29 -> 113610 | H29: =IF(E29=0,"",G29/E29) -> 0.2079284 | I29: =IF(H29<=요약!$C$4,"낮음",IF(H29>=요약!$C$7,"매우 높음",IF(H29>=요약!$C$6,"높음",IF(H29>=요약!$C$5,"다소 높음","적정")))) -> 높음 | J29: 588000 | K29: 높음 | L29: 원본 90행
A30: 29 | B30: 산업용 | C30: PM45 | D30: 1925000 | E30: 1598000 | F30: 바코드월드 | G30: =D30-E30 -> 327000 | H30: =IF(E30=0,"",G30/E30) -> 0.20463079 | I30: =IF(H30<=요약!$C$4,"낮음",IF(H30>=요약!$C$7,"매우 높음",IF(H30>=요약!$C$6,"높음",IF(H30>=요약!$C$5,"다소 높음","적정")))) -> 높음 | J30: 165만원~ | K30: 중간 | L30: 원본 15행
A31: 30 | B31: 소형(데스크탑) | C31: ZD421T 300DPI | D31: 660000 | E31: 550000 | F31: 인스텍코리아 | G31: =D31-E31 -> 110000 | H31: =IF(E31=0,"",G31/E31) -> 0.2 | I31: =IF(H31<=요약!$C$4,"낮음",IF(H31>=요약!$C$7,"매우 높음",IF(H31>=요약!$C$6,"높음",IF(H31>=요약!$C$5,"다소 높음","적정")))) -> 높음 | J31: 620000 | K31: 높음 | L31: 원본 263행
A32: 31 | B32: 감열 | C32: LK-B30IIE | D32: 210000 | E32: 175000 | F32: 하이하이몰 | G32: =D32-E32 -> 35000 | H32: =IF(E32=0,"",G32/E32) -> 0.2 | I32: =IF(H32<=요약!$C$4,"낮음",IF(H32>=요약!$C$7,"매우 높음",IF(H32>=요약!$C$6,"높음",IF(H32>=요약!$C$5,"다소 높음","적정")))) -> 높음 | J32: 175000~ | K32: 높음 | L32: 원본 284행
A33: 32 | B33: 산업용 | C33: ZT620 | D33: 5900000 | E33: 4950000 | F33: 바코드장터 | G33: =D33-E33 -> 950000 | H33: =IF(E33=0,"",G33/E33) -> 0.19191919 | I33: =IF(H33<=요약!$C$4,"낮음",IF(H33>=요약!$C$7,"매우 높음",IF(H33>=요약!$C$6,"높음",IF(H33>=요약!$C$5,"다소 높음","적정")))) -> 높음 | J33: 5500000 | K33: 높음 | L33: 원본 48행
A34: 33 | B34: 휴대용 | C34: PT-H110BW | D34: 65000 | E34: 54700 | F34: 바오 | G34: =D34-E34 -> 10300 | H34: =IF(E34=0,"",G34/E34) -> 0.18829982 | I34: =IF(H34<=요약!$C$4,"낮음",IF(H34>=요약!$C$7,"매우 높음",IF(H34>=요약!$C$6,"높음",IF(H34>=요약!$C$5,"다소 높음","적정")))) -> 높음 | J34: 54700 | K34: 높음 | L34: 원본 94행
A35: 34 | B35: 소형(데스크탑) | C35: ZD230T | D35: 352000 | E35: 297980 | F35: 제벡스코리아 | G35: =D35-E35 -> 54020 | H35: =IF(E35=0,"",G35/E35) -> 0.18128733 | I35: =IF(H35<=요약!$C$4,"낮음",IF(H35>=요약!$C$7,"매우 높음",IF(H35>=요약!$C$6,"높음",IF(H35>=요약!$C$5,"다소 높음","적정")))) -> 높음 | J35: 297980 | K35: 높음 | L35: 원본 153행
A36: 35 | B36: 손목띠 | C36: TDP247 | D36: 330000 | E36: 280000 | F36: 바이라벨 | G36: =D36-E36 -> 50000 | H36: =IF(E36=0,"",G36/E36) -> 0.17857143 | I36: =IF(H36<=요약!$C$4,"낮음",IF(H36>=요약!$C$7,"매우 높음",IF(H36>=요약!$C$6,"높음",IF(H36>=요약!$C$5,"다소 높음","적정")))) -> 높음 | J36: 280000 | K36: 높음 | L36: 원본 85행
A37: 36 | B37: 감열 | C37: ZD411D | D37: 528000 | E37: 448000 | F37: 주노바코드스토어 | G37: =D37-E37 -> 80000 | H37: =IF(E37=0,"",G37/E37) -> 0.17857143 | I37: =IF(H37<=요약!$C$4,"낮음",IF(H37>=요약!$C$7,"매우 높음",IF(H37>=요약!$C$6,"높음",IF(H37>=요약!$C$5,"다소 높음","적정")))) -> 높음 | J37: 448000 | K37: 낮음 | L37: 원본 290행
A38: 37 | B38: 소형(데스크탑) | C38: DT4 | D38: 385000 | E38: 329000 | F38: 지오바코드 | G38: =D38-E38 -> 56000 | H38: =IF(E38=0,"",G38/E38) -> 0.17021277 | I38: =IF(H38<=요약!$C$4,"낮음",IF(H38>=요약!$C$7,"매우 높음",IF(H38>=요약!$C$6,"높음",IF(H38>=요약!$C$5,"다소 높음","적정")))) -> 높음 | J38: 329000~ | K38: 중간 | L38: 원본 405행
A39: 38 | B39: 감열 | C39: ZD230D/쇼핑검색off | D39: 231000 | E39: 197900 | F39: 하이하이몰 | G39: =D39-E39 -> 33100 | H39: =IF(E39=0,"",G39/E39) -> 0.16725619 | I39: =IF(H39<=요약!$C$4,"낮음",IF(H39>=요약!$C$7,"매우 높음",IF(H39>=요약!$C$6,"높음",IF(H39>=요약!$C$5,"다소 높음","적정")))) -> 높음 | J39: 194000~ | K39: 높음 | L39: 원본 151행
A40: 39 | B40: 산업용 | C40: MH241T / MH341T | D40: 1400000 | E40: 1200000 | F40: 바코드랩 | G40: =D40-E40 -> 200000 | H40: =IF(E40=0,"",G40/E40) -> 0.16666667 | I40: =IF(H40<=요약!$C$4,"낮음",IF(H40>=요약!$C$7,"매우 높음",IF(H40>=요약!$C$6,"높음",IF(H40>=요약!$C$5,"다소 높음","적정")))) -> 높음 | J40: 1200000 | K40: 높음 | L40: 원본 56행
...

Sheet 스캐너
A1: No | B1: 분류 | C1: 상품명 | D1: 우리 판매가 | E1: 타업체 최저가 | F1: 최저가 업체 | G1: 차액(우리-최저) | H1: 차이율 | I1: 판정 | J1: 시중가격대 | K1: 경쟁정도 | L1: 비고
A2: 1 | B2: 무선스캐너 | C2: LI4278 | D2: 380000 | E2: 187380 | F2: 더원시스 | G2: =D2-E2 -> 192620 | H2: =IF(E2=0,"",G2/E2) -> 1.0279646 | I2: =IF(H2<=요약!$C$4,"낮음",IF(H2>=요약!$C$7,"매우 높음",IF(H2>=요약!$C$6,"높음",IF(H2>=요약!$C$5,"다소 높음","적정")))) -> 매우 높음 | J2: 187천원~ | K2: 높음 | L2: 원본 10행
A3: 2 | B3: 탁상형 | C3: DS9308 | D3: 246000 | E3: 149500 | F3: 에이치스토어 | G3: =D3-E3 -> 96500 | H3: =IF(E3=0,"",G3/E3) -> 0.64548495 | I3: =IF(H3<=요약!$C$4,"낮음",IF(H3>=요약!$C$7,"매우 높음",IF(H3>=요약!$C$6,"높음",IF(H3>=요약!$C$5,"다소 높음","적정")))) -> 매우 높음 | J3: 145000~ | K3: 높음 | L3: 원본 3행
A4: 3 | B4: 무선스캐너 | C4: GBT4500 | D4: 660000 | E4: 588000 | F4: 원인터 | G4: =D4-E4 -> 72000 | H4: =IF(E4=0,"",G4/E4) -> 0.12244898 | I4: =IF(H4<=요약!$C$4,"낮음",IF(H4>=요약!$C$7,"매우 높음",IF(H4>=요약!$C$6,"높음",IF(H4>=요약!$C$5,"다소 높음","적정")))) -> 다소 높음 | J4: 588천원~ | K4: 높음 | L4: 원본 11행
A5: 4 | B5: 1D 바코드 | C5: SB7700 | D5: 77000 | E5: 2280000 | F5: EarthWide Mark | G5: =D5-E5 -> -2203000 | H5: =IF(E5=0,"",G5/E5) -> -0.96622807 | I5: =IF(H5<=요약!$C$4,"낮음",IF(H5>=요약!$C$7,"매우 높음",IF(H5>=요약!$C$6,"높음",IF(H5>=요약!$C$5,"다소 높음","적정")))) -> 낮음 | J5: 2300000 | K5: 높음 | L5: 최저가·업체·시중가가 프린터 ZT421 행과 동일 → 복붙 오류로 보임, 실제 최저가 재확인 필요 / 원본 2행
