Workbook

Sheet 지브라PDA목록
A1: 번호 | B1: 상품분류 | C1: 상품명 | D1: 제조사 | E1: 제품규격 | F1: 판매가
A2: 1 | B2: PDA > 윈도우OS > 윈도우 CE | C2: M3 OX10 | D2: M3mobile | F2: 750000
A3: '1531 | B3: PDA > 안드로이드OS > 풀터치(가성비) | C3: TC21 | D3: ZEBRA | F3: 800000
A4: '1589 | B4: PDA > 안드로이드OS > 풀터치(가성비) | C4: PM90(2D) | D4: PointMobile | F4: 715000
A5: '1585 | B5: PDA > 안드로이드OS > 풀터치(가성비) | C5: EDA52 | D5: Honeywell | F5: 890000
A6: '44 | B6: PDA > 안드로이드OS > 풀터치(가성비) | C6: PM85(2D) | D6: PointMobile | F6: 788000
A7: '451 | B7: PDA > 안드로이드OS > 프리미엄풀터치 | C7: EDA51 | D7: Honeywell | F7: 0
A8: '6 | B8: PDA > 안드로이드OS > 풀터치(가성비) | C8: SM15 | D8: M3mobile | F8: 792000
A9: '11 | B9: PDA > 윈도우OS > 윈도우 CE | C9: M3 BLACK | D9: M3mobile | F9: 825000
A10: '51 | B10: PDA | C10: CT60(단종) | F10: 2310000
A11: '45 | B11: PDA > 안드로이드OS > 롱레인지타입 | C11: UL20 | D11: M3mobile | F11: 1155000
A12: '1077 | B12: PDA > 안드로이드OS > 키패드(핸드헬드) | C12: US20 | D12: M3mobile | F12: 880000
A13: '492 | B13: PDA > 안드로이드OS > 키패드(핸드헬드) | C13: MC9300(2D) | D13: ZEBRA | F13: 2600000
A14: '1376 | B14: PDA > 안드로이드OS > 키패드(핸드헬드) | C14: NLS-MT37 | D14: Newland | F14: 600000
A15: '1150 | B15: PDA > 안드로이드OS > 키패드(핸드헬드) | C15: PM67 | D15: PointMobile | F15: 858000
A16: '881 | B16: PDA > 안드로이드OS > 키패드(핸드헬드) | C16: PM451 | D16: PointMobile | F16: 950000
A17: '13 | B17: PDA > 안드로이드OS > 키패드(핸드헬드) | C17: PM550 | D17: PointMobile | F17: 1090000
A18: '12 | B18: PDA > 안드로이드OS > 기타 | C18: H3 | D18: BIXOLON | F18: 880000
A19: '1149 | B19: PDA > 안드로이드OS > 풀터치(가성비) | C19: PM30 | D19: PointMobile | F19: 825000
A20: '931 | B20: PDA > 안드로이드OS > 풀터치(가성비) | C20: PM90(2D) | D20: PointMobile | F20: 715000
A21: '50 | B21: PDA > 안드로이드OS > 풀터치(가성비) | C21: PM70(단종) | D21: PointMobile | F21: 0
A22: '966 | B22: PDA > 안드로이드OS > 롱레인지타입 | C22: CT40XP | D22: Honeywell | F22: 0
... A40: '1148 | B40: PDA > 안드로이드OS > 키패드(핸드헬드) | C40: MC2200 | D40: ZEBRA | F40: 1210000
A41: '972 | B41: PDA > 안드로이드OS > 키패드(핸드헬드) | C41: DT-X400-10 | F41: 990000
A42: '933 | B42: PDA > 안드로이드OS > 풀터치(가성비) | C42: PM45 | D42: PointMobile | F42: 880000
A43: '85 | B43: PDA > | C43: PM350(단종) | D43: PointMobile | F43: 880000
A44: '1292 | B44: PDA > 안드로이드OS > 풀터치(가성비) | C44: PM75 | D44: PointMobile | F44: 770000
A45: '1230 | B45: PDA > 안드로이드OS > 풀터치(가성비) | C45: SL20 | D45: M3mobile | F45: 700000
A46: '79 | B46: PDA > RFID리더기 | C46: M3 RFID GUN | D46: M3mobile | F46: 660000
A47: '1314 | B47: PDA > 안드로이드OS > 풀터치(가성비) | C47: SM20 | D47: M3mobile | F47: 880000
A48: '65 | B48: PDA > 윈도우OS > 윈도우 모바일 | C48: DS5(단종) | D48: DSIC | F48: 0
A49: '937 | B49: PDA > 안드로이드OS > 프리미엄풀터치 | C49: TC8300 | D49: ZEBRA | F49: 3300000
A50: '62 | B50: PDA > | C50: DOTH-300S(단종) | D50: DOTH | F50: 0
A51: '822 | B51: PDA > 안드로이드OS > 풀터치(가성비) | C51: TC21 | D51: ZEBRA | F51: 800000
A52: '958 | B52: PDA > 안드로이드OS > 프리미엄풀터치 | C52: TC52 / TC57 | D52: ZEBRA | F52: 0
A53: '76 | B53: PDA > 윈도우OS > 윈도우 모바일 | C53: AB700 | D53: ATID | F53: 990000
... A61: '54 | B61: PDA > 안드로이드OS > 키패드(핸드헬드) | C61: MC32N0(단종) | D61: ZEBRA | F61: 0
A62: '524 | B62: 소프트웨어 > PDA 맞춤 솔루션 | C62: 자산이력관리SW | F62: 330000
A63: '739 | B63: 소프트웨어 > PDA 맞춤 솔루션 | C63: 자산이동관리SW | F63: 330000
A64: '529 | B64: 소프트웨어 > PDA 맞춤 솔루션 | C64: 입출고재고관리SW PRO | F64: 330000
...

Sheet 지브라-스캐너
D1: 코스모스몰 | L1: 최저가업체 | Q1: 기타업체 | V1: 옵션장난 업체 (노출가 + 추가옵션) | AD1: 참고
A2: 번호 | B2: 제품명 | C2: USB케이블 (O/X) | D2: 코스모스몰 구성 | E2: 매입가(VAT별도) | F2: 매입가(VAT포함) | G2: 판매가(VAT포함) | H2: 판매가(VAT별도) | I2: USB포함가(18,000원 기준) | J2: USB포함 매입가 (VAT별도) | K2: 현재 마진율(USB포함) | L2: 최저가업체 | M2: 최저가업체 구성 | N2: 최저가(VAT포함) | O2: 최저가(VAT별도) | P2: 최저가 마진율 | Q2: 기타 업체 | R2: 기타업체 구성 | S2: 기타업체 마진율 | T2: 기타 업체 가격 (VAT별도) | U2: 기타 업체 가격 (VAT포함) | V2: 옵션장난 업체 | W2: 구성 (옵션 포함) | X2: 노출가 (VAT포함) | Y2: 추가옵션 내용 | Z2: 추가옵션 금액 (VAT포함) | AA2: 실구매가 (VAT포함) | AB2: 실구매가 (VAT별도) | AC2: 실구매가 마진율 | AD2: 현재 마진율(VAT별도) | AE2: 최저가 마진율(VAT별도) | AF2: 전달사항 | AG2: 옵션(USB 제외, 추가금액)
A3: 1 | B3: LS2208 SR | C3: X | D3: 본체 | E3: 63000 | F3: =E3*110% | G3: 99000 | H3: =G3/110% | I3: =G3+18000 | J3: =E3+9000 | K3: =1-(J3/(I3/110%)) | L3: 미르스캔몰 | M3: 본체 | N3: 81990 | O3: =N3/110% | P3: =1-(E3/O3) | Q3: 지맥스코리아 | R3: 본체 | S3: =1-(H3/T3) | T3: =U3/110% | U3: 87000 | AA3: =X3+Z3 | AB3: =AA3/110% | AC3: =1-(E3/AB3) | AD3: =1-(E3/H3) | AE3: =1-(E3/O3) | AG3: RS232C (+24,200원) 본체만(케이블없음) (+0원)
A4: 2 | B4: DS2278 | C4: X | D4: 본+크 | E4: 305000 | F4: =E4*110% | G4: 348250 | H4: =G4/110% | I4: =G4+18000 | J4: =E4+9000 | K4: =1-(J4/(I4/110%)) | L4: 에이치에스스토어 | M4: 본+크+USB | N4: 335540 | O4: =N4/110% | P4: =1-(E4/O4) | Q4: 원인터 | R4: 본+크+USB | S4: =1-(H4/T4) | T4: =U4/110% | U4: 400000 | AA4: =X4+Z4 | AB4: =AA4/110% | AC4: =1-(E4/AB4) | AD4: =1-(E4/H4) | AE4: =1-(E4/O4) | AG4: RS232C (+24,200원) 본체+크래들만(케이블없음) (+0원)
A5: 3 | B5: DS2208 | C5: X | D5: 본체 | E5: 96000 | F5: =E5*110% | G5: 125000 | H5: =G5/110% | I5: =G5+18000 | J5: =E5+9000 | K5: =1-(J5/(I5/110%)) | L5: 마켓굿초이스 | M5: 본체 | N5: 85900 | O5: =N5/110% | P5: =1-(E5/O5) | Q5: 원인터 | R5: 본체 | S5: =1-(H5/T5) | T5: =U5/110% | U5: 120000 | AA5: =X5+Z5 | AB5: =AA5/110% | AC5: =1-(E5/AB5) | AD5: =1-(E5/H5) | AE5: =1-(E5/O5) | AG5: RS232C / 선택안함 (+24,200원) RS232C / 스탠드거치대 (+79,200원) 본체만(케이블없음) / 선택안함 (+0원) 본체만(케이블없음) / 스탠드거치대 (+55,000원)
A6: 4 | B6: DS8108 | C6: X | D6: 본체 | E6: 210000 | F6: =E6*110% | G6: 300000 | H6: =G6/110% | I6: =G6+18000 | J6: =E6+9000 | K6: =1-(J6/(I6/110%)) | L6: 바코드다판다 | M6: 본체 | N6: 239000 | O6: =N6/110% | P6: =1-(E6/O6) | Q6: 바코드싸다구 | R6: 본체 | S6: =1-(H6/T6) | T6: =U6/110% | U6: 240000 | AA6: =X6+Z6 | AB6: =AA6/110% | AC6: =1-(E6/AB6) | AD6: =1-(E6/H6) | AE6: =1-(E6/O6) | AG6: RS232C (+24,200원) 본체만 (+0원)
A7: 5 | B7: DS4608 SR | C7: X | D7: 본체 | E7: 165000 | F7: =E7*110% | G7: 207500 | H7: =G7/110% | I7: =G7+18000 | J7: =E7+9000 | K7: =1-(J7/(I7/110%)) | L7: 에이치에스스토어 | M7: 본체 | N7: 138700 | O7: =N7/110% | P7: =1-(E7/O7) | Q7: 바코드싸다구 | R7: 본체+USB | S7: =1-(H7/T7) | T7: =U7/110% | U7: 217000 | AA7: =X7+Z7 | AB7: =AA7/110% | AC7: =1-(E7/AB7) | AD7: =1-(E7/H7) | AE7: =1-(E7/O7) | AG7: RS232C / 선택안함 (+24,200원) RS232C / 스탠드거치대 (+79,200원) 본체만(케이블없음) / 선택안함 (+0원) 본체만(케이블없음) / 스탠드거치대 (+55,000원)
A8: 6 | B8: LI2208 | C8: X | D8: 본체 | F8: =E8*110% | G8: 220000 | H8: =G8/110% | I8: =G8+18000 | J8: =E8+9000 | K8: =1-(J8/(I8/110%)) | L8: 컴엔더 | M8: 본체 | N8: 80000 | O8: =N8/110% | P8: =1-(E8/O8) | T8: =U8/110% | AA8: =X8+Z8 | AB8: =AA8/110% | AC8: =1-(E8/AB8) | AD8: =1-(E8/H8) | AE8: =1-(E8/O8) | AG8: RS232C (+24,200원)
A9: 7 | B9: LI3608 SR | C9: O | D9: 본+USB | E9: 70000 | F9: =E9*110% | G9: 396000 | H9: =G9/110% | I9: =G9 | J9: =E9 | K9: =1-(J9/(I9/110%)) | L9: 유니정보 | M9: 본+USB | N9: 359000 | O9: =N9/110% | P9: =1-(E9/O9) | Q9: 하이하이몰 | R9: 본체+USB | S9: =1-(H9/T9) | T9: =U9/110% | U9: 390000 | AA9: =X9+Z9 | AB9: =AA9/110% | AC9: =1-(E9/AB9) | AD9: =1-(E9/H9) | AE9: =1-(E9/O9) | AG9: 없음
A10: 8 | B10: DS3608 SR | C10: O | D10: 본+USB | E10: 470000 | F10: =E10*110% | G10: 660000 | H10: =G10/110% | I10: =G10 | J10: =E10 | K10: =1-(J10/(I10/110%)) | L10: 한국바코드시스템 | M10: 본체(미기재) | N10: 514700 | O10: =N10/110% | P10: =1-(E10/O10) | Q10: 더원시스 | R10: 본체+USB | S10: =1-(H10/T10) | T10: =U10/110% | U10: 516000 | AA10: =X10+Z10 | AB10: =AA10/110% | AC10: =1-(E10/AB10) | AD10: =1-(E10/H10) | AE10: =1-(E10/O10) | AG10: RS232C (+24,200원)
A11: 9 | B11: LI3678 | C11: O | D11: 본+크+USB | F11: =E11*110% | G11: 1210000 | H11: =G11/110% | I11: =G11 | J11: =E11 | K11: =1-(J11/(I11/110%)) | L11: 착한라벨 | M11: 본+USB | N11: 680000 | O11: =N11/110% | P11: =1-(E11/O11) | Q11: 바이라벨 | R11: 본체(미기재) | S11: =1-(H11/T11) | T11: =U11/110% | U11: 770000 | AA11: =X11+Z11 | AB11: =AA11/110% | AC11: =1-(E11/AB11) | AD11: =1-(E11/H11) | AE11: =1-(E11/O11) | AG11: RS232C (+33,000원)
A12: 10 | B12: DS9908 | C12: X | D12: 본체 | E12: 290000 | F12: =E12*110% | G12: 385000 | H12: =G12/110% | I12: =G12+18000 | J12: =E12+9000 | K12: =1-(J12/(I12/110%)) | L12: 디앤에스테크 | M12: 본체 | N12: 295000 | O12: =N12/110% | P12: =1-(E12/O12) | Q12: 비타민씨엔씨 | R12: 본체 | S12: =1-(H12/T12) | T12: =U12/110% | U12: 330000 | AA12: =X12+Z12 | AB12: =AA12/110% | AC12: =1-(E12/AB12) | AD12: =1-(E12/H12) | AE12: =1-(E12/O12) | AG12: RS232C (+24,200원)
A13: 11 | B13: CS6080 | C13: - | D13: 본체 | E13: 380000 | F13: =E13*110% | G13: 820000 | H13: =G13/110% | L13: 코스모스몰 | M13: 본체 | N13: 820000 | O13: =N13/110% | P13: =1-(E13/O13) | T13: =U13/110% | AA13: =X13+Z13 | AB13: =AA13/110% | AC13: =1-(E13/AB13) | AD13: =1-(E13/H13) | AE13: =1-(E13/O13) | AG13: 2D (+0원)
A14: 12 | B14: DS3678 SR | C14: O | D14: 본+크+USB | E14: 750000 | F14: =E14*110% | G14: 980000 | H14: =G14/110% | I14: =G14 | J14: =E14 | K14: =1-(J14/(I14/110%)) | L14: 바코스토어 | M14: 본+크(미기재) | N14: 925000 | O14: =N14/110% | P14: =1-(E14/O14) | Q14: 더원시스 | R14: 본체+USB | S14: =1-(H14/T14) | T14: =U14/110% | U14: 980000 | AA14: =X14+Z14 | AB14: =AA14/110% | AC14: =1-(E14/AB14) | AD14: =1-(E14/H14) | AE14: =1-(E14/O14) | AG14: SR버전+USB케이블 (+0원) HD버전+USB케이블 (+220,000원) SR버전+RS232C케이블 (+33,000원) HD버전+RS232C케이블 (+275,000원)
A15: 13 | B15: DS3678 HD | C15: O | D15: 본+크+USB | E15: 790000 | F15: =E15*110% | G15: 1200000 | H15: =G15/110% | I15: =G15 | J15: =E15 | K15: =1-(J15/(I15/110%)) | L15: 아크메시스 | M15: 본+아답타+USB | N15: 1060000 | O15: =N15/110% | P15: =1-(E15/O15) | Q15: 유니정보 | R15: 본체+USB | S15: =1-(H15/T15) | T15: =U15/110% | U15: 1090000 | AA15: =X15+Z15 | AB15: =AA15/110% | AC15: =1-(E15/AB15) | AD15: =1-(E15/H15) | AE15: =1-(E15/O15)
A16: 14 | B16: DS4608 XD | C16: X | D16: 본체 | E16: 280000 | F16: =E16*110% | G16: 495000 | H16: =G16/110% | I16: =G16+18000 | J16: =E16+9000 | K16: =1-(J16/(I16/110%)) | L16: 한국바코드시스템 | M16: 본체 | N16: 297000 | O16: =N16/110% | P16: =1-(E16/O16) | Q16: 아크메시스 | R16: 본체+USB | S16: =1-(H16/T16) | T16: =U16/110% | U16: 340000 | AA16: =X16+Z16 | AB16: =AA16/110% | AC16: =1-(E16/AB16) | AD16: =1-(E16/H16) | AE16: =1-(E16/O16) | AG16: RS232C / 선택안함 (+24,200원) RS232C / 스탠드거치대 (+79,200원) 본체만(케이블없음) / 선택안함 (+0원) 본체만(케이블없음) / 스탠드거치대 (+55,000원)
A17: 15 | B17: DS8288/타업체없음 | C17: O | D17: 본+USB | E17: 700000 | F17: =E17*110% | G17: 1058200 | H17: =G17/110% | I17: =G17 | J17: =E17 | K17: =1-(J17/(I17/110%)) | L17: 코스모스몰 | M17: 본+USB | N17: 1058200 | O17: =N17/110% | P17: =1-(E17/O17) | T17: =U17/110% | AA17: =X17+Z17 | AB17: =AA17/110% | AC17: =1-(E17/AB17) | AD17: =1-(E17/H17) | AE17: =1-(E17/O17) | AG17: RS232C (+24,200원)
A18: 16 | B18: DS8208/타업체없음 | C18: O | D18: 본+USB | F18: =E18*110% | G18: 577500 | H18: =G18/110% | I18: =G18 | J18: =E18 | K18: =1-(J18/(I18/110%)) | L18: 코스모스몰 | M18: 본+USB | N18: 577500 | O18: =N18/110% | P18: =1-(E18/O18) | T18: =U18/110% | AA18: =X18+Z18 | AB18: =AA18/110% | AC18: =1-(E18/AB18) | AD18: =1-(E18/H18) | AE18: =1-(E18/O18) | AG18: RS232C (+24,200원)
A19: 17 | B19: DS3608 ER | C19: O | D19: 본+USB | E19: 65000 | F19: =E19*110% | G19: 660000 | H19: =G19/110% | I19: =G19 | J19: =E19 | K19: =1-(J19/(I19/110%)) | L19: 코스모스몰 | M19: 본+USB | N19: 200000 | O19: =N19/110% | P19: =1-(E19/O19) | T19: =U19/110% | AA19: =X19+Z19 | AB19: =AA19/110% | AC19: =1-(E19/AB19) | AD19: =1-(E19/H19) | AE19: =1-(E19/O19) | AG19: 없음
A20: 18 | B20: LI3608 ER | C20: O | D20: 본+USB | E20: 70000 | F20: =E20*110% | G20: 572000 | H20: =G20/110% | I20: =G20 | J20: =E20 | K20: =1-(J20/(I20/110%)) | L20: 유니정보 | M20: 본+USB | N20: 359000 | O20: =N20/110% | P20: =1-(E20/O20) | T20: =U20/110% | AA20: =X20+Z20 | AB20: =AA20/110% | AC20: =1-(E20/AB20) | AD20: =1-(E20/H20) | AE20: =1-(E20/O20) | AG20: 없음
A21: 19 | B21: DS3678 XR | C21: O | D21: 본+USB | F21: =E21*110% | G21: 1628000 | H21: =G21/110% | I21: =G21 | J21: =E21 | K21: =1-(J21/(I21/110%)) | L21: 코스모스몰 | M21: 본+USB | N21: 1628000 | O21: =N21/110% | P21: =1-(E21/O21) | T21: =U21/110% | AA21: =X21+Z21 | AB21: =AA21/110% | AC21: =1-(E21/AB21) | AD21: =1-(E21/H21) | AE21: =1-(E21/O21) | AG21: RS232C (+24,200원)
A22: 20 | B22: DS5502 | C22: O | D22: 본+USB | F22: =E22*110% | G22: 418000 | H22: =G22/110% | I22: =G22 | J22: =E22 | K22: =1-(J22/(I22/110%)) | L22: 유니정보,착한라벨,우주사무기 | M22: 본+USB | N22: 390000 | O22: =N22/110% | P22: =1-(E22/O22) | T22: =U22/110% | AA22: =X22+Z22 | AB22: =AA22/110% | AC22: =1-(E22/AB22) | AD22: =1-(E22/H22) | AE22: =1-(E22/O22) | AG22: RS232C (+49,500원)
A23: 21 | B23: DS4678 | C23: X | D23: 본+크 | E23: 440000 | F23: =E23*110% | G23: 566500 | H23: =G23/110% | I23: =G23+18000 | J23: =E23+9000 | K23: =1-(J23/(I23/110%)) | L23: 주노바코드스토어 | M23: 본+크+USB | N23: 530000 | O23: =N23/110% | P23: =1-(E23/O23) | Q23: 바코드랩 | R23: 본+크 | S23: =1-(H23/T23) | T23: =U23/110% | U23: 530000 | AA23: =X23+Z23 | AB23: =AA23/110% | AC23: =1-(E23/AB23) | AD23: =1-(E23/H23) | AE23: =1-(E23/O23) | AG23: 본체+크래들만(케이블없음) (+0원) RS232C (+24,200원)
A24: 22 | B24: SP72 | C24: O | D24: 본+USB | E24: 448000 | F24: =E24*110% | G24: 980000 | H24: =G24/110% | I24: =G24 | J24: =E24 | K24: =1-(J24/(I24/110%)) | L24: 코스모스몰,더원시스 | M24: 본+USB | N24: 980000 | O24: =N24/110% | P24: =1-(E24/O24) | T24: =U24/110% | AA24: =X24+Z24 | AB24: =AA24/110% | AC24: =1-(E24/AB24) | AD24: =1-(E24/H24) | AE24: =1-(E24/O24) | AG24: 없음
A25: 23 | B25: DS9308 | C25: X | D25: 본체 | E25: 182000 | F25: =E25*110% | G25: 246000 | H25: =G25/110% | I25: =G25+18000 | J25: =E25+9000 | K25: =1-(J25/(I25/110%)) | L25: 에이치앤아이디지탈 | M25: 본체 | N25: 149500 | O25: =N25/110% | P25: =1-(E25/O25) | Q25: 바코드랩 | R25: 본체 | S25: =1-(H25/T25) | T25: =U25/110% | U25: 215000 | AA25: =X25+Z25 | AB25: =AA25/110% | AC25: =1-(E25/AB25) | AG25: RS232C (+24,200원) 본체만(케이블없음) (+0원)
A26: 24 | B26: DS8178 | C26: X | D26: 본+크 | E26: 510000 | F26: =E26*110% | G26: 660000 | H26: =G26/110% | I26: =G26+18000 | J26: =E26+9000 | K26: =1-(J26/(I26/110%)) | L26: BA인터네셔널 | M26: 본+크+USB | N26: 555000 | O26: =N26/110% | P26: =1-(E26/O26) | Q26: 더원시스 | R26: 본+크+USB | S26: =1-(H26/T26) | T26: =U26/110% | U26: 654610 | AA26: =X26+Z26 | AB26: =AA26/110% | AC26: =1-(E26/AB26) | AG26: RS232C (+24,200원) 본체+크래들만(케이블없음) (+0원)
A27: 25 | B27: LI4278 | C27: X | D27: 본+크 | E27: 305000 | F27: =E27*110% | G27: 380000 | H27: =G27/110% | I27: =G27+18000 | J27: =E27+9000 | K27: =1-(J27/(I27/110%)) | L27: 아크메시스 | M27: 본+크+USB | N27: 360000 | O27: =N27/110% | P27: =1-(E27/O27) | Q27: 더원시스 | R27: 본+크+USB | S27: =1-(H27/T27) | T27: =U27/110% | U27: 393400 | AA27: =X27+Z27 | AB27: =AA27/110% | AC27: =1-(E27/AB27) | AG27: RS232C (+24,200원) 본체+크래들만(케이블없음) (+0원)
A28: 26 | B28: RS6100/견적요청 | C28: - | T28: =U28/110% | AA28: =X28+Z28 | AB28: =AA28/110% | AC28: =1-(E28/AB28) | AG28: 링트리거 (+0원)
A29: 27 | B29: FS10/견적요청 | C29: - | T29: =U29/110% | AA29: =X29+Z29 | AB29: =AA29/110% | AC29: =1-(E29/AB29) | AG29: 본체 (+0원)
A30: 28 | B30: FS20/견적요청 | C30: - | T30: =U30/110% | AA30: =X30+Z30 | AB30: =AA30/110% | AC30: =1-(E30/AB30) | AG30: 본체 (+0원)
A31: 29 | B31: FS40/견적요청 | C31: - | T31: =U31/110% | AA31: =X31+Z31 | AB31: =AA31/110% | AC31: =1-(E31/AB31) | AG31: 본체 (+0원)
A32: 30 | B32: FS70/견적요청 | C32: - | T32: =U32/110% | AA32: =X32+Z32 | AB32: =AA32/110% | AC32: =1-(E32/AB32) | AG32: 본체 (+0원)

Sheet 지브라-PDA
A1: 번호 | B1: 제품명 | C1: 카테고리 | D1: 매입가(VAT별도) | E1: 매입가(VAT포함) | F1: 판매가(VAT포함) | G1: 판매가(VAT별도) | J1: 최저가(VAT포함) | K1: 최저가(VAT별도) | L1: 최저가업체 | M1: 현재 마진율(VAT별도) | N1: 최저가 마진율(VAT별도) | O1: 전달사항
A2: 1 | B2: TC21(단종) | C2: 풀터치(가성비) | D2: 470000 | E2: =D2*1.1 | F2: 800000 | G2: =F2/110% | J2: 746630 | K2: =J2/1.1 | L2: 나우픽스 | M2: =1-(D2/G2) | N2: =1-(D2/K2) | O2: 단종
A3: 2 | B3: MC9300 | C3: 키패드(핸드헬드) | D3: 2266000 | E3: =D3*1.1 | F3: 2600000 | G3: =F3/110% | J3: 2600000 | K3: =J3/1.1 | L3: 코스모스몰 | M3: =1-(D3/G3) | N3: =1-(D3/K3) | O3: 단종
A4: 3 | B4: MC3300 | C4: 키패드(핸드헬드) | D4: 1840000 | E4: =D4*1.1 | F4: 2640000 | G4: =F4/110% | H4: 2500000 | I4: =ROUND(H4*1.1/0.95,-1) | J4: 2640000 | K4: =J4/1.1 | L4: 코스모스몰 | M4: =1-(D4/G4) | N4: =1-(D4/K4)
A5: 4 | B5: TC8000 | C5: 프리미엄풀터치 | E5: =D5*1.1 | F5: 3300000 | G5: =F5/110% | J5: 3250450 | K5: =J5/1.1 | L5: 더원시스 | M5: =1-(D5/G5) | N5: =1-(D5/K5) | O5: 단종
A6: 5 | B6: MC2200 | C6: 키패드(핸드헬드) | D6: 1030000 | E6: =D6*1.1 | F6: 1210000 | G6: =F6/110% | J6: 1180000 | K6: =J6/1.1 | L6: 하이하이몰 | M6: =1-(D6/G6) | N6: =1-(D6/K6) | O6: 단종
A7: 6 | B7: TC8300 | C7: 프리미엄풀터치 | E7: =D7*1.1 | F7: 3300000 | G7: =F7/110% | J7: 3249900 | K7: =J7/1.1 | L7: 더원시스 | M7: =1-(D7/G7) | N7: =1-(D7/K7)
A8: 8 | B8: TC53 | C8: 프리미엄풀터치 | D8: 2500000 | E8: =D8*1.1 | F8: 2640000 | H8: 3000000 | I8: =ROUND(H8*1.1/0.95,-1) | J8: 2577960 | K8: =J8/1.1 | L8: 솔바텍지마켓 | M8: =1-(D8/G8) | N8: =1-(D8/K8)
A9: 9 | B9: MC9400 | C9: 키패드(핸드헬드) | D9: 2470000 | E9: =D9*1.1 | F9: 5300000 | G9: =F9/110% | J9: 3115040 | K9: =J9/1.1 | L9: 솔바텍지마켓 | M9: =1-(D9/G9) | N9: =1-(D9/K9)
A10: 10 | B10: MC3400 | C10: 키패드(핸드헬드) | D10: 1490000 | E10: =D10*1.1 | F10: 2750000 | G10: =F10/110% | J10: 2750000 | K10: =J10/1.1 | L10: 코스모스몰,더원시스 | M10: =1-(D10/G10) | N10: =1-(D10/K10)
A11: 11 | B11: TC22 / TC27 | C11: 프리미엄풀터치 | D11: 560000 | E11: =D11*1.1 | F11: 979000 | G11: =F11/110% | J11: 929930 | K11: =J11/1.1 | L11: 코스모스전문몰(최저가) | M11: =1-(D11/G11) | N11: =1-(D11/K11)
A12: 12 | B12: TC77ex-NI | C12: 방폭형 | E12: =D12*1.1 | F12: 3850000 | G12: =F12/110% | J12: 3850000 | K12: =J12/1.1 | L12: 코스모스몰 | M12: =1-(D12/G12) | N12: =1-(D12/K12) | O12: 단종
A13: 13 | B13: RFD40 | C13: RFID 리더기 | D13: 1150000 | E13: =D13*1.1 | F13: 1650000 | G13: =F13/110% | J13: 1650000 | K13: =J13/1.1 | L13: 코스모스몰 | M13: =1-(D13/G13) | N13: =1-(D13/K13)

Sheet 지브라-스캐너-옵션
A1: 번호 | B1: 제품명 | C1: 기본 판매가(VAT포함) | D1: 옵션명 | E1: 옵션값 | F1: 옵션 추가금액 | G1: 최종 판매가(VAT포함) | H1: 최종 판매가(VAT별도)
A2: 1 | B2: LS2208 SR | C2: ='지브라-스캐너'!G3 | D2: 인터페이스 | E2: RS232C | F2: 24200 | G2: =C2+F2 | H2: =G2/110%
A3: 2 | B3: LS2208 SR | C3: ='지브라-스캐너'!G3 | D3: 인터페이스 | E3: 본체만(케이블없음) | F3: 0 | G3: =C3+F3 | H3: =G3/110%
A4: 3 | B4: DS2278 | C4: ='지브라-스캐너'!G4 | D4: 인터페이스 | E4: RS232C | F4: 24200 | G4: =C4+F4 | H4: =G4/110%
A5: 4 | B5: DS2278 | C5: ='지브라-스캐너'!G4 | D5: 인터페이스 | E5: 본체+크래들만(케이블없음) | F5: 0 | G5: =C5+F5 | H5: =G5/110%
A6: 5 | B6: DS2208 | C6: ='지브라-스캐너'!G5 | D6: 인터페이스 / 악세사리 | E6: RS232C / 선택안함 | F6: 24200 | G6: =C6+F6 | H6: =G6/110%
A7: 6 | B7: DS2208 | C7: ='지브라-스캐너'!G5 | D7: 인터페이스 / 악세사리 | E7: RS232C / 스탠드거치대 | F7: 79200 | G7: =C7+F7 | H7: =G7/110%
A8: 7 | B8: DS2208 | C8: ='지브라-스캐너'!G5 | D8: 인터페이스 / 악세사리 | E8: 본체만(케이블없음) / 선택안함 | F8: 0 | G8: =C8+F8 | H8: =G8/110%
A9: 8 | B9: DS2208 | C9: ='지브라-스캐너'!G5 | D9: 인터페이스 / 악세사리 | E9: 본체만(케이블없음) / 스탠드거치대 | F9: 55000 | G9: =C9+F9 | H9: =G9/110%
A10: 9 | B10: DS8108 | C10: ='지브라-스캐너'!G6 | D10: 인터페이스 | E10: RS232C | F10: 24200 | G10: =C10+F10 | H10: =G10/110%
A11: 10 | B11: DS8108 | C11: ='지브라-스캐너'!G6 | D11: 인터페이스 | E11: 본체만 | F11: 0 | G11: =C11+F11 | H11: =G11/110%
A12: 11 | B12: DS4608 SR | C12: ='지브라-스캐너'!G7 | D12: 인터페이스 / 악세사리 | E12: RS232C / 선택안함 | F12: 24200 | G12: =C12+F12 | H12: =G12/110%
A13: 12 | B13: DS4608 SR | C13: ='지브라-스캐너'!G7 | D13: 인터페이스 / 악세사리 | E13: RS232C / 스탠드거치대 | F13: 79200 | G13: =C13+F13 | H13: =G13/110%
A14: 13 | B14: DS4608 SR | C14: ='지브라-스캐너'!G7 | D14: 인터페이스 / 악세사리 | E14: 본체만(케이블없음) / 선택안함 | F14: 0 | G14: =C14+F14 | H14: =G14/110%
A15: 14 | B15: DS4608 SR | C15: ='지브라-스캐너'!G7 | D15: 인터페이스 / 악세사리 | E15: 본체만(케이블없음) / 스탠드거치대 | F15: 55000 | G15: =C15+F15 | H15: =G15/110%
A16: 15 | B16: LI2208 | C16: ='지브라-스캐너'!G8 | D16: 인터페이스 | E16: RS232C | F16: 24200 | G16: =C16+F16 | H16: =G16/110%
A17: 16 | B17: DS3608 SR | C17: ='지브라-스캐너'!G10 | D17: 인터페이스 | E17: RS232C | F17: 24200 | G17: =C17+F17 | H17: =G17/110%
A18: 17 | B18: LI3678 | C18: ='지브라-스캐너'!G11 | D18: 인터페이스 | E18: RS232C | F18: 33000 | G18: =C18+F18 | H18: =G18/110%
A19: 18 | B19: DS9908 | C19: ='지브라-스캐너'!G12 | D19: 인터페이스 | E19: RS232C | F19: 24200 | G19: =C19+F19 | H19: =G19/110%
A20: 19 | B20: CS6080 | C20: ='지브라-스캐너'!G13 | D20: 스캔엔진 | E20: 2D | F20: 0 | G20: =C20+F20 | H20: =G20/110%
A21: 20 | B21: DS3678 SR | C21: ='지브라-스캐너'!G14 | D21: 인터페이스 | E21: SR버전+USB케이블 | F21: 0 | G21: =C21+F21 | H21: =G21/110%
A22: 21 | B22: DS3678 SR | C22: ='지브라-스캐너'!G14 | D22: 인터페이스 | E22: HD버전+USB케이블 | F22: 220000 | G22: =C22+F22 | H22: =G22/110%
A23: 22 | B23: DS3678 SR | C23: ='지브라-스캐너'!G14 | D23: 인터페이스 | E23: SR버전+RS232C케이블 | F23: 33000 | G23: =C23+F23 | H23: =G23/110%
A24: 23 | B24: DS3678 SR | C24: ='지브라-스캐너'!G14 | D24: 인터페이스 | E24: HD버전+RS232C케이블 | F24: 275000 | G24: =C24+F24 | H24: =G24/110%
A25: 24 | B25: DS4608 XD | C25: ='지브라-스캐너'!G16 | D25: 인터페이스 / 악세사리 | E25: RS232C / 선택안함 | F25: 24200 | G25: =C25+F25 | H25: =G25/110%
A26: 25 | B26: DS4608 XD | C26: ='지브라-스캐너'!G16 | D26: 인터페이스 / 악세사리 | E26: RS232C / 스탠드거치대 | F26: 79200 | G26: =C26+F26 | H26: =G26/110%
A27: 26 | B27: DS4608 XD | C27: ='지브라-스캐너'!G16 | D27: 인터페이스 / 악세사리 | E27: 본체만(케이블없음) / 선택안함 | F27: 0 | G27: =C27+F27 | H27: =G27/110%
A28: 27 | B28: DS4608 XD | C28: ='지브라-스캐너'!G16 | D28: 인터페이스 / 악세사리 | E28: 본체만(케이블없음) / 스탠드거치대 | F28: 55000 | G28: =C28+F28 | H28: =G28/110%
A29: 28 | B29: DS8288 | C29: ='지브라-스캐너'!G17 | D29: 인터페이스 | E29: RS232C | F29: 24200 | G29: =C29+F29 | H29: =G29/110%
A30: 29 | B30: DS8208 | C30: ='지브라-스캐너'!G18 | D30: 인터페이스 | E30: RS232C | F30: 24200 | G30: =C30+F30 | H30: =G30/110%
A31: 30 | B31: DS3678 XR | C31: ='지브라-스캐너'!G21 | D31: 인터페이스 | E31: RS232C | F31: 24200 | G31: =C31+F31 | H31: =G31/110%
A32: 31 | B32: DS5502 | C32: ='지브라-스캐너'!G22 | D32: 인터페이스 | E32: RS232C | F32: 49500 | G32: =C32+F32 | H32: =G32/110%
A33: 32 | B33: DS4678 | C33: ='지브라-스캐너'!G23 | D33: 인터페이스 | E33: 본체+크래들만(케이블없음) | F33: 0 | G33: =C33+F33 | H33: =G33/110%
A34: 33 | B34: DS4678 | C34: ='지브라-스캐너'!G23 | D34: 인터페이스 | E34: RS232C | F34: 24200 | G34: =C34+F34 | H34: =G34/110%
A35: 34 | B35: DS9308 | C35: ='지브라-스캐너'!G25 | D35: 인터페이스 | E35: RS232C | F35: 24200 | G35: =C35+F35 | H35: =G35/110%
A36: 35 | B36: DS9308 | C36: ='지브라-스캐너'!G25 | D36: 인터페이스 | E36: 본체만(케이블없음) | F36: 0 | G36: =C36+F36 | H36: =G36/110%
A37: 36 | B37: DS8178 | C37: ='지브라-스캐너'!G26 | D37: 인터페이스 | E37: RS232C | F37: 24200 | G37: =C37+F37 | H37: =G37/110%
A38: 37 | B38: DS8178 | C38: ='지브라-스캐너'!G26 | D38: 인터페이스 | E38: 본체+크래들만(케이블없음) | F38: 0 | G38: =C38+F38 | H38: =G38/110%
A39: 38 | B39: LI4278 | C39: ='지브라-스캐너'!G27 | D39: 인터페이스 | E39: RS232C | F39: 24200 | G39: =C39+F39 | H39: =G39/110%
A40: 39 | B40: LI4278 | C40: ='지브라-스캐너'!G27 | D40: 인터페이스 | E40: 본체+크래들만(케이블없음) | F40: 0 | G40: =C40+F40 | H40: =G40/110%
...
